Workbook
Name \a: #REF!
Name \a: #REF!
Name \a: #REF!
Name \a: #REF!
Name \c: [1]FLASH!#REF!
Name \c: [1]FLASH!#REF!
Name \c: [1]FLASH!#REF!
Name \c: [1]FLASH!#REF!
Name \f: [1]FLASH!#REF!
Name \f: [1]FLASH!#REF!
Name \f: [1]FLASH!#REF!
Name \f: [1]FLASH!#REF!
Name \q: [1]FLASH!#REF!
Name \q: [1]FLASH!#REF!
Name \q: [1]FLASH!#REF!
Name \q: [1]FLASH!#REF!
Name \s: #REF!
Name \s: #REF!
Name \s: #REF!
Name \s: #REF!
Name \t: [1]FLASH!#REF!
Name \t: [1]FLASH!#REF!
Name \t: [1]FLASH!#REF!
Name \t: [1]FLASH!#REF!
Name \u: #REF!
Name \u: #REF!
Name \u: #REF!
Name \u: #REF!
Name \z: #REF!
Name _1: #REF!
Name _1: #REF!
Name _1: #REF!
Name _1: #REF!
Name _2: #REF!
Name _2: #REF!
Name _2: #REF!
Name _2: #REF!
Name _3: #REF!
Name _3: #REF!
Name _3: #REF!
Name _3: #REF!
Name A: #REF!
Name A: #REF!
Name A: #REF!
Name A: #REF!
Name Audit_adj: [2]validation!$I$9
Name Audit_adj_LY: [2]validation_LY!$I$9
Name Axis: OFFSET(#REF!,0,0,MAX(#REF!),1)
Name Axis: OFFSET(#REF!,0,0,MAX(#REF!),1)
Name Axis: OFFSET(#REF!,0,0,MAX(#REF!),1)
Name Axis: OFFSET(#REF!,0,0,MAX(#REF!),1)
Name Axis1: OFFSET(#REF!,0,0,MAX(#REF!),1)
Name Axis1: OFFSET(#REF!,0,0,MAX(#REF!),1)
Name Axis1: OFFSET(#REF!,0,0,MAX(#REF!),1)
Name Axis1: OFFSET(#REF!,0,0,MAX(#REF!),1)
Name B: #REF!
Name B: #REF!
Name B: #REF!
Name B: #REF!
Name BUDGETM: '[3]Budget By Month'!$E$7:$R$83

Sheet IS Feb KSA
I4: 8980975.6 | Z4: 8980975.6
I5: =I4-I12 -> 8980975.6 | Z5: =Z4-Z12 -> 1267.92
B7: INCOME STATEMENT (KSA SAR) | C7: YTD | D7: Q4 | E7: MTD | F7: MTD | G7: MTD | H7: Q3 | I7: MTD | J7: MTD | K7: MTD | L7: Q2 | M7: MTD | N7: MTD | O7: MTD | P7: Q1 | Q7: MTD | R7: MTD | S7: MTD | T7: YTD | U7: Q4 | V7: MTD | W7: MTD | X7: MTD | Y7: Q3 | Z7: MTD | AA7: MTD | AB7: MTD | AC7: Q2 | AD7: MTD | AE7: MTD | AF7: MTD | AG7: Q1 | AH7: MTD | AI7: MTD | AJ7: MTD | AL7: MTD | AM7: YTD
B8: FOR THE PERIOD 28 Feb 2026 | C8: 2026 | D8: 2026 | E8: 46387 | F8: 46356 | G8: 46326 | H8: 2026 | I8: 46295 | J8: 46265 | K8: 46234 | L8: 2026 | M8: 46203 | N8: 46173 | O8: 46142 | P8: 2026 | Q8: 46112 | R8: 46081 | S8: 46053 | T8: 2025 | U8: 2025 | V8: 46022 | W8: 45991 | X8: 45961 | Y8: 2025 | Z8: 45930 | AA8: 45900 | AB8: 45869 | AC8: 2025 | AD8: 45838 | AE8: 45808 | AF8: 45777 | AG8: 2025 | AH8: 45747 | AI8: 45716 | AJ8: 45688 | AL8: 45657 | AM8: 2024
B10: Sales | C10: =SUM(D10:S10)-P10-L10-H10-D10 -> 32825790 | D10: =SUM(E10:G10) -> 0 | H10: =SUM(I10:K10) -> 0 | L10: =SUM(M10:O10) -> 0 | P10: =SUM(Q10:S10) -> 32825790 | R10: 16439013 | S10: 16386777 | T10: =SUM(U10:AJ10)-AG10-AC10-Y10-U10 -> 1.578257e+08 | U10: =SUM(V10:X10) -> 54905864 | V10: 20791023 | W10: 18885652 | X10: =15268743.82-39555.14 -> 15229189 | Y10: =SUM(Z10:AB10) -> 37535436 | Z10: 9966234.8 | AA10: 7379008.3 | AB10: 20190193 | AC10: =SUM(AD10:AF10) -> 32972335 | AD10: 11726376 | AE10: 11371331 | AF10: 9874628.2 | AG10: =SUM(AH10:AJ10) -> 32412070 | AH10: 13667110 | AI10: 10659013 | AJ10: 8085946.4 | AL10: 10080211 | AM10: 76420880
B11: Sales Discount | C11: =SUM(D11:S11)-P11-L11-H11-D11 -> 14516.1 | H11: =SUM(I11:K11) -> 0 | L11: =SUM(M11:O11) -> 0 | P11: =SUM(Q11:S11) -> 14516.1 | R11: 14516.1 | S11: 0 | T11: =SUM(U11:AJ11)-AG11-AC11-Y11-U11 -> 82363.38 | V11: 0 | X11: 0 | Y11: =SUM(Z11:AB11) -> 0 | Z11: 0 | AA11: 0 | AB11: 0 | AC11: =SUM(AD11:AF11) -> 82363.38 | AD11: -7558.83 | AE11: 78283.38 | AF11: 11638.83
B12: Cost of Goods Sold | C12: =SUM(D12:S12)-P12-L12-H12-D12 -> 29328846 | D12: =SUM(E12:G12) -> 0 | H12: =SUM(I12:K12) -> 0 | L12: =SUM(M12:O12) -> 0 | P12: =SUM(Q12:S12) -> 29328846 | R12: 14552433 | S12: 14776413 | T12: =SUM(U12:AJ12)-AG12-AC12-Y12-U12 -> 1.4091252e+08 | U12: =SUM(V12:X12) -> 48616545 | V12: 18140835 | W12: 16962082 | X12: 13513628 | Y12: =SUM(Z12:AB12) -> 33436502 | Z12: 8979707.7 | AA12: 6625405.5 | AB12: 17831388 | AC12: =SUM(AD12:AF12) -> 29582790 | AD12: 10608445 | AE12: 10128323 | AF12: 8846021.3 | AG12: =SUM(AH12:AJ12) -> 29276685 | AH12: 12403281 | AI12: 9631833 | AJ12: 7241571.2 | AL12: 9065157.9 | AM12: 69127802
B13: Purchase Discounts | C13: =SUM(D13:S13)-P13-L13-H13-D13 -> -88806.57 | D13: =SUM(E13:G13) -> 0 | H13: =SUM(I13:K13) -> 0 | I13: 0 | J13: 0 | K13: 0 | L13: =SUM(M13:O13) -> 0 | P13: =SUM(Q13:S13) -> -88806.57 | R13: -12857.77 | S13: -75948.8 | T13: =SUM(U13:AJ13)-AG13-AC13-Y13-U13 -> -222027.19 | U13: =SUM(V13:X13) -> -148153.36 | V13: -131612.06 | W13: -14990.36 | X13: -1550.94 | Y13: =SUM(Z13:AB13) -> 0 | Z13: 0 | AA13: 0 | AB13: 0 | AC13: =SUM(AD13:AF13) -> -62005.67 | AD13: 0 | AE13: -62005.67 | AF13: 0 | AG13: =SUM(AH13:AJ13) -> -11868.16 | AH13: -7728.16 | AI13: -4140 | AJ13: 0 | AL13: 0 | AM13: -93226.45
B14: Gross Profit / (Loss) | C14: =+C10-C11-(C12+C13) -> 3571235 | D14: =+D10-D11-(D12+D13) -> 0 | E14: =+E10-E11-(E12+E13) -> 0 | F14: =+F10-F11-(F12+F13) -> 0 | G14: =+G10-G11-(G12+G13) -> 0 | H14: =+H10-H11-(H12+H13) -> 0 | I14: =+I10-I11-(I12+I13) -> 0 | J14: =+J10-J11-(J12+J13) -> 0 | ... U14: =+U10-U11-(U12+U13) -> 6437472.5 | V14: =+V10-(V12+V13) -> 2781799.7 | W14: =+W10-(W12+W13) -> 1938560.6 | X14: =+X10-(X12+X13) -> 1717112.1 | Y14: =+Y10-(Y12+Y13) -> 4098934.8 | Z14: =+Z10-(Z12+Z13) -> 986527.13 | AA14: =+AA10-(AA12+AA13) -> 753602.78 | AB14: =+AB10-AB11-(AB12+AB13) -> 2358804.9 | AC14: =+AC10-AC11-(AC12+AC13) -> 3369187.1 | AD14: =+AD10-AD11-(AD12+AD13) -> 1125489.3 | AE14: =+AE10-AE11-(AE12+AE13) -> 1226729.8 | AF14: =+AF10-AF11-(AF12+AF13) -> 1016968 | AG14: =+AG10-(AG12+AG13) -> 3147252.4 | AH14: =+AH10-(AH12+AH13) -> 1271557.3 | AI14: =+AI10-(AI12+AI13) -> 1031319.9 | AJ14: =+AJ10-(AJ12+AJ13) -> 844375.15 | AL14: =+AL10-(AL12+AL13) -> 1015053.3 | AM14: =+AM10-(AM12+AM13) -> 7386304.4
B15: Other Income | C15: =SUM(D15:S15)-P15-L15-H15-D15 -> 0 | D15: =SUM(E15:G15) -> 0 | E15: 0 | G15: 0 | H15: =SUM(I15:K15) -> 0 | I15: 0 | J15: 0 | K15: 0 | L15: =SUM(M15:O15) -> 0 | M15: 0 | N15: 0 | O15: 0 | P15: =SUM(Q15:S15) -> 0 | T15: =SUM(U15:AJ15)-AG15-AC15-Y15-U15 -> 18000 | U15: =SUM(V15:X15) -> 0 | V15: 0 | X15: 0 | Y15: =SUM(Z15:AB15) -> 0 | Z15: 0 | AA15: 0 | AB15: 0 | AC15: =SUM(AD15:AF15) -> 0 | AD15: 0 | AE15: 0 | AF15: 0 | AG15: =SUM(AH15:AJ15) -> 18000 | AH15: 12000 | AI15: 6000 | AJ15: 0
B16: Consultation Income | C16: =+D16+H16+L16+P16 -> 0 | D16: =SUM(E16:G16) -> 0 | E16: 0 | G16: 0 | H16: =SUM(I16:K16) -> 0 | I16: 0 | J16: 0 | K16: 0 | L16: =SUM(M16:O16) -> 0 | M16: 0 | N16: 0 | O16: 0 | P16: =SUM(Q16:S16) -> 0 | T16: =+U16+Y16+AC16+AG16 -> 65217.39 | U16: =SUM(V16:X16) -> 0 | V16: 0 | X16: 0 | Y16: =SUM(Z16:AB16) -> 0 | Z16: 0 | AA16: 0 | AB16: 0 | AC16: =SUM(AD16:AF16) -> 0 | AD16: 0 | AE16: 0 | AF16: 0 | AG16: =SUM(AH16:AJ16) -> 65217.39 | AH16: 0 | AI16: 0 | AJ16: 65217.39 | AL16: 26086.96 | AM16: 293478.27
B17: Gross Income | C17: =+D17+H17+L17+P17 -> 3571235 | D17: =+D16+D14 -> 0 | E17: =+E16+E14 -> 0 | F17: =+F16+F14 -> 0 | G17: =+G16+G14 -> 0 | H17: =SUM(I17:K17) -> 0 | I17: =+I16+I14 -> 0 | J17: =+J16+J14 -> 0 | K17: =+K16+K14 -> 0 | L17: =SUM(M17:O17) -> 0 | M17: =+M16+M14 -> 0 | N17: =+N16+N14 -> 0 | O17: =+O16+O14+O15 -> 0 | P17: =+P16+P14+P15 -> 3571235 | Q17: =+Q16+Q14+Q15 -> 0 | R17: =+R16+R14+R15 -> 1884921.5 | S17: =+S16+S14 -> 1686313.6 | T17: =+U17+Y17+AC17+AG17 -> 17136064 | U17: =+U16+U14 -> 6437472.5 | V17: =+V16+V14 -> 2781799.7 | W17: =+W16+W14 -> 1938560.6 | X17: =+X16+X14 -> 1717112.1 | Y17: =SUM(Z17:AB17) -> 4098934.8 | Z17: =+Z16+Z14 -> 986527.13 | AA17: =+AA16+AA14 -> 753602.78 | AB17: =+AB16+AB14 -> 2358804.9 | AC17: =SUM(AD17:AF17) -> 3369187.1 | AD17: =+AD16+AD14 -> 1125489.3 | AE17: =+AE16+AE14 -> 1226729.8 | AF17: =+AF16+AF14+AF15 -> 1016968 | AG17: =+AG16+AG14+AG15 -> 3230469.8 | AH17: =+AH16+AH14+AH15 -> 1283557.3 | AI17: =+AI16+AI14+AI15 -> 1037319.9 | AJ17: =+AJ16+AJ14 -> 909592.54 | AL17: =+AL16+AL14 -> 1041140.2 | AM17: =+AM16+AM14 -> 7679782.7
B19: General and Administrative Expenses | C19: =SUM(C20:C38) -> 330689.42 | D19: =SUM(D20:D38) -> 0 | E19: =SUM(E20:E38) -> 0 | F19: =SUM(F20:F38) -> 0 | G19: =SUM(G20:G38) -> 0 | H19: =SUM(H20:H38) -> 0 | I19: =SUM(I20:I38) -> 0 | J19: =SUM(J20:J38) -> 0 | ... AJ19: =SUM(AJ20:AJ38) -> 88485.15 | AL19: =SUM(AL20:AL38) -> 293429.8 | AM19: =SUM(AM20:AM38) -> 865548.78
B20: Bad Debt | C20: =SUM(D20:S20)-P20-L20-H20-D20 -> 114105.01 | D20: =SUM(E20:G20) -> 0 | H20: =SUM(I20:K20) -> 0 | L20: =SUM(M20:O20) -> 0 | P20: =SUM(Q20:S20) -> 114105.01 | R20: 0 | S20: 114105.01 | T20: =SUM(U20:AJ20)-AG20-AC20-Y20-U20 -> 2044438.5 | U20: =SUM(V20:X20) -> 1820446.2 | V20: 526062.9 | W20: 857099.96 | X20: 437283.39 | Y20: =SUM(Z20:AB20) -> 75000 | Z20: 25000 | AA20: 25000 | AB20: 25000 | AC20: =SUM(AD20:AF20) -> 73991.16 | AD20: 25000 | AE20: 23991.16 | AF20: 25000 | AG20: =SUM(AH20:AJ20) -> 75001.1 | AH20: 25000.8 | AI20: 25000.3 | AJ20: 25000 | AL20: 203009.5 | AM20: 203016.64
B21: Bank Fees and Charges | C21: =SUM(D21:S21)-P21-L21-H21-D21 -> 954.62 | D21: =SUM(E21:G21) -> 0 | H21: =SUM(I21:K21) -> 0 | L21: =SUM(M21:O21) -> 0 | P21: =SUM(Q21:S21) -> 954.62 | R21: 152.63 | S21: 801.99 | T21: =SUM(U21:AJ21)-AG21-AC21-Y21-U21 -> 10168.59 | U21: =SUM(V21:X21) -> 2486.04 | V21: 884.94 | W21: 797.09 | X21: 804.01 | Y21: =SUM(Z21:AB21) -> 1887.04 | Z21: 545.34 | AA21: 530.48 | AB21: 811.22 | AC21: =SUM(AD21:AF21) -> 3285.83 | AD21: 672.17 | AE21: 688.09 | AF21: 1925.57 | AG21: =SUM(AH21:AJ21) -> 2509.68 | AH21: 1049.44 | AI21: 852.65 | AJ21: 607.59 | AL21: 354.16 | AM21: 7108.25
B22: Office Supplies | C22: =SUM(D22:S22)-P22-L22-H22-D22 -> 11778.03 | D22: =SUM(E22:G22) -> 0 | H22: =SUM(I22:K22) -> 0 | L22: =SUM(M22:O22) -> 0 | P22: =SUM(Q22:S22) -> 11778.03 | R22: 5544.51 | S22: 6233.52 | T22: =SUM(U22:AJ22)-AG22-AC22-Y22-U22 -> 75454.71 | U22: =SUM(V22:X22) -> 18760.53 | V22: 4745.27 | W22: 6432.08 | X22: =47138.32-39555.14 -> 7583.18 | Y22: =SUM(Z22:AB22) -> 26652.27 | Z22: 9026.58 | AA22: 10858.29 | AB22: 6767.4 | AC22: =SUM(AD22:AF22) -> 17661.99 | AD22: 5457.01 | AE22: 9625.38 | AF22: 2579.6 | AG22: =SUM(AH22:AJ22) -> 12379.92 | AH22: 2845.92 | AI22: 5694.16 | AJ22: 3839.84 | AL22: 819.32 | AM22: 25690.34
B23: Office Utilities - Electricity/Water/Janitorial | C23: =SUM(D23:S23)-P23-L23-H23-D23 -> 0 | D23: =SUM(E23:G23) -> 0 | H23: =SUM(I23:K23) -> 0 | L23: =SUM(M23:O23) -> 0 | P23: =SUM(Q23:S23) -> 0 | R23: 0 | S23: 0 | T23: =SUM(U23:AJ23)-AG23-AC23-Y23-U23 -> 3541.19 | U23: =SUM(V23:X23) -> 0 | V23: 0 | W23: 0 | X23: 0 | Y23: =SUM(Z23:AB23) -> 1649.27 | Z23: 165.22 | AA23: 949.15 | AB23: 534.9 | AC23: =SUM(AD23:AF23) -> 1459.95 | AD23: 985.5 | AE23: 474.45 | AF23: 0 | AG23: =SUM(AH23:AJ23) -> 431.97 | AH23: 0 | AI23: 99.3 | AJ23: 332.67 | AL23: 4705.55 | AM23: 24609.21
B24: Office Expenses | C24: =SUM(D24:S24)-P24-L24-H24-D24 -> 24907.84 | D24: =SUM(E24:G24) -> 0 | H24: =SUM(I24:K24) -> 0 | L24: =SUM(M24:O24) -> 0 | P24: =SUM(Q24:S24) -> 24907.84 | R24: 7342.16 | S24: 17565.68 | T24: =SUM(U24:AJ24)-AG24-AC24-Y24-U24 -> 46991.43 | U24: =SUM(V24:X24) -> 23520.55 | V24: 3827.91 | W24: 9629.94 | X24: 10062.7 | Y24: =SUM(Z24:AB24) -> 12223.31 | Z24: 641.74 | AA24: 2711.91 | AB24: 8869.66 | AC24: =SUM(AD24:AF24) -> 11113.66 | AD24: 3687.1 | AE24: 3555.84 | AF24: 3870.72 | AG24: =SUM(AH24:AJ24) -> 133.91 | AH24: 0 | AI24: 133.91 | AJ24: 0 | AL24: 0 | AM24: 481
B25: Office Repair & Maintenance Expense | C25: =SUM(D25:S25)-P25-L25-H25-D25 -> 2985 | D25: =SUM(E25:G25) -> 0 | H25: =SUM(I25:K25) -> 0 | L25: =SUM(M25:O25) -> 0 | P25: =SUM(Q25:S25) -> 2985 | R25: 1560 | S25: 1425 | T25: =SUM(U25:AJ25)-AG25-AC25-Y25-U25 -> 16428.24 | U25: =SUM(V25:X25) -> 8126.67 | V25: 3560 | W25: 760 | X25: 3806.67 | Y25: =SUM(Z25:AB25) -> 8301.57 | Z25: 4237.61 | AA25: 4063.96
B26: Travel Expense | C26: =SUM(D26:S26)-P26-L26-H26-D26 -> 3957.14 | D26: =SUM(E26:G26) -> 0 | H26: =SUM(I26:K26) -> 0 | L26: =SUM(M26:O26) -> 0 | P26: =SUM(Q26:S26) -> 3957.14 | R26: 1007.81 | S26: 2949.33 | T26: =SUM(U26:AJ26)-AG26-AC26-Y26-U26 -> 17063.53 | U26: =SUM(V26:X26) -> 4459.33 | V26: 1943.78 | W26: 1292.13 | X26: 1223.42 | Y26: =SUM(Z26:AB26) -> 857.98 | Z26: 812.75 | AA26: 0 | AB26: 45.23 | AC26: =SUM(AD26:AF26) -> 3180.56 | AD26: 343.75 | AE26: 457.09 | AF26: 2379.72 | AG26: =SUM(AH26:AJ26) -> 8565.66 | AH26: 5067 | AI26: 3498.66 | AJ26: 0 | AL26: 3750 | AM26: 29931.99
B27: Printing and Stationery | C27: =SUM(D27:S27)-P27-L27-H27-D27 -> 702.7 | D27: =SUM(E27:G27) -> 0 | H27: =SUM(I27:K27) -> 0 | L27: =SUM(M27:O27) -> 0 | P27: =SUM(Q27:S27) -> 702.7 | R27: 359.54 | S27: 343.16 | T27: =SUM(U27:AJ27)-AG27-AC27-Y27-U27 -> 8193.6 | U27: =SUM(V27:X27) -> 2051 | V27: 0 | W27: 671 | X27: 1380 | Y27: =SUM(Z27:AB27) -> 4360.61 | Z27: 46 | AA27: 3717.22 | AB27: 597.39 | AC27: =SUM(AD27:AF27) -> 1671.99 | AD27: 1219.99 | AE27: 452 | AF27: 0 | AG27: =SUM(AH27:AJ27) -> 110 | AH27: 0 | AI27: 0 | AJ27: 110 | AL27: 241 | AM27: 4591.36
B28: Rent Expense (G&A) | C28: =SUM(D28:S28)-P28-L28-H28-D28 -> 33396.49 | D28: =SUM(E28:G28) -> 0 | H28: =SUM(I28:K28) -> 0 | L28: =SUM(M28:O28) -> 0 | P28: =SUM(Q28:S28) -> 33396.49 | R28: 10311.48 | S28: 23085.01 | T28: =SUM(U28:AJ28)-AG28-AC28-Y28-U28 -> 303572.58 | U28: =SUM(V28:X28) -> 71280.02 | V28: 23085.01 | W28: 24097.51 | X28: 24097.5 | Y28: =SUM(Z28:AB28) -> 74907.58 | Z28: 24097.5 | AA28: 24579.25 | AB28: 26230.83 | AC28: =SUM(AD28:AF28) -> 78692.49 | AD28: 26230.83 | AE28: 26230.83 | AF28: 26230.83 | AG28: =SUM(AH28:AJ28) -> 78692.49 | AH28: 26230.83 | AI28: 26230.83 | AJ28: 26230.83 | AL28: 32096.09 | AM28: 127377.94
B29: Meals and Entertainment | C29: =SUM(D29:S29)-P29-L29-H29-D29 -> 8019.85 | D29: =SUM(E29:G29) -> 0 | H29: =SUM(I29:K29) -> 0 | L29: =SUM(M29:O29) -> 0 | P29: =SUM(Q29:S29) -> 8019.85 | R29: 4127.03 | S29: 3892.82 | T29: =SUM(U29:AJ29)-AG29-AC29-Y29-U29 -> 84957.26 | U29: =SUM(V29:X29) -> 14808.57 | V29: 5215.28 | W29: 4527.88 | X29: 5065.41 | Y29: =SUM(Z29:AB29) -> 21110.6 | Z29: 10439.41 | AA29: 6048.24 | AB29: 4622.95 | AC29: =SUM(AD29:AF29) -> 18776.74 | AD29: 5737.6 | AE29: 5781.48 | AF29: 7257.66 | AG29: =SUM(AH29:AJ29) -> 30261.35 | AH29: 14668.43 | AI29: 5604.42 | AJ29: 9988.5 | AL29: 3897.75 | AM29: 84744.32
B30: Audit & Consultancy expense | C30: =SUM(D30:S30)-P30-L30-H30-D30 -> 0 | D30: =SUM(E30:G30) -> 0 | H30: =SUM(I30:K30) -> 0 | L30: =SUM(M30:O30) -> 0 | P30: =SUM(Q30:S30) -> 0 | R30: 0 | S30: 0 | T30: =SUM(U30:AJ30)-AG30-AC30-Y30-U30 -> 35000 | U30: =SUM(V30:X30) -> 35000 | V30: 35000 | W30: 0 | X30: 0 | Y30: =SUM(Z30:AB30) -> 0 | Z30: 0 | AA30: 0 | AB30: 0 | AC30: =SUM(AD30:AF30) -> 0 | AD30: 0 | AE30: 0 | AF30: 0 | AG30: =SUM(AH30:AJ30) -> 0 | AH30: 0 | AI30: 0 | AJ30: 0 | AL30: 17500 | AM30: 42500
B31: Communication Exp - Mobile & Internet | C31: =SUM(D31:S31)-P31-L31-H31-D31 -> 18883.31 | D31: =SUM(E31:G31) -> 0 | H31: =SUM(I31:K31) -> 0 | L31: =SUM(M31:O31) -> 0 | P31: =SUM(Q31:S31) -> 18883.31 | R31: 6771.94 | S31: 12111.37 | T31: =SUM(U31:AJ31)-AG31-AC31-Y31-U31 -> 63743.66 | U31: =SUM(V31:X31) -> 29094.34 | V31: 8861 | W31: 6890.44 | X31: 13342.9 | Y31: =SUM(Z31:AB31) -> 17709.52 | Z31: 9880.72 | AA31: 4099.12 | AB31: 3729.68 | AC31: =SUM(AD31:AF31) -> 8861.41 | AD31: 3298.5 | AE31: 2802.08 | AF31: 2760.83 | AG31: =SUM(AH31:AJ31) -> 8078.39 | AH31: 5361.89 | AI31: 0 | AJ31: 2716.5 | AL31: 2142.64 | AM31: 24754.9
B32: Subscriptions & Memberships | C32: =SUM(D32:S32)-P32-L32-H32-D32 -> 92577.27 | D32: =SUM(E32:G32) -> 0 | H32: =SUM(I32:K32) -> 0 | L32: =SUM(M32:O32) -> 0 | P32: =SUM(Q32:S32) -> 92577.27 | R32: 52003.09 | S32: 40574.18 | T32: =SUM(U32:AJ32)-AG32-AC32-Y32-U32 -> 479512.13 | U32: =SUM(V32:X32) -> 189181.08 | V32: 73293.74 | W32: 26969.17 | X32: 88918.17 | Y32: =SUM(Z32:AB32) -> 151194.2 | Z32: 63284.6 | AA32: 20005.06 | AB32: 67904.54 | AC32: =SUM(AD32:AF32) -> 80100.2 | AD32: 38653.92 | AE32: 24451.97 | AF32: 16994.31 | AG32: =SUM(AH32:AJ32) -> 59036.65 | AH32: 10881.39 | AI32: 35723.87 | AJ32: 12431.39 | AL32: 22184.55 | AM32: 227892.91
B33: Events & Activity Expense | C33: =SUM(D33:S33)-P33-L33-H33-D33 -> 13566.86 | D33: =SUM(E33:G33) -> 0 | L33: =SUM(M33:O33) -> 0 | P33: =SUM(Q33:S33) -> 13566.86 | R33: 4007.5 | S33: 9559.36 | T33: =SUM(U33:AJ33)-AG33-AC33-Y33-U33 -> 43313.02 | U33: =SUM(V33:X33) -> 43313.02 | V33: 22232.75 | W33: 2237.35 | X33: 18842.92
B34: Team Building Activities | C34: =SUM(D34:S34)-P34-L34-H34-D34 -> 0 | D34: =SUM(E34:G34) -> 0 | L34: =SUM(M34:O34) -> 0 | P34: =SUM(Q34:S34) -> 0 | R34: 0 | S34: 0 | T34: =SUM(U34:AJ34)-AG34-AC34-Y34-U34 -> 1200 | U34: =SUM(V34:X34) -> 1200 | V34: 0 | W34: 0 | X34: 1200
B35: Penny Difference | C35: =SUM(D35:S35)-P35-L35-H35-D35 -> 6.3 | D35: =SUM(E35:G35) -> 0 | H35: =SUM(I35:K35) -> 0 | L35: =SUM(M35:O35) -> 0 | P35: =SUM(Q35:S35) -> 6.3 | R35: 0 | S35: 6.3 | T35: =SUM(U35:AJ35)-AG35-AC35-Y35-U35 -> 8.16 | U35: =SUM(V35:X35) -> 0.65 | V35: 0 | W35: 0 | X35: 0.65 | Y35: =SUM(Z35:AB35) -> 3.51 | Z35: 0.77 | AA35: 2.77 | AB35: -0.03 | AC35: =SUM(AD35:AF35) -> 4 | AD35: 2.94 | AE35: 0.01 | AF35: 1.05 | AG35: =SUM(AH35:AJ35) -> 0 | AH35: 0 | AI35: 0 | AJ35: 0 | AL35: 0.24 | AM35: -103.77
B36: Low Value Assets | C36: =SUM(D36:S36)-P36-L36-H36-D36 -> 849 | D36: =SUM(E36:G36) -> 0 | H36: =SUM(I36:K36) -> 0 | L36: =SUM(M36:O36) -> 0 | P36: =SUM(Q36:S36) -> 849 | R36: 0 | S36: 849 | T36: =SUM(U36:AJ36)-AG36-AC36-Y36-U36 -> 56438.33 | U36: =SUM(V36:X36) -> 22771.62 | V36: 1665.09 | W36: 2350.4 | X36: 18756.13 | Y36: =SUM(Z36:AB36) -> 13695.24 | Z36: 8226.53 | AA36: 1562.62 | AB36: 3906.09 | AC36: =SUM(AD36:AF36) -> 5351.42 | AD36: 4772.18 | AE36: 157.5 | AF36: 421.74 | AG36: =SUM(AH36:AJ36) -> 14620.05 | AH36: 974.78 | AI36: 8417.44 | AJ36: 5227.83 | AL36: 729 | AM36: 5344.88
B37: Charity | C37: =SUM(D37:S37)-P37-L37-H37-D37 -> 4000 | D37: =SUM(E37:G37) -> 0 | H37: =SUM(I37:K37) -> 0 | L37: =SUM(M37:O37) -> 0 | P37: =SUM(Q37:S37) -> 4000 | R37: 2000 | S37: 2000 | T37: =SUM(U37:AJ37)-AG37-AC37-Y37-U37 -> 31000 | U37: =SUM(V37:X37) -> 13000 | V37: 2000 | W37: 2000 | X37: 9000 | Y37: =SUM(Z37:AB37) -> 6000 | Z37: 2000 | AA37: 2000 | AB37: 2000 | AC37: =SUM(AD37:AF37) -> 6000 | AD37: 2000 | AE37: 2000 | AF37: 2000 | AG37: =SUM(AH37:AJ37) -> 6000 | AH37: 2000 | AI37: 2000 | AJ37: 2000 | AL37: 2000 | AM37: 10000
B38: Witholding Tax | C38: =SUM(D38:S38)-P38-L38-H38-D38 -> 0 | D38: =SUM(E38:G38) -> 0 | H38: =SUM(I38:K38) -> 0 | L38: =SUM(M38:O38) -> 0 | P38: =SUM(Q38:S38) -> 0 | R38: 0 | S38: 0 | T38: =SUM(U38:AJ38)-AG38-AC38-Y38-U38 -> 0 | U38: =SUM(V38:X38) -> 0 | V38: 0 | W38: 0 | X38: 0 | Y38: =SUM(Z38:AB38) -> 0 | Z38: 0 | AA38: 0 | AB38: 0 | AC38: =SUM(AD38:AF38) -> 0 | AD38: 0 | AE38: 0 | AF38: 0 | AI38: 0 | AJ38: 0 | AL38: 0 | AM38: 47608.81
B39: Selling Expenses | C39: =SUM(C40:C55) -> 160268.02 | D39: =SUM(D40:D55) -> 0 | E39: =SUM(E40:E55) -> 0 | F39: =SUM(F40:F55) -> 0 | G39: =SUM(G40:G55) -> 0 | H39: =SUM(H40:H55) -> 0 | I39: =SUM(I40:I55) -> 0 | J39: =SUM(J40:J55) -> 0 | ... AJ39: =SUM(AJ40:AJ55) -> 56646.93 | AL39: =SUM(AL40:AL55) -> 58404.56 | AM39: =SUM(AM40:AM55) -> 591969.18
B40: Business travel expenses | C40: =SUM(D40:S40)-P40-L40-H40-D40 -> 17256.72 | D40: =SUM(E40:G40) -> 0 | H40: =SUM(I40:K40) -> 0 | L40: =SUM(M40:O40) -> 0 | P40: =SUM(Q40:S40) -> 17256.72 | R40: 6068.14 | S40: 11188.58 | T40: =SUM(U40:AJ40)-AG40-AC40-Y40-U40 -> 58476.06 | U40: =SUM(V40:X40) -> 17955.61 | V40: 17621.22 | W40: -11004.45 | X40: 11338.84 | Y40: =SUM(Z40:AB40) -> 11900.03 | Z40: 6977.04 | AA40: 1891.56 | AB40: 3031.43 | AC40: =SUM(AD40:AF40) -> 12382.85 | AD40: 4361 | AE40: 4405.15 | AF40: 3616.7 | AG40: =SUM(AH40:AJ40) -> 16237.57 | AH40: 952 | AI40: 4372.08 | AJ40: 10913.49 | AL40: 18271.01 | AM40: 96381.63
B41: Business Accommodation Expense | C41: =SUM(D41:S41)-P41-L41-H41-D41 -> 17753.03 | D41: =SUM(E41:G41) -> 0 | H41: =SUM(I41:K41) -> 0 | L41: =SUM(M41:O41) -> 0 | P41: =SUM(Q41:S41) -> 17753.03 | R41: 16460.27 | S41: 1292.76 | T41: =SUM(U41:AJ41)-AG41-AC41-Y41-U41 -> 127516.15 | U41: =SUM(V41:X41) -> 40679.4 | V41: 36312.33 | W41: -2227.86 | X41: 6594.93 | Y41: =SUM(Z41:AB41) -> 49747.17 | Z41: 28716.5 | AA41: 11602.53 | AB41: 9428.14 | AC41: =SUM(AD41:AF41) -> 23508.19 | AD41: 13811.06 | AE41: 8712.51 | AF41: 984.62 | AG41: =SUM(AH41:AJ41) -> 13581.39 | AH41: 22.61 | AI41: 5592.49 | AJ41: 7966.29
B42: Collection Commission | C42: =SUM(D42:S42)-P42-L42-H42-D42 -> 0 | D42: =SUM(E42:G42) -> 0 | H42: =SUM(I42:K42) -> 0 | L42: =SUM(M42:O42) -> 0 | P42: =SUM(Q42:S42) -> 0 | R42: 0 | S42: 0 | T42: =SUM(U42:AJ42)-AG42-AC42-Y42-U42 -> 0 | U42: =SUM(V42:X42) -> 0 | V42: 0 | W42: 0 | X42: 0 | Y42: =SUM(Z42:AB42) -> 0 | Z42: 0 | AA42: 0 | AB42: 0 | AC42: =SUM(AD42:AF42) -> 0 | AD42: 0 | AE42: 0 | AF42: 0 | AG42: =SUM(AH42:AJ42) -> 0 | AH42: 0 | AI42: 0 | AJ42: 0 | AL42: 4797.13 | AM42: 61150.53
B43: Dinar commission | C43: =SUM(D43:S43)-P43-L43-H43-D43 -> 0 | D43: =SUM(E43:G43) -> 0 | H43: =SUM(I43:K43) -> 0 | L43: =SUM(M43:O43) -> 0 | P43: =SUM(Q43:S43) -> 0 | R43: 0 | S43: 0 | T43: =SUM(U43:AJ43)-AG43-AC43-Y43-U43 -> 2578.26 | U43: =SUM(V43:X43) -> 0 | V43: 0 | W43: 0 | X43: 0 | Y43: =SUM(Z43:AB43) -> 0 | Z43: 0 | AA43: 0 | AB43: 0 | AC43: =SUM(AD43:AF43) -> 1600 | AD43: 0 | AE43: 0 | AF43: 1600 | AG43: =SUM(AH43:AJ43) -> 978.26 | AH43: 0 | AI43: 978.26 | AJ43: 0 | AL43: 0 | AM43: 8543.48
B44: New customer commission | C44: =SUM(D44:S44)-P44-L44-H44-D44 -> 13000 | D44: =SUM(E44:G44) -> 0 | H44: =SUM(I44:K44) -> 0 | L44: =SUM(M44:O44) -> 0 | P44: =SUM(Q44:S44) -> 13000 | R44: 5000 | S44: 8000 | T44: =SUM(U44:AJ44)-AG44-AC44-Y44-U44 -> 127000 | U44: =SUM(V44:X44) -> 39000 | V44: 7500 | W44: 21500 | X44: 10000 | Y44: =SUM(Z44:AB44) -> 35000 | Z44: 6000 | AA44: 7000 | AB44: 22000 | AC44: =SUM(AD44:AF44) -> 34000 | AD44: 13000 | AE44: 6000 | AF44: 15000 | AG44: =SUM(AH44:AJ44) -> 19000 | AH44: 7000 | AI44: 7000 | AJ44: 5000 | AL44: 5000 | AM44: 44606.18
B45: New Approved client Commission (SDA) | C45: =SUM(D45:S45)-P45-L45-H45-D45 -> 5500 | D45: =SUM(E45:G45) -> 0 | H45: =SUM(I45:K45) -> 0 | L45: =SUM(M45:O45) -> 0 | P45: =SUM(Q45:S45) -> 5500 | R45: 2500 | S45: 3000 | T45: =SUM(U45:AJ45)-AG45-AC45-Y45-U45 -> 55000 | U45: =SUM(V45:X45) -> 17200 | V45: 3400 | W45: 6300 | X45: 7500 | Y45: =SUM(Z45:AB45) -> 14200 | Z45: 4900 | AA45: 3700 | AB45: 5600 | AC45: =SUM(AD45:AF45) -> 10100 | AD45: 5400 | AE45: 1700 | AF45: 3000 | AG45: =SUM(AH45:AJ45) -> 13500 | AH45: 7000 | AI45: 5000 | AJ45: 1500
B46: Sales Commission-Employee | C46: =SUM(D46:S46)-P46-L46-H46-D46 -> 54400.79 | D46: =SUM(E46:G46) -> 0 | H46: =SUM(I46:K46) -> 0 | L46: =SUM(M46:O46) -> 0 | P46: =SUM(Q46:S46) -> 54400.79 | R46: 30932.16 | S46: 23468.63 | T46: =SUM(U46:AJ46)-AG46-AC46-Y46-U46 -> 323555.43 | U46: =SUM(V46:X46) -> 93218.17 | V46: 29491.08 | W46: 36269.68 | X46: 27457.41 | Y46: =SUM(Z46:AB46) -> 102093.22 | Z46: 19446.8 | AA46: 14722.76 | AB46: 67923.66 | AC46: =SUM(AD46:AF46) -> 71738.54 | AD46: 26518.85 | AE46: 19610.97 | AF46: 25608.72 | AG46: =SUM(AH46:AJ46) -> 56505.5 | AH46: 20701.1 | AI46: 19876.4 | AJ46: 15928
...

Sheet BS Feb KSA
D4: -1 | P4: -1
B6: STATEMENT OF FINANCIAL POSITION (KSA SAR) | D6: 46387 | E6: 46356 | F6: 46326 | G6: 46295 | H6: 46265 | I6: 46234 | J6: 46203 | K6: 46173 | L6: 46142 | M6: 46112 | N6: 46081 | O6: 46053 | P6: 46022 | Q6: 45991 | R6: 45961 | S6: 45930 | T6: 45900 | U6: 45869 | V6: 45838 | W6: 45808 | X6: 45777 | Y6: 45747 | Z6: 45716 | AA6: 45688 | AC6: 45291 | AD6: 45657
B7: AS OF 28 Feb 2026
B8: ASSETS
B10: Cash and Bank Balances | D10: =SUM(D11:D30) -> 0 | E10: =SUM(E11:E30) -> 0 | F10: =SUM(F11:F30) -> 0 | G10: =SUM(G11:G30) -> 0 | H10: =SUM(H11:H30) -> 0 | I10: =SUM(I11:I31) -> 0 | J10: =SUM(J11:J31) -> 0 | K10: =SUM(K11:K30) -> 0 | L10: =SUM(L11:L29) -> 0 | M10: =SUM(M11:M29) -> 0 | N10: =SUM(N11:N30) -> 21114591 | O10: =SUM(O11:O30) -> 10108437 | P10: =SUM(P11:P30) -> 5193846.4 | Q10: =SUM(Q11:Q30) -> 2433842.9 | R10: =SUM(R11:R30) -> 8732807.8 | S10: =SUM(S11:S30) -> 3751151.1 | T10: =SUM(T11:T30) -> 3703439.9 | U10: =SUM(U11:U31) -> 2071152.1 | V10: =SUM(V11:V31) -> 6618299.3 | W10: =SUM(W11:W30) -> 6035298.9 | X10: =SUM(X11:X29) -> 6828123.3 | Y10: =SUM(Y11:Y29) -> 4763461.8 | Z10: =SUM(Z11:Z29) -> 11306999 | AA10: =SUM(AA11:AA29) -> 5535732.6 | AC10: 3957363.2 | AD10: =SUM(AD11:AD29) -> 10448735
B11: ALINMA BILDNW FEE | C11: =B11 -> ALINMA BILDNW FEE | N11: 0 | O11: 0 | P11: 0 | Q11: 0 | R11: 0 | S11: 0 | T11: 0 | U11: 0 | V11: 0 | W11: 0 | X11: 0 | Y11: 0 | Z11: 0 | AA11: 0 | AC11: 0 | AD11: 0
B12: ALINMA BILDNW PROFIT | C12: =B12 -> ALINMA BILDNW PROFIT | N12: 0 | O12: 0 | P12: 0 | Q12: 0 | R12: 0 | S12: 0 | T12: 0 | U12: 0 | V12: 0 | W12: 0 | X12: 140074.92 | Y12: 140074.92 | Z12: 140074.92 | AA12: 140103.67 | AC12: 0 | AD12: 140103.67
B13: ALINMA CLIENT PROFIT | C13: =B13 -> ALINMA CLIENT PROFIT | N13: 0 | O13: 0 | P13: 0 | Q13: 0 | R13: 0 | S13: 0 | T13: 0 | U13: 0 | V13: 0 | W13: 0 | X13: 135818.27 | Y13: 135818.27 | Z13: 166814.23 | AA13: 166842.98 | AC13: 668024.87 | AD13: 166842.98
B14: ALINMA DINAR DEALs PROFIT | C14: =B14 -> ALINMA DINAR DEALs PROFIT | N14: 0 | O14: 0 | P14: 0 | Q14: 0 | R14: 0 | S14: 0 | T14: 0 | U14: 0 | V14: 0 | W14: 0 | X14: 91275.6 | Y14: 91275.6 | Z14: 91275.6 | AA14: 26086.96 | AC14: 0 | AD14: 30000
B15: ALINMA DINAR DEALs VAT | C15: =B15 -> ALINMA DINAR DEALs VAT | N15: 0 | O15: 0 | P15: 0 | Q15: 0 | R15: 0 | S15: 0 | T15: 0 | U15: 0 | V15: 0 | W15: 0 | X15: 0 | Y15: 0 | Z15: 0 | AA15: 0 | AC15: 43532.61 | AD15: 0
B16: ALINMA EQUITY | C16: =B16 -> ALINMA EQUITY | N16: 1597648.6 | O16: 843035.65 | P16: 477588.36 | Q16: =276114.21 -> 276114.21 | R16: =272657.47 -> 272657.47 | S16: 447636.35 | T16: 27033.82 | U16: 260341.61 | V16: 243984.07 | W16: 427314.42 | X16: 269658.08 | Y16: 792735.94 | Z16: 1482647.5 | AA16: 268408.67 | AC16: 767469.48 | AD16: 1315636.9
B17: ALINMA USD | C17: =B17 -> ALINMA USD | N17: 0 | O17: 0 | P17: 0 | Q17: 0 | R17: 0 | S17: 0 | T17: 0 | U17: 0 | V17: 0 | W17: 0 | X17: 0 | Y17: 0 | Z17: 0 | AA17: 0 | AC17: 0.44 | AD17: 0
B18: ALINMA VAT | C18: =B18 -> ALINMA VAT | N18: 2680.22 | O18: 1850.44 | P18: 1850.44 | Q18: 1850.44 | R18: 1495.53 | S18: 13439.92 | T18: 11985.57 | U18: 75189.77 | V18: 73991.63 | W18: 1.04 | X18: 216190.05 | Y18: 210463.42 | Z18: 200112.41 | AA18: 295015.01 | AC18: 90759.47 | AD18: 131821.9
B19: ALINMA-DEBT | C19: =B19 -> ALINMA-DEBT | N19: 9608915.4 | O19: 1845260.8 | P19: 324493.81 | Q19: 1328664.5 | R19: 6295570.3 | S19: 2340058.2 | T19: 3289226.9 | U19: 1660211.7 | V19: 6201976.1 | W19: 4513496.9 | X19: 5896394.3 | Y19: 3318463.4 | Z19: 9175560.6 | AA19: 4576535.8 | AC19: 2381669.3 | AD19: 8593232.1
B20: ANB-BILDNW TRADINGCOMPANY | C20: =B20 -> ANB-BILDNW TRADINGCOMPANY | N20: 706 | O20: 706 | P20: 706 | Q20: 706 | R20: 706 | S20: 706 | T20: 706 | U20: 706 | V20: 706 | W20: 706 | X20: 706 | Y20: 706 | Z20: 706 | AA20: 106 | AC20: 100.8 | AD20: 6
B21: Riyadh Bank | C21: =B21 -> Riyadh Bank | N21: 130.48 | O21: 130.48 | P21: 130.48 | Q21: 130.48 | R21: 130.48 | S21: 130.48 | T21: 130.48 | U21: 130.48 | V21: 130.48 | W21: 130.48 | X21: 130.48 | Y21: 130.48 | Z21: 130.48 | AA21: 130.48 | AC21: 6.31 | AD21: 30.48
B22: Saudi Awwal Bank (SAB)-5001 | C22: =B22 -> Saudi Awwal Bank (SAB)-5001 | N22: 9333530.6 | O22: 6837833.2 | P22: 161737.04 | Q22: 642122.4 | R22: 2001328.5 | S22: 749992.23 | T22: 100 | U22: 100 | V22: 100
B23: Saudi Awwal Bank (SAB)-5002 | C23: =B23 -> Saudi Awwal Bank (SAB)-5002 | N23: 449991.95 | O23: 449991.95 | P23: 2250000
B24: US Checking Account | C24: =B24 -> US Checking Account | N24: 0 | O24: 0 | P24: 0 | Q24: 0 | R24: 0 | S24: 0 | T24: 0 | U24: 0 | V24: 0 | W24: 0 | X24: 0 | Y24: 0 | Z24: 0 | AA24: 0 | AD24: 0
B25: anb - Tanmeya Debt Acct | C25: =B25 -> anb - Tanmeya Debt Acct | N25: 37094.8 | O25: 37094.8 | P25: 37094.8 | Q25: 37094.8 | R25: 37094.8 | S25: 37094.8 | T25: 37094.8 | U25: 37094.8 | V25: 37094.8 | W25: 37094.8 | X25: 37094.8 | Y25: 37094.8 | Z25: 37094.8 | AA25: 37094.8 | AD25: 37094.8
B26: Simplifi | C26: =B26 -> Simplifi | N26: 7822.62 | O26: 7822.62 | P26: 7822.62 | Q26: 7822.62 | R26: 7822.62 | S26: 7822.62 | T26: 7822.62 | U26: 7822.62 | V26: 7822.62 | W26: 7822.62 | X26: 7822.62 | Y26: 7822.62 | Z26: 7822.62 | AA26: 7822.62 | AD26: 7822.62
B27: SiFi Wallet | C27: =B27 -> SiFi Wallet | N27: -3233.66 | O27: 5088.47 | P27: 19073.71 | Q27: 22604.65 | R27: 13409.11 | S27: 22387.23 | T27: 15814.78 | U27: 20975.45 | V27: 41534 | W27: 37494.58 | X27: 31308.32 | Y27: 25000
B28: Sinking Fund Account | C28: =B28 -> Sinking Fund Account | N28: 104755.43 | O28: 104755.43 | P28: 104755.43 | Q28: 104755.43 | R28: 104755.43 | S28: 104755.43 | T28: 276809.23
B29: Petty Cash | C29: =B29 -> Petty Cash | N29: 10841.71 | O29: 11186.71 | P29: 17506.71 | Q29: 20969.21 | R29: 6863.71 | S29: 36154.71 | T29: 36715.69 | U29: 8579.6 | V29: 10959.6 | W29: 2491.77 | X29: 1649.94 | Y29: 3876.4 | Z29: 4759.4 | AA29: 17585.52 | AC29: 5800 | AD29: 26143.5
B30: Control/ Adjustment | C30: =B30 -> Control/ Adjustment | N30: -36293.05 | O30: -36319.83 | P30: 1791087 | Q30: -8991.84 | R30: -9026.21 | S30: -9026.88 | T30: 0 | U30: -0.01 | V30: 0 | W30: 1008746.3
B32: Trade Receivables (net) | D32: =SUM(D33:D34) -> 0 | E32: =SUM(E33:E34) -> 0 | F32: =SUM(F33:F34) -> 0 | G32: =SUM(G33:G34) -> 0 | H32: =SUM(H33:H34) -> 0 | I32: =SUM(I33:I34) -> 0 | J32: =SUM(J33:J34) -> 0 | K32: =SUM(K33:K34) -> 0 | ... AA32: =SUM(AA33:AA34) -> 41571833 | AC32: 25749560 | AD32: =SUM(AD33:AD34) -> 39178410
B33: Trade Receivables - Gross | C33: Accounts Receivable | N33: 80843930 | O33: 79176075 | P33: 74207264 | Q33: 67634653 | R33: 60700920 | S33: 58161987 | T33: 60295260 | U33: 63272134 | V33: 53991265 | W33: 55060572 | X33: 54945077 | Y33: 56093249 | Z33: 48931754 | AA33: 42002842 | AC33: 25749560 | AD33: 39584419
B34: Closing Provision for doubtful Accounts | C34: Provision for Doubtful Debts | N34: -1152044.2 | O34: -1152044.2 | P34: -1152044.2 | Q34: -678587.63 | R34: -678587.63 | S34: -678587.63 | T34: -1366836 | U34: -1341836 | V34: -556009 | W34: -531009 | X34: =506009*(-1) -> -506009 | Y34: =481009*(-1) -> -481009 | Z34: =456009*(-1) -> -456009 | AA34: =431009*(-1) -> -431009 | AC34: 0 | AD34: -406009
B36: Prepaid Expenses & Other recievables | D36: =SUM(D37:D52) -> 0 | E36: =SUM(E37:E52) -> 0 | F36: =SUM(F37:F52) -> 0 | G36: =SUM(G37:G52) -> 0 | H36: =SUM(H37:H52) -> 0 | I36: =SUM(I37:I52) -> 0 | J36: =SUM(J37:J52) -> 0 | K36: =SUM(K37:K52) -> 0 | L36: =SUM(L37:L52) -> 0 | M36: =SUM(M37:M53) -> 0 | N36: =SUM(N37:N52) -> 19015730 | O36: =SUM(O37:O52) -> 14043475 | P36: =SUM(P37:P52) -> 16759490 | Q36: =SUM(Q37:Q52) -> 13478509 | R36: =SUM(R37:R52) -> 12698551 | S36: =SUM(S37:S52) -> 12990816 | T36: =SUM(T37:T52) -> 9109504.1 | U36: =SUM(U37:U52) -> 8959889.8 | ... X36: =SUM(X37:X52) -> 3623673.8 | Y36: =SUM(Y37:Y53) -> 1466553.8 | Z36: =SUM(Z37:Z53) -> 1750361.7 | AA36: =SUM(AA37:AA53) -> 3197061.1 | AC36: 288133.91 | AD36: =SUM(AD37:AD53) -> 1263663.6
B37: Prepaid Vendors | C37: Prepaid vendors Bildnw Inc. | N37: 15925680 | O37: 12539611 | P37: 12629040 | Q37: 11912369 | R37: 11075859 | S37: 11332316 | T37: 7411466.9 | U37: 7284763.8 | V37: 6372603.1 | W37: 3515144.3 | X37: 2040088.9 | Y37: 0 | Z37: 0 | AA37: 0 | AC37: -8.05 | AD37: 0
B38: Prepaid Accommodation Rent Expense | C38: =B38 -> Prepaid Accommodation Rent Expense | N38: 10416.67 | O38: 0 | P38: 0 | Q38: 0 | R38: 0 | S38: 0 | T38: 0 | U38: 10666.69 | V38: 12800.02 | W38: 2133.35 | X38: 4266.68 | Y38: 6400.01 | Z38: 8533.34 | AA38: 10666.67 | AD38: 0
B39: Prepaid Financing Expense | C39: =B39 -> Prepaid Financing Expense | N39: 18888.91 | O39: 20000.02 | P39: 21111.13 | Q39: 22222.24 | R39: 23333.35 | S39: 24444.46 | T39: 25555.57 | U39: 26666.68 | V39: 27777.79 | W39: 28888.9 | X39: 30000.01 | Y39: 31111.12 | Z39: 32222.23 | AA39: 33333.34 | AD39: 34444.45
B40: Prepaid Govt. Legal Expense | C40: =B40 -> Prepaid Govt. Legal Expense | N40: 9110.02 | O40: 16878.35 | P40: 24646.68 | Q40: 4915.01 | R40: 7683.34 | S40: 10451.67 | T40: 10000 | U40: 12500 | V40: 0 | W40: 5416.65 | X40: 10833.32 | Y40: 16249.99 | Z40: 21666.66 | AA40: 27083.33 | AD40: 32500
B41: Prepaid IT Subscriptions Expense | C41: =B41 -> Prepaid IT Subscriptions Expense | N41: 64783.94 | O41: 41447.61 | P41: 48628.78 | Q41: 55809.95 | R41: 68815.01 | S41: 81820.07 | T41: 58825.13 | U41: 54061.19 | V41: 63623 | W41: 44747.31 | X41: 44921.62 | Y41: 49960.93 | Z41: 56792.32 | AA41: 63623.71 | AD41: 70455.1
B42: Prepaid Office Rent Expense | C42: =B42 -> Prepaid Office Rent Expense | N42: 24684.44 | O42: 0 | P42: 0 | Q42: 0 | R42: 24097.51 | S42: 48195.01 | T42: 72292.51 | U42: 96390.01 | V42: 5062.51 | W42: 6075.01 | X42: 30172.51 | Y42: 54270.01 | Z42: 78367.51 | AA42: 102465.01 | AD42: 126562.51
B43: Prepaid Other Expense | C43: =B43 -> Prepaid Other Expense | N43: 24637.46 | O43: 53727.44 | P43: 77440.92 | Q43: 105418.32 | R43: 133395.72 | S43: 161373.12 | T43: 182258.52 | U43: 181205.77 | V43: 194719.59 | W43: 213412.41 | X43: 186011.13 | Y43: 8171.65 | Z43: 23200.23 | AA43: 43267.67 | AC43: 71234.03 | AD43: 75416.45
B44: Prepaid Employment Expense (Iqama) | C44: =B44 -> Prepaid Employment Expense (Iqama) | N44: 45708.43 | O44: 53291.74 | P44: 41475.05 | Q44: 36125.03 | R44: 22666.68 | S44: 7791.67
B45: Fund Raising Expense receivable | C45: =B45 -> Fund Raising Expense receivable | N45: 4837 | O45: 4837 | P45: 4837 | Q45: 4837 | R45: 4837 | S45: 4837 | T45: 4837 | U45: 4837 | V45: 4837 | W45: 0 | X45: 0 | Y45: 0 | Z45: 215625 | AA45: 0
B46: Employee Receivable | C46: Employee Advance | N46: 210516.54 | O46: 149408.21 | P46: 125999.88 | Q46: 128774.9 | R46: 139325.6 | S46: 127799.47 | T46: 154230.58 | U46: 128380.2 | V46: 97432.82 | W46: 74575.87 | X46: 95688.5 | Y46: 116972.13 | Z46: 133805.47 | AA46: 134197.37 | AC46: 57592.47 | AD46: 150690.88
B47: Security deposits | C47: =B47 -> Security deposits | N47: 11446 | O47: 11446 | P47: 11446 | Q47: 11446 | R47: 11446 | S47: 11446 | T47: 11446 | U47: 2000 | V47: 2000 | W47: 2000 | X47: 2000 | Y47: 2000 | Z47: 2000 | AA47: 2000 | AC47: 1500 | AD47: 2000
...

Sheet IS Feb USA
B7: INCOME STATEMENT (US SAR) | C7: YTD | D7: Q4 | E7: MTD | F7: MTD | G7: MTD | H7: Q3 | I7: MTD | J7: MTD | K7: MTD | L7: Q2 | M7: MTD | N7: MTD | O7: MTD | P7: Q1 | Q7: MTD | R7: MTD | S7: MTD | T7: YTD | U7: Q4 | V7: MTD | W7: MTD | X7: MTD | Y7: Q3 | Z7: MTD | AA7: MTD | AB7: MTD | AC7: Q2 | AD7: MTD | AE7: MTD | AF7: MTD | AG7: Q1 | AH7: MTD | AI7: MTD | AJ7: MTD | AL7: MTD | AM7: YTD
B8: FOR THE PERIOD 28 Feb 2026 | C8: 46387 | D8: 2026 | E8: 46387 | F8: 46356 | G8: 46326 | H8: 2026 | I8: 46295 | J8: 46265 | K8: 46234 | L8: 2026 | M8: 46203 | N8: 46173 | O8: 46142 | P8: 2026 | Q8: 46112 | R8: 46081 | S8: 46053 | T8: 46022 | U8: 2025 | V8: 46022 | W8: 45991 | X8: 45961 | Y8: 2025 | Z8: 45930 | AA8: 45900 | AB8: 45869 | AC8: 2025 | AD8: 45838 | AE8: 45808 | AF8: 45777 | AG8: 2025 | AH8: 45747 | AI8: 45716 | AJ8: 45688 | AL8: 45657 | AM8: 45657
B10: Sales | C10: =SUM(D10:S10)-P10-L10-H10-D10 -> 0 | D10: =SUM(E10:G10) -> 0 | H10: =SUM(I10:K10) -> 0 | I10: 0 | J10: 0 | K10: 0 | L10: =SUM(M10:O10) -> 0 | M10: 0 | N10: 0 | O10: 0 | P10: =SUM(Q10:S10) -> 0 | Q10: 0 | R10: 0 | S10: 0 | T10: =SUM(U10:AJ10)-AG10-AC10-Y10-U10 -> 0 | U10: =SUM(V10:X10) -> 0 | Y10: =SUM(Z10:AB10) -> 0 | Z10: 0 | AA10: 0 | AB10: 0 | AC10: =SUM(AD10:AF10) -> 0 | AD10: 0 | AE10: 0 | AF10: 0 | AG10: =SUM(AH10:AJ10) -> 0 | AH10: 0 | AI10: 0 | AJ10: 0 | AM10: 0
B11: Sales Discount | H11: =SUM(I11:K11) -> 0 | K11: 0 | L11: =SUM(M11:O11) -> 0 | M11: 0 | O11: 0 | S11: 0 | Y11: =SUM(Z11:AB11) -> 0 | AB11: 0 | AC11: =SUM(AD11:AF11) -> 0 | AD11: 0 | AF11: 0
B12: Cost of Goods Sold | C12: =SUM(D12:S12)-P12-L12-H12-D12 -> 0 | D12: =SUM(E12:G12) -> 0 | H12: =SUM(I12:K12) -> 0 | I12: 0 | J12: 0 | K12: 0 | L12: =SUM(M12:O12) -> 0 | M12: 0 | N12: 0 | O12: 0 | P12: =SUM(Q12:S12) -> 0 | Q12: 0 | R12: 0 | S12: 0 | T12: =SUM(U12:AJ12)-AG12-AC12-Y12-U12 -> 0 | U12: =SUM(V12:X12) -> 0 | Y12: =SUM(Z12:AB12) -> 0 | Z12: 0 | AA12: 0 | AB12: 0 | AC12: =SUM(AD12:AF12) -> 0 | AD12: 0 | AE12: 0 | AF12: 0 | AG12: =SUM(AH12:AJ12) -> 0 | AH12: 0 | AI12: 0 | AJ12: 0 | AM12: 0
B13: Purchase Discounts | C13: =SUM(D13:S13)-P13-L13-H13-D13 -> 0 | D13: =SUM(E13:G13) -> 0 | H13: =SUM(I13:K13) -> 0 | I13: 0 | J13: 0 | K13: 0 | L13: =SUM(M13:O13) -> 0 | M13: 0 | N13: 0 | O13: 0 | P13: =SUM(Q13:S13) -> 0 | Q13: 0 | R13: 0 | S13: 0 | T13: =SUM(U13:AJ13)-AG13-AC13-Y13-U13 -> 0 | U13: =SUM(V13:X13) -> 0 | Y13: =SUM(Z13:AB13) -> 0 | Z13: 0 | AA13: 0 | AB13: 0 | AC13: =SUM(AD13:AF13) -> 0 | AD13: 0 | AE13: 0 | AF13: 0 | AG13: =SUM(AH13:AJ13) -> 0 | AH13: 0 | AI13: 0 | AJ13: 0 | AM13: 0
B14: Gross Profit / (Loss) | C14: =+C10-C12 -> 0 | D14: =+D10-D12 -> 0 | E14: =+E10-E12 -> 0 | F14: =+F10-F12 -> 0 | G14: =+G10-G12 -> 0 | H14: =+H10-H12 -> 0 | I14: =+I10-I12 -> 0 | J14: =+J10-J12 -> 0 | K14: 0 | L14: =+L10-L12 -> 0 | M14: =+M10-M12 -> 0 | N14: =+N10-N12 -> 0 | O14: =+O10-O12 -> 0 | P14: =+P10-P12 -> 0 | Q14: =+Q10-Q12 -> 0 | R14: =+R10-R12 -> 0 | S14: =+S10-S12 -> 0 | ... AA14: =+AA10-AA12 -> 0 | AB14: 0 | AC14: =+AC10-AC12 -> 0 | AD14: =+AD10-AD12 -> 0 | AE14: =+AE10-AE12 -> 0 | AF14: =+AF10-AF12 -> 0 | AG14: =+AG10-AG12 -> 0 | AH14: =+AH10-AH12 -> 0 | AI14: =+AI10-AI12 -> 0 | AJ14: =+AJ10-AJ12 -> 0 | AL14: =+AL10-AL12 -> 0 | AM14: 0
B15: Other Income | C15: =+D15+H15+L15+P15 -> 0 | D15: =SUM(E15:G15) -> 0 | H15: =SUM(I15:K15) -> 0 | L15: =SUM(M15:O15) -> 0 | O15: 0 | P15: =SUM(Q15:S15) -> 0 | Q15: 0 | S15: 0 | T15: =+U15+Y15+AC15+AG15 -> 230.96 | U15: =SUM(V15:X15) -> 0 | Y15: =SUM(Z15:AB15) -> 124.13 | Z15: 37.5 | AB15: 86.63 | AC15: =SUM(AD15:AF15) -> 98.26 | AD15: 49.13 | AE15: 49.13 | AF15: 0 | AG15: =SUM(AH15:AJ15) -> 8.57 | AH15: 0 | AI15: 8.57
B16: Consultation Income | C16: =+D16+H16+L16+P16 -> 0 | D16: =SUM(E16:G16) -> 0 | H16: =SUM(I16:K16) -> 0 | I16: 0 | J16: 0 | K16: 0 | L16: =SUM(M16:O16) -> 0 | N16: 0 | O16: 0 | P16: =SUM(Q16:S16) -> 0 | Q16: 0 | R16: 0 | S16: 0 | T16: =+U16+Y16+AC16+AG16 -> 0 | U16: =SUM(V16:X16) -> 0 | Y16: =SUM(Z16:AB16) -> 0 | Z16: 0 | AA16: 0 | AB16: 0 | AC16: =SUM(AD16:AF16) -> 0 | AE16: 0 | AF16: 0 | AG16: =SUM(AH16:AJ16) -> 0 | AH16: 0 | AI16: 0 | AJ16: 0 | AM16: 0
B17: Gross Income | C17: =+D17+H17+L17+P17 -> 0 | D17: =SUM(E17:G17) -> 0 | E17: =+E16+E14 -> 0 | F17: =+F16+F14 -> 0 | G17: =+G16+G14 -> 0 | H17: =SUM(I17:K17) -> 0 | I17: =+I16+I14 -> 0 | J17: =+J16+J14 -> 0 | K17: =+K16+K14 -> 0 | L17: =SUM(M17:O17) -> 0 | M17: =+M16+M14 -> 0 | N17: =+N16+N14 -> 0 | O17: =+O16+O14 -> 0 | P17: =SUM(Q17:S17) -> 0 | Q17: =+Q16+Q14 -> 0 | R17: =+R16+R14 -> 0 | S17: =+S16+S14 -> 0 | T17: =+U17+Y17+AC17+AG17 -> 0 | U17: =SUM(V17:X17) -> 0 | V17: =+V16+V14 -> 0 | W17: =+W16+W14 -> 0 | X17: =+X16+X14 -> 0 | Y17: =SUM(Z17:AB17) -> 0 | Z17: =+Z16+Z14 -> 0 | AA17: =+AA16+AA14 -> 0 | AB17: =+AB16+AB14 -> 0 | AC17: =SUM(AD17:AF17) -> 0 | AD17: =+AD16+AD14 -> 0 | AE17: =+AE16+AE14 -> 0 | AF17: =+AF16+AF14 -> 0 | AG17: =SUM(AH17:AJ17) -> 0 | AH17: =+AH16+AH14 -> 0 | AI17: =+AI16+AI14 -> 0 | AJ17: =+AJ16+AJ14 -> 0 | AL17: =+AL16+AL14 -> 0 | AM17: 0
B19: General and Administrative Expenses | C19: =SUM(C20:C36) -> 110952.55 | D19: =SUM(D20:D36) -> 0 | E19: =SUM(E20:E38) -> 0 | F19: =SUM(F20:F38) -> 0 | G19: =SUM(G20:G38) -> 0 | H19: =SUM(H20:H36) -> 0 | I19: =SUM(I20:I36) -> 0 | J19: =SUM(J20:J36) -> 0 | K19: =SUM(K20:K36) -> 0 | L19: =SUM(L20:L36) -> 0 | M19: =SUM(M20:M36) -> 0 | N19: =SUM(N20:N36) -> 0 | O19: =SUM(O20:O36) -> 0 | ... U19: =SUM(U20:U36) -> 175978.66 | V19: =SUM(V20:V38) -> 66302.95 | W19: =SUM(W20:W38) -> 54700.53 | X19: =SUM(X20:X38) -> 54975.19 | Y19: =SUM(Y20:Y36) -> 137466.07 | Z19: =SUM(Z20:Z36) -> 53626.05 | AA19: =SUM(AA20:AA36) -> 41895.4 | AB19: =SUM(AB20:AB36) -> 41944.62 | AC19: =SUM(AC20:AC36) -> 132170.5 | AD19: =SUM(AD20:AD36) -> 38505.31 | AE19: =SUM(AE20:AE36) -> 47225.39 | AF19: =SUM(AF20:AF36) -> 46439.8 | ... AJ19: =SUM(AJ20:AJ36) -> 37396.01 | AL19: =SUM(AL20:AL36) -> 33034.48 | AM19: =SUM(AM20:AM36) -> 317021.54
B20: Bad Debt | C20: =SUM(D20:S20)-P20-L20-H20-D20 -> 0 | D20: =SUM(E20:G20) -> 0 | H20: =SUM(I20:K20) -> 0 | L20: =SUM(M20:O20) -> 0 | P20: =SUM(Q20:S20) -> 0 | T20: =SUM(U20:AJ20)-AG20-AC20-Y20-U20 -> 0 | U20: =SUM(V20:X20) -> 0 | Y20: =SUM(Z20:AB20) -> 0 | AB20: 0 | AC20: =SUM(AD20:AF20) -> 0 | AF20: 0 | AG20: =SUM(AH20:AJ20) -> 0 | AH20: 0 | AI20: 0 | AJ20: 0 | AL20: 0 | AM20: 0
B21: Bank Fees and Charges | C21: =SUM(D21:S21)-P21-L21-H21-D21 -> 4023.15 | D21: =SUM(E21:G21) -> 0 | H21: =SUM(I21:K21) -> 0 | L21: =SUM(M21:O21) -> 0 | P21: =SUM(Q21:S21) -> 4023.15 | R21: 1640.47 | S21: 2382.68 | T21: =SUM(U21:AJ21)-AG21-AC21-Y21-U21 -> 23806.49 | U21: =SUM(V21:X21) -> 6354.89 | V21: 2799.75 | W21: 1044.61 | X21: 2510.53 | Y21: =SUM(Z21:AB21) -> 5516.69 | Z21: 1401.42 | AA21: 1613.27 | AB21: 2502 | AC21: =SUM(AD21:AF21) -> 5864.87 | AD21: 1620.12 | AE21: 1984.52 | AF21: 2260.23 | AG21: =SUM(AH21:AJ21) -> 6070.04 | AH21: 2424.47 | AI21: 1909.9 | AJ21: 1735.67 | AL21: 2027.25 | AM21: 17230.24
B22: Office Supplies | C22: =SUM(D22:S22)-P22-L22-H22-D22 -> 0 | D22: =SUM(E22:G22) -> 0 | H22: =SUM(I22:K22) -> 0 | L22: =SUM(M22:O22) -> 0 | P22: =SUM(Q22:S22) -> 0 | S22: 0 | T22: =SUM(U22:AJ22)-AG22-AC22-Y22-U22 -> 1046.52 | U22: =SUM(V22:X22) -> 71.06 | V22: 0 | W22: 71.06 | X22: 0 | Y22: =SUM(Z22:AB22) -> 0 | AB22: 0 | AC22: =SUM(AD22:AF22) -> 0 | AE22: 0 | AF22: 0 | AG22: =SUM(AH22:AJ22) -> 975.46 | AH22: 0 | AI22: 975.46 | AJ22: 0 | AL22: 0 | AM22: 28437.69
B23: Office Utilities - Electricity/Water/Janitorial | C23: =SUM(D23:S23)-P23-L23-H23-D23 -> 0 | D23: =SUM(E23:G23) -> 0 | H23: =SUM(I23:K23) -> 0 | L23: =SUM(M23:O23) -> 0 | P23: =SUM(Q23:S23) -> 0 | T23: =SUM(U23:AJ23)-AG23-AC23-Y23-U23 -> 0 | U23: =SUM(V23:X23) -> 0 | V23: 0 | X23: 0 | Y23: =SUM(Z23:AB23) -> 0 | AB23: 0 | AC23: =SUM(AD23:AF23) -> 0 | AE23: 0 | AF23: 0 | AG23: =SUM(AH23:AJ23) -> 0 | AH23: 0 | AI23: 0 | AJ23: 0 | AL23: 0 | AM23: 0
B24: Office Expenses | C24: =SUM(D24:S24)-P24-L24-H24-D24 -> 0 | D24: =SUM(E24:G24) -> 0 | H24: =SUM(I24:K24) -> 0 | L24: =SUM(M24:O24) -> 0 | P24: =SUM(Q24:S24) -> 0 | S24: 0 | T24: =SUM(U24:AJ24)-AG24-AC24-Y24-U24 -> 667.5 | U24: =SUM(V24:X24) -> 0 | V24: 0 | X24: 0 | Y24: =SUM(Z24:AB24) -> 0 | Z24: 0 | AB24: 0 | AC24: =SUM(AD24:AF24) -> 667.5 | AD24: 0 | AE24: 0 | AF24: 667.5 | AG24: =SUM(AH24:AJ24) -> 0 | AH24: 0 | AI24: 0 | AJ24: 0 | AL24: 0 | AM24: 2963.41
B25: Office Repair & Maintenance Expense | L25: =SUM(M25:O25) -> 0 | P25: =SUM(Q25:S25) -> 0 | V25: 0 | X25: 0
B26: Travel Expense | C26: =SUM(D26:S26)-P26-L26-H26-D26 -> 2487.72 | D26: =SUM(E26:G26) -> 0 | H26: =SUM(I26:K26) -> 0 | L26: =SUM(M26:O26) -> 0 | P26: =SUM(Q26:S26) -> 2487.72 | R26: 687.72 | S26: 1800 | T26: =SUM(U26:AJ26)-AG26-AC26-Y26-U26 -> 13275.92 | U26: =SUM(V26:X26) -> 10260.88 | V26: 6471.88 | W26: 1684.86 | X26: 2104.14 | Y26: =SUM(Z26:AB26) -> 3015.04 | Z26: 178.05 | AA26: 2836.99 | AB26: 0 | AC26: =SUM(AD26:AF26) -> 0 | AE26: 0 | AF26: 0 | AG26: =SUM(AH26:AJ26) -> 0 | AH26: 0 | AI26: 0 | AJ26: 0 | AL26: 0 | AM26: 8231.25
B27: Printing and Stationery | C27: =SUM(D27:S27)-P27-L27-H27-D27 -> 0 | D27: =SUM(E27:G27) -> 0 | H27: =SUM(I27:K27) -> 0 | L27: =SUM(M27:O27) -> 0 | P27: =SUM(Q27:S27) -> 0 | S27: 0 | T27: =SUM(U27:AJ27)-AG27-AC27-Y27-U27 -> 223.48 | U27: =SUM(V27:X27) -> 0 | V27: 0 | X27: 0 | Y27: =SUM(Z27:AB27) -> 0 | AB27: 0 | AC27: =SUM(AD27:AF27) -> 0 | AD27: 0 | AE27: 0 | AF27: 0 | AG27: =SUM(AH27:AJ27) -> 223.48 | AH27: 0 | AI27: 0 | AJ27: 223.48 | AL27: 0 | AM27: 0
B28: Rent Expense (G&A) | C28: =SUM(D28:S28)-P28-L28-H28-D28 -> 0 | D28: =SUM(E28:G28) -> 0 | H28: =SUM(I28:K28) -> 0 | L28: =SUM(M28:O28) -> 0 | P28: =SUM(Q28:S28) -> 0 | T28: =SUM(U28:AJ28)-AG28-AC28-Y28-U28 -> 0 | U28: =SUM(V28:X28) -> 0 | V28: 0 | X28: 0 | Y28: =SUM(Z28:AB28) -> 0 | AB28: 0 | AC28: =SUM(AD28:AF28) -> 0 | AD28: 0 | AE28: 0 | AF28: 0 | AG28: =SUM(AH28:AJ28) -> 0 | AH28: 0 | AI28: 0 | AJ28: 0 | AL28: 0 | AM28: 0
B29: Meals and Entertainment | C29: =SUM(D29:S29)-P29-L29-H29-D29 -> 1014.94 | D29: =SUM(E29:G29) -> 0 | H29: =SUM(I29:K29) -> 0 | L29: =SUM(M29:O29) -> 0 | P29: =SUM(Q29:S29) -> 1014.94 | R29: 1014.94 | S29: 0 | T29: =SUM(U29:AJ29)-AG29-AC29-Y29-U29 -> 6281.59 | U29: =SUM(V29:X29) -> 2641.82 | V29: =1486.69+150 -> 1636.69 | W29: 0 | X29: 1005.13 | Y29: =SUM(Z29:AB29) -> 986.55 | Z29: 0 | AA29: 574.05 | AB29: 412.5 | AC29: =SUM(AD29:AF29) -> 1677.26 | AD29: 0 | AE29: 1677.26 | AF29: 0 | AG29: =SUM(AH29:AJ29) -> 975.96 | AH29: 0 | AI29: 975.96 | AJ29: 0 | AL29: 0 | AM29: 7229.12
B30: Audit & Consultancy expense | C30: =SUM(D30:S30)-P30-L30-H30-D30 -> 0 | D30: =SUM(E30:G30) -> 0 | H30: =SUM(I30:K30) -> 0 | L30: =SUM(M30:O30) -> 0 | P30: =SUM(Q30:S30) -> 0 | T30: =SUM(U30:AJ30)-AG30-AC30-Y30-U30 -> 0 | U30: =SUM(V30:X30) -> 0 | V30: 0 | X30: 0 | Y30: =SUM(Z30:AB30) -> 0 | AB30: 0 | AC30: =SUM(AD30:AF30) -> 0 | AD30: 0 | AE30: 0 | AF30: 0 | AG30: =SUM(AH30:AJ30) -> 0 | AH30: 0 | AI30: 0 | AJ30: 0 | AL30: 0 | AM30: 0
B31: Communication Exp - Mobile & Internet | C31: =SUM(D31:S31)-P31-L31-H31-D31 -> 0 | D31: =SUM(E31:G31) -> 0 | H31: =SUM(I31:K31) -> 0 | L31: =SUM(M31:O31) -> 0 | P31: =SUM(Q31:S31) -> 0 | S31: 0 | T31: =SUM(U31:AJ31)-AG31-AC31-Y31-U31 -> 1983.34 | U31: =SUM(V31:X31) -> 0 | V31: 0 | X31: 0 | Y31: =SUM(Z31:AB31) -> 1348.39 | AB31: 1348.39 | AC31: =SUM(AD31:AF31) -> 346.34 | AD31: 0 | AE31: 0 | AF31: 346.34 | AG31: =SUM(AH31:AJ31) -> 288.61 | AH31: 0 | AI31: 173.24 | AJ31: 115.37 | AL31: 0 | AM31: 852.62
B32: Subscriptions & Memberships | C32: =SUM(D32:S32)-P32-L32-H32-D32 -> 103426.74 | D32: =SUM(E32:G32) -> 0 | H32: =SUM(I32:K32) -> 0 | L32: =SUM(M32:O32) -> 0 | P32: =SUM(Q32:S32) -> 103426.74 | R32: 49890.22 | S32: 53536.52 | T32: =SUM(U32:AJ32)-AG32-AC32-Y32-U32 -> 525463.26 | U32: =SUM(V32:X32) -> 156650.01 | V32: 55394.62 | W32: 51900 | X32: 49355.39 | Y32: =SUM(Z32:AB32) -> 126599.4 | Z32: 52046.58 | AA32: 36871.09 | AB32: 37681.73 | AC32: =SUM(AD32:AF32) -> 123614.53 | AD32: 36885.19 | AE32: 43563.61 | AF32: 43165.73 | AG32: =SUM(AH32:AJ32) -> 118599.32 | AH32: 50222.06 | AI32: 37076.83 | AJ32: 31300.43 | AL32: 29315.68 | AM32: 244247.23
B33: Events & Activity Expense | C33: =SUM(D33:S33)-P33-L33-H33-D33 -> 0 | D33: =SUM(E33:G33) -> 0 | H33: =SUM(I33:K33) -> 0 | L33: =SUM(M33:O33) -> 0 | P33: =SUM(Q33:S33) -> 0 | T33: =SUM(U33:AJ33)-AG33-AC33-Y33-U33 -> 0 | U33: =SUM(V33:X33) -> 0 | V33: 0 | X33: 0 | Y33: =SUM(Z33:AB33) -> 0
B34: Team Building Activities | C34: =SUM(D34:S34)-P34-L34-H34-D34 -> 0 | D34: =SUM(E34:G34) -> 0 | L34: =SUM(M34:O34) -> 0 | P34: =SUM(Q34:S34) -> 0 | T34: =SUM(U34:AJ34)-AG34-AC34-Y34-U34 -> 0 | U34: =SUM(V34:X34) -> 0 | V34: 0 | X34: 0
B35: Penny Difference | C35: =SUM(D35:S35)-P35-L35-H35-D35 -> 0 | H35: =SUM(I35:K35) -> 0 | L35: =SUM(M35:O35) -> 0 | P35: =SUM(Q35:S35) -> 0 | S35: 0 | T35: =SUM(U35:AJ35)-AG35-AC35-Y35-U35 -> 0.01 | V35: 0.01 | X35: 0 | Y35: =SUM(Z35:AB35) -> 0 | AB35: 0 | AD35: 0 | AE35: 0 | AF35: 0 | AG35: =SUM(AH35:AJ35) -> 0 | AH35: 0 | AI35: 0 | AJ35: 0 | AL35: 0 | AM35: 0
B36: Low Value Assets | C36: =SUM(D36:S36)-P36-L36-H36-D36 -> 0 | D36: =SUM(E36:G36) -> 0 | H36: =SUM(I36:K36) -> 0 | L36: =SUM(M36:O36) -> 0 | P36: =SUM(Q36:S36) -> 0 | S36: 0 | T36: =SUM(U36:AJ36)-AG36-AC36-Y36-U36 -> 4021.06 | U36: =SUM(V36:X36) -> 0 | V36: 0 | X36: 0 | Y36: =SUM(Z36:AB36) -> 0 | AB36: 0 | AC36: =SUM(AD36:AF36) -> 0 | AD36: 0 | AE36: 0 | AF36: 0 | AG36: =SUM(AH36:AJ36) -> 4021.06 | AH36: 0 | AI36: 0 | AJ36: 4021.06 | AL36: 1691.55 | AM36: 7829.98
B37: Charity | C37: =SUM(D37:S37)-P37-L37-H37-D37 -> 0 | D37: =SUM(E37:G37) -> 0 | H37: =SUM(I37:K37) -> 0 | L37: =SUM(M37:O37) -> 0 | P37: =SUM(Q37:S37) -> 0 | T37: =SUM(U37:AJ37)-AG37-AC37-Y37-U37 -> 0 | U37: =SUM(V37:X37) -> 0 | V37: 0 | X37: 0 | Y37: =SUM(Z37:AB37) -> 0 | AB37: 0 | AD37: 0 | AE37: 0 | AF37: 0 | AG37: =SUM(AH37:AJ37) -> 0 | AH37: 0 | AI37: 0 | AJ37: 0 | AM37: 0
B38: Witholding Tax | C38: =SUM(D38:S38)-P38-L38-H38-D38 -> 0 | D38: =SUM(E38:G38) -> 0 | H38: =SUM(I38:K38) -> 0 | L38: =SUM(M38:O38) -> 0 | P38: =SUM(Q38:S38) -> 0 | T38: =SUM(U38:AJ38)-AG38-AC38-Y38-U38 -> 0 | U38: =SUM(V38:X38) -> 0 | V38: 0 | X38: 0 | Y38: =SUM(Z38:AB38) -> 0 | AB38: 0 | AD38: 0 | AE38: 0 | AF38: 0 | AG38: =SUM(AH38:AJ38) -> 0 | AH38: 0 | AI38: 0 | AJ38: 0 | AM38: 0
B39: Selling Expenses | C39: =SUM(C40:C55) -> 82983.06 | D39: =SUM(E39:G39) -> 0 | E39: =SUM(E40:E55) -> 0 | F39: =SUM(F40:F55) -> 0 | G39: =SUM(G40:G55) -> 0 | H39: =SUM(I39:K39) -> 0 | I39: =SUM(I40:I55) -> 0 | J39: =SUM(J40:J55) -> 0 | K39: =SUM(K40:K55) -> 0 | L39: =SUM(M39:O39) -> 0 | M39: =SUM(M40:M55) -> 0 | N39: =SUM(N40:N55) -> 0 | O39: =SUM(O40:O55) -> 0 | P39: =SUM(Q39:S39) -> 82983.06 | Q39: =SUM(Q40:Q55) -> 0 | R39: =SUM(R40:R55) -> 45138.65 | S39: =SUM(S40:S55) -> 37844.41 | T39: =SUM(T40:T55) -> 669599.75 | U39: =SUM(V39:X39) -> 162969.64 | V39: =SUM(V40:V55) -> 52018.05 | W39: =SUM(W40:W55) -> 41585.01 | X39: =SUM(X40:X55) -> 69366.58 | Y39: =SUM(Z39:AB39) -> 177755.03 | Z39: =SUM(Z40:Z55) -> 55789.35 | AA39: =SUM(AA40:AA55) -> 56565.6 | AB39: =SUM(AB40:AB55) -> 65400.08 | AC39: =SUM(AD39:AF39) -> 155760.79 | AD39: =SUM(AD40:AD55) -> 68407.3 | AE39: =SUM(AE40:AE55) -> 59361.17 | AF39: =SUM(AF40:AF55) -> 27992.32 | AG39: =SUM(AH39:AJ39) -> 173114.29 | AH39: =SUM(AH40:AH55) -> 41542.73 | AI39: =SUM(AI40:AI55) -> 95489.88 | AJ39: =SUM(AJ40:AJ55) -> 36081.68 | AL39: =SUM(AL40:AL55) -> 29936.94 | AM39: =SUM(AM40:AM55) -> 179659.18
B40: Business travel expenses | C40: =SUM(D40:S40)-P40-L40-H40-D40 -> 0 | D40: =SUM(E40:G40) -> 0 | H40: =SUM(I40:K40) -> 0 | L40: =SUM(M40:O40) -> 0 | P40: =SUM(Q40:S40) -> 0 | S40: 0 | T40: =SUM(U40:AJ40)-AG40-AC40-Y40-U40 -> 83690.52 | U40: =SUM(V40:X40) -> 6761.32 | V40: 811.01 | W40: 2549.51 | X40: 3400.8 | Y40: =SUM(Z40:AB40) -> 12885.49 | Z40: 0 | AA40: 995.44 | AB40: 11890.05 | AC40: =SUM(AD40:AF40) -> 15967.62 | AD40: 7793.14 | AE40: 6787.8 | AF40: 1386.68 | AG40: =SUM(AH40:AJ40) -> 48076.09 | AH40: 7086.76 | AI40: 36880.6 | AJ40: 4108.73 | AL40: 37.58 | AM40: 14193.81
B41: Business Accommodation Expense | C41: =SUM(D41:S41)-P41-L41-H41-D41 -> 0 | D41: =SUM(E41:G41) -> 0 | H41: =SUM(I41:K41) -> 0 | L41: =SUM(M41:O41) -> 0 | P41: =SUM(Q41:S41) -> 0 | S41: 0 | T41: =SUM(U41:AJ41)-AG41-AC41-Y41-U41 -> 6445.12 | U41: =SUM(V41:X41) -> 3421.77 | V41: 0 | W41: 0 | X41: 3421.77 | Y41: =SUM(Z41:AB41) -> 0 | AC41: =SUM(AD41:AF41) -> 1020.9 | AF41: 1020.9 | AG41: =SUM(AH41:AJ41) -> 2002.45 | AH41: 1401.17 | AJ41: 601.28
B42: Collection Commission | C42: =SUM(D42:S42)-P42-L42-H42-D42 -> 0 | D42: =SUM(E42:G42) -> 0 | H42: =SUM(I42:K42) -> 0 | L42: =SUM(M42:O42) -> 0 | P42: =SUM(Q42:S42) -> 0 | T42: =SUM(U42:AJ42)-AG42-AC42-Y42-U42 -> 0 | U42: =SUM(V42:X42) -> 0 | V42: 0 | Y42: =SUM(Z42:AB42) -> 0 | AB42: 0 | AC42: =SUM(AD42:AF42) -> 0 | AD42: 0 | AE42: 0 | AF42: 0 | AG42: =SUM(AH42:AJ42) -> 0 | AH42: 0 | AI42: 0 | AJ42: 0 | AL42: 0 | AM42: 0
B43: Dinar commission | C43: =SUM(D43:S43)-P43-L43-H43-D43 -> 0 | D43: =SUM(E43:G43) -> 0 | H43: =SUM(I43:K43) -> 0 | L43: =SUM(M43:O43) -> 0 | P43: =SUM(Q43:S43) -> 0 | T43: =SUM(U43:AJ43)-AG43-AC43-Y43-U43 -> 0 | U43: =SUM(V43:X43) -> 0 | V43: 0 | Y43: =SUM(Z43:AB43) -> 0 | AB43: 0 | AC43: =SUM(AD43:AF43) -> 0 | AD43: 0 | AE43: 0 | AF43: 0 | AG43: =SUM(AH43:AJ43) -> 0 | AH43: 0 | AI43: 0 | AJ43: 0 | AL43: 0 | AM43: 0
B44: New customer commission | C44: =SUM(D44:S44)-P44-L44-H44-D44 -> 0 | D44: =SUM(E44:G44) -> 0 | H44: =SUM(I44:K44) -> 0 | L44: =SUM(M44:O44) -> 0 | P44: =SUM(Q44:S44) -> 0 | T44: =SUM(U44:AJ44)-AG44-AC44-Y44-U44 -> 0 | U44: =SUM(V44:X44) -> 0 | V44: 0 | Y44: =SUM(Z44:AB44) -> 0 | AB44: 0 | AC44: =SUM(AD44:AF44) -> 0 | AD44: 0 | AE44: 0 | AF44: 0 | AG44: =SUM(AH44:AJ44) -> 0 | AH44: 0 | AI44: 0 | AJ44: 0 | AL44: 0 | AM44: 0
B45: New Approved client Commission (SDA) | C45: =SUM(D45:S45)-P45-L45-H45-D45 -> 0 | H45: =SUM(I45:K45) -> 0 | T45: =SUM(U45:AJ45)-AG45-AC45-Y45-U45 -> 0 | V45: 0 | Y45: =SUM(Z45:AB45) -> 0 | AB45: 0 | AD45: 0 | AE45: 0 | AF45: 0 | AH45: 0 | AI45: 0 | AJ45: 0
B46: Sales Commission-Employee | C46: =SUM(D46:S46)-P46-L46-H46-D46 -> 0 | H46: =SUM(I46:K46) -> 0 | T46: =SUM(U46:AJ46)-AG46-AC46-Y46-U46 -> 0 | V46: 0 | Y46: =SUM(Z46:AB46) -> 0 | AB46: 0 | AD46: 0 | AE46: 0 | AF46: 0 | AH46: 0 | AI46: 0 | AJ46: 0
B47: Cash Purchase - Backend Margin | C47: =SUM(D47:S47)-P47-L47-H47-D47 -> 0 | H47: =SUM(I47:K47) -> 0 | L47: =SUM(M47:O47) -> 0 | T47: =SUM(U47:AJ47)-AG47-AC47-Y47-U47 -> 0 | V47: 0 | Y47: =SUM(Z47:AB47) -> 0 | AB47: 0 | AC47: =SUM(AD47:AF47) -> 0 | AD47: 0 | AE47: 0 | AF47: 0 | AH47: 0 | AI47: 0 | AJ47: 0 | AL47: 0
B48: Cash Sale Commission | C48: =SUM(D48:S48)-P48-L48-H48-D48 -> 0 | H48: =SUM(I48:K48) -> 0 | L48: =SUM(M48:O48) -> 0 | T48: =SUM(U48:AJ48)-AG48-AC48-Y48-U48 -> 0 | V48: 0 | Y48: =SUM(Z48:AB48) -> 0 | AB48: 0 | AC48: =SUM(AD48:AF48) -> 0 | AD48: 0 | AE48: 0 | AF48: 0 | AH48: 0 | AI48: 0 | AJ48: 0 | AL48: 0
...

Sheet BS Feb USA
B6: STATEMENT OF FINANCIAL POSITION (US SAR) | D6: 46387 | E6: 46356 | F6: 46326 | G6: 46295 | H6: 46265 | I6: 46234 | J6: 46203 | K6: 46173 | L6: 46142 | M6: 46112 | N6: 46081 | O6: 46053 | P6: 46022 | Q6: 45991 | R6: 45961 | S6: 45930 | T6: 45900 | U6: 45869 | V6: 45838 | W6: 45808 | X6: 45777 | Y6: 45747 | Z6: 45716 | AA6: 45688 | AC6: 45657
B7: As of 28 Feb 2026
B8: ASSETS
B10: Cash and Bank Balances | D10: =SUM(D11:D29) -> 0 | E10: =SUM(E11:E29) -> 0 | F10: =SUM(F11:F29) -> 0 | G10: =SUM(G11:G29) -> 0 | H10: =SUM(H11:H29) -> 0 | I10: =SUM(I11:I29) -> 0 | J10: =SUM(J11:J29) -> 0 | K10: =SUM(K11:K29) -> 0 | ... AA10: =SUM(AA11:AA29) -> 1685710.6 | AC10: =SUM(AC11:AC29) -> 2008252.4
B11: ALINMA BILDNW FEE | C11: =B11 -> ALINMA BILDNW FEE | I11: 0 | J11: 0 | K11: 0 | L11: 0 | M11: 0 | N11: 0 | O11: 0 | U11: 0 | V11: 0 | W11: 0 | X11: 0 | Y11: 0 | Z11: 0 | AA11: 0
B12: ALINMA BILDNW PROFIT | C12: =B12 -> ALINMA BILDNW PROFIT | I12: 0 | J12: 0 | K12: 0 | L12: 0 | M12: 0 | N12: 0 | O12: 0 | U12: 0 | V12: 0 | W12: 0 | X12: 0 | Y12: 0 | Z12: 0 | AA12: 0
B13: ALINMA CLIENT PROFIT | C13: =B13 -> ALINMA CLIENT PROFIT | I13: 0 | J13: 0 | K13: 0 | L13: 0 | M13: 0 | N13: 0 | O13: 0 | U13: 0 | V13: 0 | W13: 0 | X13: 0 | Y13: 0 | Z13: 0 | AA13: 0
B14: ALINMA DINAR DEALs PROFIT | C14: =B14 -> ALINMA DINAR DEALs PROFIT | I14: 0 | J14: 0 | K14: 0 | L14: 0 | M14: 0 | N14: 0 | O14: 0 | U14: 0 | V14: 0 | W14: 0 | X14: 0 | Y14: 0 | Z14: 0 | AA14: 0
B15: ALINMA DINAR DEALs VAT | C15: =B15 -> ALINMA DINAR DEALs VAT | O15: 0 | U15: 0 | V15: 0 | W15: 0 | X15: 0 | Y15: 0 | Z15: 0 | AA15: 0
B16: ALINMA EQUITY | C16: =B16 -> ALINMA EQUITY | O16: 0 | U16: 0 | V16: 0 | W16: 0 | X16: 0 | Y16: 0 | Z16: 0 | AA16: 0
B17: ALINMA USD | C17: =B17 -> ALINMA USD | O17: 0 | U17: 0 | V17: 0 | W17: 0 | X17: 0 | Y17: 0 | Z17: 0 | AA17: 0
B18: ALINMA VAT | C18: =B18 -> ALINMA VAT | O18: 0 | U18: 0 | V18: 0 | W18: 0 | X18: 0 | Y18: 0 | Z18: 0 | AA18: 0
B19: ALINMA-DEBT | C19: =B19 -> ALINMA-DEBT | O19: 0 | U19: 0 | V19: 0 | W19: 0 | X19: 0 | Y19: 0 | Z19: 0 | AA19: 0
B20: ANB-BILDNW TRADINGCOMPANY | C20: =B20 -> ANB-BILDNW TRADINGCOMPANY | O20: 0 | U20: 0 | V20: 0 | W20: 0 | X20: 0 | Y20: 0 | Z20: 0 | AA20: 0
B21: Riyad Bank | C21: =B21 -> Riyad Bank | O21: 0 | U21: 0 | V21: 0 | W21: 0 | X21: 0 | Y21: 0 | Z21: 0 | AA21: 0
B22: Saudi Awwal Bank (SAB)-5001 | C22: =B22 -> Saudi Awwal Bank (SAB)-5001 | O22: 0
B23: Saudi Awwal Bank (SAB)-5002 | C23: =B23 -> Saudi Awwal Bank (SAB)-5002 | O23: 0
B24: US Checking Account | C24: =B24 -> US Checking Account | N24: 3615947.2 | O24: 3972174.1 | P24: 4665832.4 | Q24: 7232496.4 | R24: 8332218.7 | S24: 1698141.5 | T24: 157288.17 | U24: 71680.74 | V24: 374733.33 | W24: 207571.61 | X24: 387020.37 | Y24: 825153.17 | Z24: 1283941.1 | AA24: 1685710.6 | AC24: 2008252.4
B25: ANB Tanmeya Debt A/C | C25: =B25 -> ANB Tanmeya Debt A/C | O25: 0 | U25: 0 | Z25: 0 | AA25: 0
B26: Simplifi | C26: =B26 -> Simplifi | O26: 0 | U26: 0 | Z26: 0 | AA26: 0
B27: SiFi Wallet | C27: =B27 -> SiFi Wallet | O27: 0 | U27: 0
B28: Sinking Fund | C28: =B28 -> Sinking Fund | O28: 0
B29: Petty Cash | C29: =B29 -> Petty Cash | O29: 0 | U29: 0 | Z29: 0 | AA29: 0 | AC29: 0
C30: =B30 -> 0
B32: Trade Receivables (net) | D32: =SUM(D33:D34) -> 0 | E32: =SUM(E33:E34) -> 0 | F32: =SUM(F33:F34) -> 0 | G32: =SUM(G33:G34) -> 0 | I32: =SUM(I33:I34) -> 0 | J32: =SUM(J33:J34) -> 0 | K32: =SUM(K33:K34) -> 0 | L32: =SUM(L33:L34) -> 0 | M32: =SUM(M33:M34) -> 0 | N32: =SUM(N33:N34) -> 0 | O32: =SUM(O33:O34) -> 0 | P32: =SUM(P33:P34) -> 0 | ... S32: =SUM(S33:S34) -> 0 | U32: =SUM(U33:U34) -> 0 | V32: =SUM(V33:V34) -> 0 | W32: =SUM(W33:W34) -> 0 | X32: =SUM(X33:X34) -> 0 | Y32: =SUM(Y33:Y34) -> 0 | Z32: =SUM(Z33:Z34) -> 0 | AA32: =SUM(AA33:AA34) -> 0 | AC32: =SUM(AC33:AC34) -> 0
B33: Trade Receivables - Gross | C33: Accounts Receivable | K33: 0 | L33: 0 | M33: 0 | N33: 0 | O33: 0 | W33: 0 | X33: 0 | Y33: 0 | Z33: 0 | AA33: 0
B34: Closing Provision for doubtful Accounts | C34: Provision for Doubtful Debts | D34: 0 | E34: 0 | F34: 0 | G34: 0 | I34: 0 | J34: 0 | K34: 0 | L34: 0 | M34: 0 | N34: 0 | O34: 0 | P34: 0 | Q34: 0 | R34: 0 | S34: 0 | U34: 0 | V34: 0 | W34: 0 | X34: 0 | Y34: 0 | Z34: 0 | AA34: 0 | AC34: 0
B36: Prepaid Expenses & Other recievables | D36: =SUM(D37:D50) -> 0 | E36: =SUM(E37:E50) -> 0 | F36: =SUM(F37:F50) -> 0 | G36: =SUM(G37:G50) -> 0 | H36: =SUM(H37:H50) -> 0 | I36: =SUM(I37:I50) -> 0 | J36: =SUM(J37:J50) -> 0 | K36: =SUM(K37:K50) -> 0 | L36: =SUM(L37:L50) -> 0 | M36: =SUM(M37:M53) -> 0 | N36: =SUM(N37:N50) -> 190985.2 | O36: =SUM(O37:O50) -> 203100.53 | P36: =SUM(P37:P50) -> 180412.78 | Q36: =SUM(Q37:Q50) -> 189850.03 | R36: =SUM(R37:R50) -> 212214.73 | S36: =SUM(S37:S50) -> 180274.82 | T36: =SUM(T37:T50) -> 203896.86 | U36: =SUM(U37:U50) -> 199268.9 | ... X36: =SUM(X37:X50) -> 167543.76 | Y36: =SUM(Y37:Y53) -> 164594.37 | Z36: =SUM(Z37:Z53) -> 164694.03 | AA36: =SUM(AA37:AA52) -> 161368.51 | AC36: =SUM(AC37:AC52) -> 131186.62
B37: Prepaid Vendors | C37: Prepaid vendors Bildnw Inc. | O37: 0 | Z37: 0 | AA37: 0
B38: Prepaid Accommodation Rent Expense | C38: =B38 -> Prepaid Accommodation Rent Expense | O38: 0 | Z38: 0 | AA38: 0
B39: Prepaid Financing Expense | C39: =B39 -> Prepaid Financing Expense | N39: 53894.21 | O39: 55144.2 | P39: 56394.19 | Q39: 57644.18 | R39: 58894.17 | S39: 60144.16 | T39: 61394.15 | U39: 62644.14 | V39: 63894.13 | W39: 65144.12 | X39: 66394.11 | Y39: 67644.1 | Z39: 68896.75 | AA39: 70149.4 | AC39: 71402.05
B40: Prepaid Govt. Legal Expense | C40: =B40 -> Prepaid Govt. Legal Expense | O40: 0 | Z40: 0 | AA40: 0
B41: Prepaid IT Subscriptions Expense | C41: =B41 -> Prepaid IT Subscriptions Expense | N41: 20811.83 | O41: 27410.41 | P41: 12330.91 | Q41: 13699.88 | R41: 496.31 | S41: 650.92 | T41: 4640.55 | U41: 8630.18 | V41: 3244.81 | W41: 7234.44 | X41: 11224.07 | Y41: 15213.7 | Z41: 9816.84 | AA41: 11955.6 | AC41: 15798.79
B42: Prepaid Office Rent Expense | C42: =B42 -> Prepaid Office Rent Expense | O42: 0 | Z42: 0 | AA42: 0
B43: Prepaid Other Expense | C43: =B43 -> Prepaid Other Expense | N43: 10869.72 | O43: 15136.48 | P43: 6278.24 | Q43: 13096.53 | R43: 19914.82 | S43: 14257.8 | T43: 21066.86 | U43: 27875.92 | V43: 34684.98 | W43: 10508.09 | X43: 14765.58 | Y43: 6576.57 | Z43: 10820.44 | AA43: 4103.51 | AC43: 6155.23
B44: Prepaid Employment Expense (Iqama) | C44: =B44 -> Prepaid Employment Expense (Iqama) | O44: 0
B45: Fund Raising Expense receivable | C45: =B45 -> Fund Raising Expense receivable | N45: 75160 | O45: 75160 | P45: 75160 | Q45: 75160 | R45: 75160 | S45: 75160 | T45: 75160 | U45: 75160 | V45: 75160 | W45: 75160 | X45: 75160 | Y45: 75160 | Z45: 75160 | AA45: 75160 | AC45: 37580
B46: Employee Receivable | C46: Employee Advance | N46: 30249.44 | O46: 30249.44 | P46: 30249.44 | Q46: 30249.44 | R46: 57749.43 | S46: 30061.94 | T46: 41635.3 | U46: 24208.66 | V46: 9375 | Y46: 0 | Z46: 0 | AA46: 0 | AC46: 250.55
B47: Security deposits | C47: =B47 -> Security deposits | O47: 0 | Z47: 0 | AA47: 0
B48: Advance to Other Vendors | C48: =B48 -> Advance to Other Vendors | O48: 0 | S48: 0 | T48: 0 | U48: 750 | Z48: 0
...

Sheet IS Jan Consolidated (YTD)
