Workbook
Name \a: #REF!
Name \a: #REF!
Name \a: #REF!
Name \a: #REF!
Name \c: [1]FLASH!#REF!
Name \c: [1]FLASH!#REF!
Name \c: [1]FLASH!#REF!
Name \c: [1]FLASH!#REF!
Name \f: [1]FLASH!#REF!
Name \f: [1]FLASH!#REF!
Name \f: [1]FLASH!#REF!
Name \f: [1]FLASH!#REF!
Name \q: [1]FLASH!#REF!
Name \q: [1]FLASH!#REF!
Name \q: [1]FLASH!#REF!
Name \q: [1]FLASH!#REF!
Name \s: #REF!
Name \s: #REF!
Name \s: #REF!
Name \s: #REF!
Name \t: [1]FLASH!#REF!
Name \t: [1]FLASH!#REF!
Name \t: [1]FLASH!#REF!
Name \t: [1]FLASH!#REF!
Name \u: '[2]R & M - H L P'!#REF!
Name \u: '[2]R & M - H L P'!#REF!
Name \u: '[2]R & M - H L P'!#REF!
Name \u: '[2]R & M - H L P'!#REF!
Name \z: '[2]R & M - H L P'!#REF!
Name _1: #REF!
Name _1: #REF!
Name _1: #REF!
Name _1: #REF!
Name _2: #REF!
Name _2: #REF!
Name _2: #REF!
Name _2: #REF!
Name _3: #REF!
Name _3: #REF!
Name _3: #REF!
Name _3: #REF!
Name A: #REF!
Name A: #REF!
Name A: #REF!
Name A: #REF!
Name Audit_adj: [3]validation!$I$9
Name Audit_adj_LY: [3]validation_LY!$I$9
Name Axis: OFFSET(#REF!,0,0,MAX(#REF!),1)
Name Axis: OFFSET(#REF!,0,0,MAX(#REF!),1)
Name Axis: OFFSET(#REF!,0,0,MAX(#REF!),1)
Name Axis: OFFSET(#REF!,0,0,MAX(#REF!),1)
Name Axis1: OFFSET(#REF!,0,0,MAX(#REF!),1)
Name Axis1: OFFSET(#REF!,0,0,MAX(#REF!),1)
Name Axis1: OFFSET(#REF!,0,0,MAX(#REF!),1)
Name Axis1: OFFSET(#REF!,0,0,MAX(#REF!),1)
Name B: #REF!
Name B: #REF!
Name B: #REF!
Name B: #REF!
Name BUDGETM: '[4]Budget By Month'!$E$7:$R$83

Sheet IS Dec KSA
B7: INCOME STATEMENT (KSA SAR) | C7: YTD | D7: Q4 | E7: MTD | F7: MTD | G7: MTD | H7: Q3 | I7: MTD | J7: MTD | K7: MTD | L7: Q2 | M7: MTD | N7: MTD | O7: MTD | P7: Q1 | Q7: MTD | R7: MTD | S7: MTD
B8: FOR THE PERIOD 31st December 2024 | C8: 45657 | D8: 2024 | E8: 45657 | F8: 45626 | G8: 45596 | H8: 2024 | I8: 45565 | J8: 45535 | K8: 45504 | L8: 2024 | M8: 45473 | N8: 45443 | O8: 45412 | P8: 2024 | Q8: 45382 | R8: 45350 | S8: 45322
B10: Sales | C10: =SUM(D10:S10)-P10-L10-H10-D10 -> 76420880 | D10: =SUM(E10:G10) -> 21384440 | E10: 10080211 | F10: 7198821.6 | G10: 4105407 | H10: =SUM(I10:K10) -> 18352785 | I10: 4309452.5 | J10: 6772612 | K10: 7270720.4 | L10: =SUM(M10:O10) -> 19534533 | M10: 6957712.6 | N10: 7682337.2 | O10: 4894483.3 | P10: =SUM(Q10:S10) -> 17149122 | Q10: 9910492.9 | R10: 4805893.4 | S10: 2432735.6
B11: Cost of Goods Sold | C11: =SUM(D11:S11)-P11-L11-H11-D11 -> 69127802 | D11: =SUM(E11:G11) -> 19099399 | E11: 9065157.9 | F11: 6363435 | G11: 3670806.6 | H11: =SUM(I11:K11) -> 16705223 | I11: 3901380 | J11: 6268336 | K11: 6535506.8 | L11: =SUM(M11:O11) -> 17712883 | M11: 6212033.5 | N11: 6980089.4 | O11: 4520760 | P11: =SUM(Q11:S11) -> 15610297 | Q11: 9054208.4 | R11: 4407294 | S11: 2148794.4
B12: Purchase Discounts | C12: =SUM(D12:S12)-P12-L12-H12-D12 -> -93226.45 | D12: =SUM(E12:G12) -> -1236.25 | E12: 0 | G12: -1236.25 | H12: =SUM(I12:K12) -> -54172.81 | I12: -6670 | J12: -7915.43 | K12: -39587.38 | L12: =SUM(M12:O12) -> -18295.8 | N12: -5820.46 | O12: -12475.34 | P12: =SUM(Q12:S12) -> -19521.59 | Q12: -11033.03 | R12: -8488.56 | S12: 0
B13: Gross Profit / (Loss) | C13: =+C10-(C11+C12) -> 7386304.4 | D13: =+D10-(D11+D12) -> 2286276.6 | E13: =+E10-(E11+E12) -> 1015053.3 | F13: =+F10-(F11+F12) -> 835386.63 | G13: =+G10-(G11+G12) -> 435836.72 | H13: =+H10-(H11+H12) -> 1701735 | I13: =+I10-(I11+I12) -> 414742.55 | J13: =+J10-(J11+J12) -> 512191.45 | ... S13: =+S10-(S11+S12) -> 283941.25
B14: Consultation Income | C14: =+D14+H14+L14+P14 -> 293478.27 | D14: =SUM(E14:G14) -> 26086.96 | E14: 26086.96 | G14: 0 | H14: =SUM(I14:K14) -> 143478.26 | I14: 0 | J14: 0 | K14: 143478.26 | L14: =SUM(M14:O14) -> 0 | M14: 0 | N14: 0 | O14: 0 | P14: =SUM(Q14:S14) -> 123913.05 | Q14: 19565.22 | R14: 104347.83 | S14: 0
B15: Gross Income | C15: =+D15+H15+L15+P15 -> 7679782.6 | D15: =SUM(E15:G15) -> 2312363.6 | E15: =+E14+E13 -> 1041140.2 | F15: =+F14+F13 -> 835386.63 | G15: =+G14+G13 -> 435836.72 | H15: =SUM(I15:K15) -> 1845213.2 | I15: =+I14+I13 -> 414742.55 | J15: =+J14+J13 -> 512191.45 | K15: =+K14+K13 -> 918279.21 | L15: =SUM(M15:O15) -> 1839946.1 | M15: =+M14+M13 -> 745679.15 | N15: =+N14+N13 -> 708068.27 | O15: =+O14+O13 -> 386198.65 | P15: =SUM(Q15:S15) -> 1682259.8 | Q15: =+Q14+Q13 -> 886882.8 | R15: =+R14+R13 -> 511435.75 | S15: =+S14+S13 -> 283941.25
B17: General and Administrative Expenses | C17: =SUM(C18:C33) -> 865548.78 | D17: =SUM(D18:D33) -> 472997.6 | E17: =SUM(E18:E33) -> 293429.8 | F17: =SUM(F18:F33) -> 73778.62 | G17: =SUM(G18:G33) -> 105789.18 | H17: =SUM(H18:H33) -> 144942.12 | I17: =SUM(I18:I33) -> 65829.61 | J17: =SUM(J18:J33) -> 32644.12 | ... S17: =SUM(S18:S33) -> 46670.67
B18: Bad Debt | C18: =SUM(D18:S18)-P18-L18-H18-D18 -> 203016.64 | D18: =SUM(E18:G18) -> 203011.78 | E18: 203009.5 | F18: 0.37 | G18: 1.91 | H18: =SUM(I18:K18) -> 2.67 | I18: 0.5 | J18: 0.4 | K18: 1.77 | L18: =SUM(M18:O18) -> 0.63 | M18: 0 | N18: 0.63 | O18: 0 | P18: =SUM(Q18:S18) -> 1.56 | Q18: 0.51 | R18: 0.27 | S18: 0.78
B19: Bank Fees and Charges | C19: =SUM(D19:S19)-P19-L19-H19-D19 -> 7108.25 | D19: =SUM(E19:G19) -> 1210.76 | E19: 354.16 | F19: 434.86 | G19: 421.74 | H19: =SUM(I19:K19) -> 1167.17 | I19: 268.89 | J19: 319.69 | K19: 578.59 | L19: =SUM(M19:O19) -> 2248.14 | M19: 570.09 | N19: 954.67 | O19: 723.38 | P19: =SUM(Q19:S19) -> 2482.18 | Q19: 872.4 | R19: 1040.14 | S19: 569.64
B20: Office Supplies | C20: =SUM(D20:S20)-P20-L20-H20-D20 -> 25690.34 | D20: =SUM(E20:G20) -> 2690.87 | E20: 819.32 | F20: 669.05 | G20: 1202.5 | H20: =SUM(I20:K20) -> 8440 | I20: 4877.46 | J20: 3027.63 | K20: 534.91 | L20: =SUM(M20:O20) -> 8750.4 | M20: 682.6 | N20: 7993.77 | O20: 74.03 | P20: =SUM(Q20:S20) -> 5809.07 | Q20: 7.83 | R20: 3179.47 | S20: 2621.77
B21: Office Utilities - Electricity/Water/Janitorial | C21: =SUM(D21:S21)-P21-L21-H21-D21 -> 24609.21 | D21: =SUM(E21:G21) -> 13664.34 | E21: 4705.55 | F21: 1182.28 | G21: 7776.51 | H21: =SUM(I21:K21) -> 6139.69 | I21: 282 | J21: 4257.65 | K21: 1600.04 | L21: =SUM(M21:O21) -> 3342.28 | M21: 983.6 | N21: 1889.74 | O21: 468.94 | P21: =SUM(Q21:S21) -> 1462.9 | Q21: 824.4 | R21: 454 | S21: 184.5
B22: Office Expenses | C22: =SUM(D22:S22)-P22-L22-H22-D22 -> 481 | D22: =SUM(E22:G22) -> 1 | E22: 0 | F22: 0 | G22: 1 | H22: =SUM(I22:K22) -> 0 | I22: 0 | J22: 0 | K22: 0 | L22: =SUM(M22:O22) -> 0 | M22: 0 | N22: 0 | O22: 0 | P22: =SUM(Q22:S22) -> 480 | Q22: 0 | R22: 480 | S22: 0
B23: Travel Expense | C23: =SUM(D23:S23)-P23-L23-H23-D23 -> 29931.99 | D23: =SUM(E23:G23) -> 3750 | E23: 3750 | F23: 0 | G23: 0 | H23: =SUM(I23:K23) -> 18156.74 | I23: 2446.84 | J23: 0 | K23: 15709.9 | L23: =SUM(M23:O23) -> 8025.25 | M23: 0 | N23: 8025.25 | O23: 0 | P23: =SUM(Q23:S23) -> 0 | Q23: 0 | R23: 0 | S23: 0
B24: Printing and Stationery | C24: =SUM(D24:S24)-P24-L24-H24-D24 -> 4591.36 | D24: =SUM(E24:G24) -> 1056.29 | E24: 241 | F24: 675.29 | G24: 140 | H24: =SUM(I24:K24) -> 2690.93 | I24: 990.06 | J24: 0 | K24: 1700.87 | L24: =SUM(M24:O24) -> 69.57 | M24: 69.57 | N24: 0 | O24: 0 | P24: =SUM(Q24:S24) -> 774.57 | Q24: 0 | R24: 774.57 | S24: 0
B25: Rent Expense (G&A) | C25: =SUM(D25:S25)-P25-L25-H25-D25 -> 127377.94 | D25: =SUM(E25:G25) -> 48093.19 | E25: 32096.09 | F25: 7998.55 | G25: 7998.55 | H25: =SUM(I25:K25) -> 23995.64 | I25: 7998.55 | J25: 7998.55 | K25: 7998.54 | L25: =SUM(M25:O25) -> 23899.98 | M25: 7966.66 | N25: 7966.66 | O25: 7966.66 | P25: =SUM(Q25:S25) -> 31389.13 | Q25: 10162.66 | R25: 10162.66 | S25: 11063.81
B26: Meals and Entertainment | C26: =SUM(D26:S26)-P26-L26-H26-D26 -> 84744.32 | D26: =SUM(E26:G26) -> 48368.41 | E26: 3897.75 | F26: 25111.76 | G26: 19358.9 | H26: =SUM(I26:K26) -> 19542.3 | I26: 8268.64 | J26: 6052.74 | K26: 5220.92 | L26: =SUM(M26:O26) -> 8918.73 | M26: 3696.52 | N26: 3183.82 | O26: 2038.39 | P26: =SUM(Q26:S26) -> 7914.88 | Q26: 1173.66 | R26: 3478.57 | S26: 3262.65
B27: Audit & Consultancy expense | C27: =SUM(D27:S27)-P27-L27-H27-D27 -> 42500 | D27: =SUM(E27:G27) -> 17500 | E27: 17500 | F27: 0 | G27: 0 | H27: =SUM(I27:K27) -> 0 | I27: 0 | J27: 0 | K27: 0 | L27: =SUM(M27:O27) -> 12500 | M27: 12500 | N27: 0 | O27: 0 | P27: =SUM(Q27:S27) -> 12500 | Q27: 0 | R27: 0 | S27: 12500
B28: Communication Exp - Mobile & Internet | C28: =SUM(D28:S28)-P28-L28-H28-D28 -> 24754.9 | D28: =SUM(E28:G28) -> 8450.21 | E28: 2142.64 | F28: 2122.61 | G28: 4184.96 | H28: =SUM(I28:K28) -> 3845.24 | I28: 0 | J28: 1922.61 | K28: 1922.63 | L28: =SUM(M28:O28) -> 6691.58 | M28: 1929.83 | N28: 2812.12 | O28: 1949.63 | P28: =SUM(Q28:S28) -> 5767.87 | Q28: 1922.63 | R28: 1922.61 | S28: 1922.63
B29: Subscriptions & Memberships | C29: =SUM(D29:S29)-P29-L29-H29-D29 -> 227892.91 | D29: =SUM(E29:G29) -> 62247.3 | E29: 22184.55 | F29: 31415.34 | G29: 8647.41 | H29: =SUM(I29:K29) -> 60961.74 | I29: 40696.67 | J29: 9168.95 | K29: 11096.12 | L29: =SUM(M29:O29) -> 54654.93 | M29: 7414.94 | N29: 27481.49 | O29: 19758.5 | P29: =SUM(Q29:S29) -> 50028.94 | Q29: 19510.85 | R29: 15973.2 | S29: 14544.89
B30: Penny Difference | C30: =SUM(D30:S30)-P30-L30-H30-D30 -> -103.77 | D30: =SUM(E30:G30) -> -0.24 | E30: 0.24 | F30: 0.01 | G30: -0.49 | I30: 0 | J30: -104.1 | K30: -0.03 | L30: =SUM(M30:O30) -> 0.6 | M30: 0.12 | N30: 0.04 | O30: 0.44 | P30: =SUM(Q30:S30) -> 0 | Q30: 0 | R30: 0 | S30: 0
B31: Low Value Assets | C31: =SUM(D31:S31)-P31-L31-H31-D31 -> 5344.88 | D31: =SUM(E31:G31) -> 5344.88 | E31: 729 | F31: 4168.5 | G31: 447.38 | I31: 0 | J31: 0 | K31: 0 | M31: 0 | N31: 0 | O31: 0 | Q31: 0 | R31: 0 | S31: 0
B32: Charity | C32: =SUM(D32:S32)-P32-L32-H32-D32 -> 10000 | D32: =SUM(E32:G32) -> 10000 | E32: 2000 | F32: 0 | G32: 8000
B33: Witholding Tax | C33: =SUM(D33:S33)-P33-L33-H33-D33 -> 47608.81 | D33: =SUM(E33:G33) -> 47608.81 | E33: 0 | F33: 0 | G33: 47608.81
B34: Selling Expenses | C34: =SUM(C35:C43) -> 591969.18 | D34: =SUM(D35:D43) -> 189997.51 | E34: =SUM(E35:E43) -> 58404.56 | F34: =SUM(F35:F43) -> 67054.63 | G34: =SUM(G35:G43) -> 64538.32 | H34: =SUM(H35:H43) -> 155905.83 | I34: =SUM(I35:I43) -> 69145.88 | J34: =SUM(J35:J43) -> 42955.06 | ... S34: =SUM(S35:S43) -> 24674.48
B35: Business travel expenses | C35: =SUM(D35:S35)-P35-L35-H35-D35 -> 96381.63 | D35: =SUM(E35:G35) -> 61361.03 | E35: 18271.01 | F35: 18913.71 | G35: 24176.31 | H35: =SUM(I35:K35) -> 13512.9 | I35: 4564.64 | J35: 690 | K35: 8258.26 | L35: =SUM(M35:O35) -> 16278.5 | M35: 2500 | N35: 0 | O35: 13778.5 | P35: =SUM(Q35:S35) -> 5229.2 | Q35: 1340 | R35: 3889.2 | S35: 0
B36: Collection Commission | C36: =SUM(D36:S36)-P36-L36-H36-D36 -> 61150.53 | D36: =SUM(E36:G36) -> 8117.57 | E36: 4797.13 | F36: 0 | G36: 3320.44 | H36: =SUM(I36:K36) -> 17715.01 | I36: 3388.45 | J36: 11016.84 | K36: 3309.72 | L36: =SUM(M36:O36) -> 17647.36 | M36: 10814.05 | N36: 4426.28 | O36: 2407.03 | P36: =SUM(Q36:S36) -> 17670.59 | Q36: 6731.53 | R36: 1817.82 | S36: 9121.24
B37: Dinar commission | C37: =SUM(D37:S37)-P37-L37-H37-D37 -> 8543.48 | D37: =SUM(E37:G37) -> 0 | E37: 0 | F37: 0 | G37: 0 | H37: =SUM(I37:K37) -> 2869.57 | I37: 0 | J37: 1304.35 | K37: 1565.22 | L37: =SUM(M37:O37) -> 391.3 | M37: 0 | N37: 0 | O37: 391.3 | P37: =SUM(Q37:S37) -> 5282.61 | Q37: 2086.96 | R37: 0 | S37: 3195.65
B38: New customer commission | C38: =SUM(D38:S38)-P38-L38-H38-D38 -> 44606.18 | D38: =SUM(E38:G38) -> 13166.48 | E38: 5000 | F38: 8166.48 | G38: 0 | H38: =SUM(I38:K38) -> 9439.7 | I38: 1500 | J38: 5939.7 | K38: 2000 | L38: =SUM(M38:O38) -> 13000 | M38: 7000 | N38: 3000 | O38: 3000 | P38: =SUM(Q38:S38) -> 9000 | Q38: 2000 | R38: 1000 | S38: 6000
B39: Cash Purchase - Backend Margin | C39: =SUM(D39:S39)-P39-L39-H39-D39 -> 4457.77 | D39: =SUM(E39:G39) -> 687.5 | E39: 107.5 | F39: 0 | G39: 580 | H39: =SUM(I39:K39) -> 481.81 | I39: 481.81 | J39: 0 | K39: 0 | L39: =SUM(M39:O39) -> 3288.46 | M39: 506.13 | N39: 2782.33 | O39: 0 | P39: =SUM(Q39:S39) -> 0 | Q39: 0 | R39: 0 | S39: 0
B40: Cash Sale Commission | C40: =SUM(D40:S40)-P40-L40-H40-D40 -> 21797.18 | D40: =SUM(E40:G40) -> 240 | E40: 0 | F40: 120 | G40: 120 | H40: =SUM(I40:K40) -> 4162.38 | I40: 720 | J40: 3442.38 | K40: 0 | L40: =SUM(M40:O40) -> 17394.8 | M40: 6744.8 | N40: 10650 | O40: 0 | P40: =SUM(Q40:S40) -> 0 | Q40: 0 | R40: 0 | S40: 0
B41: Fuel/Mileage Expenses | C41: =SUM(D41:S41)-P41-L41-H41-D41 -> 42649.18 | D41: =SUM(E41:G41) -> 12753.84 | E41: 4340.78 | F41: 3114.39 | G41: 5298.67 | H41: =SUM(I41:K41) -> 10160.15 | I41: 4905.08 | J41: 1943.42 | K41: 3311.65 | L41: =SUM(M41:O41) -> 12392.19 | M41: 4093.31 | N41: 5875.86 | O41: 2423.02 | P41: =SUM(Q41:S41) -> 7343 | Q41: 4287.21 | R41: 1634.11 | S41: 1421.68
B42: Marketing & Advertising | C42: =SUM(D42:S42)-P42-L42-H42-D42 -> 93575.77 | D42: =SUM(E42:G42) -> 16006.67 | E42: 0 | F42: 10851.91 | G42: 5154.76 | H42: =SUM(I42:K42) -> 41735.47 | I42: 34993.8 | J42: 0 | K42: 6741.67 | L42: =SUM(M42:O42) -> 18316.57 | M42: 6055.73 | N42: 5907.61 | O42: 6353.23 | P42: =SUM(Q42:S42) -> 17517.06 | Q42: 6361.77 | R42: 6219.38 | S42: 4935.91
B43: Trade Credit Insurance | C43: =SUM(D43:S43)-P43-L43-H43-D43 -> 218807.46 | D43: =SUM(E43:G43) -> 77664.42 | E43: 25888.14 | F43: 25888.14 | G43: 25888.14 | H43: =SUM(I43:K43) -> 55828.84 | I43: 18592.1 | J43: 18618.37 | K43: 18618.37 | L43: =SUM(M43:O43) -> 50426.81 | M43: 16795.28 | N43: 16808.98 | O43: 16822.55 | P43: =SUM(Q43:S43) -> 34887.39 | Q43: 16822.55 | R43: 18064.84 | S43: 0
B44: Legal & Consultation Expenses | C44: =SUM(C45:C47) -> 408151.68 | D44: =SUM(D45:D47) -> 210401.22 | E44: =SUM(E45:E47) -> 161922.26 | F44: =SUM(F45:F47) -> 23924.35 | G44: =SUM(G45:G47) -> 24554.61 | H44: =SUM(H45:H47) -> 91831.38 | I44: =SUM(I45:I47) -> 28490.25 | J44: =SUM(J45:J47) -> 50369.3 | ... S44: =SUM(S45:S47) -> 19548.99
B45: Consultant Expense | C45: =SUM(D45:S45)-P45-L45-H45-D45 -> 74533.33 | D45: =SUM(E45:G45) -> 0 | E45: 0 | F45: 0 | G45: 0 | H45: =SUM(I45:K45) -> 13333.33 | I45: 3333.33 | J45: 0 | K45: 10000 | L45: =SUM(M45:O45) -> 30000 | M45: 10000 | N45: 10000 | O45: 10000 | P45: =SUM(Q45:S45) -> 31200 | Q45: 10000 | R45: 10000 | S45: 11200
B46: Government & Compliance Expense | C46: =SUM(D46:S46)-P46-L46-H46-D46 -> 29073.83 | D46: =SUM(E46:G46) -> 7668.36 | E46: 1332.26 | F46: 3174.35 | G46: 3161.75 | H46: =SUM(I46:K46) -> 9461.39 | I46: 1380.25 | J46: 5155.14 | K46: 2926 | L46: =SUM(M46:O46) -> 3638.5 | M46: 1201.75 | N46: 1656.75 | O46: 780 | P46: =SUM(Q46:S46) -> 8305.58 | Q46: 1253.5 | R46: 4165.59 | S46: 2886.49
B47: Legal | C47: =SUM(D47:S47)-P47-L47-H47-D47 -> 304544.52 | D47: =SUM(E47:G47) -> 202732.86 | E47: 160590 | F47: 20750 | G47: 21392.86 | H47: =SUM(I47:K47) -> 69036.66 | I47: 23776.67 | J47: 45214.16 | K47: 45.83 | M47: 5462.5 | N47: 5462.5 | O47: 5462.5 | P47: =SUM(Q47:S47) -> 16387.5 | Q47: 5462.5 | R47: 5462.5 | S47: 5462.5
B48: Depreciation Expenses | C48: =SUM(C49:C51) -> 85187.69 | D48: =SUM(D49:D51) -> 23197.02 | E48: =SUM(E49:E51) -> 7880.36 | F48: =SUM(F49:F51) -> 7291.25 | G48: =SUM(G49:G51) -> 8025.41 | H48: =SUM(H49:H51) -> 22696.56 | I48: =SUM(I49:I51) -> 7935.01 | J48: =SUM(J49:J51) -> 8024.9 | ... S48: =SUM(S49:S51) -> 6000.35
...

Sheet BS Dec KSA
B6: STATEMENT OF FINANCIAL POSITION (KSA SAR) | C6: 45657 | D6: 45626 | E6: 45596 | F6: 45565 | G6: 45535 | H6: 45504 | I6: 45473 | J6: 45443 | K6: 45412 | L6: 45382 | M6: 45350 | N6: 45322 | P6: 45291
B7: AS OF 31st December 2024
B8: ASSETS
B10: Cash and Bank Balances | C10: =SUM(C11:C25) -> 10448735 | D10: =SUM(D11:D25) -> 13623467 | E10: =SUM(E11:E25) -> 14580341 | F10: =SUM(F11:F25) -> 4079900.2 | G10: =SUM(G11:G25) -> 1768114.7 | H10: =SUM(H11:H25) -> 4979907 | I10: =SUM(I11:I25) -> 7931667.7 | J10: =SUM(J11:J25) -> 3213576.5 | ... N10: =SUM(N11:N25) -> 4556446.7 | P10: 3957363.2
B11: ALINMA BILDNW FEE | C11: 0 | D11: 0 | F11: 0 | G11: 0 | H11: 75.7 | I11: 75.7 | J11: 75.7 | K11: 75.7 | L11: 0 | M11: 37036.55 | N11: 26646.61 | P11: 0
B12: ALINMA BILDNW PROFIT | C12: 140103.67 | D12: 140103.67 | E12: 140103.67 | F12: 0 | G12: 0 | H12: 569757.95 | I12: 0 | J12: 0 | K12: 0 | L12: 0 | M12: 428055.73 | N12: 408472.76 | P12: 0
B13: ALINMA CLIENT PROFIT | C13: 166842.98 | D13: 166834.93 | E13: 166834.93 | F13: 339620.94 | G13: 339620.94 | H13: -8.05 | I13: 1708.15 | J13: 1708.15 | K13: 1708.15 | L13: 729157.71 | M13: 266776.95 | N13: 188464.65 | P13: 668024.87
B14: ALINMA DINAR DEALs PROFIT | C14: 30000 | D14: 0 | E14: 0 | F14: 0 | G14: 0 | H14: 165000 | I14: 0 | J14: 0 | K14: 0 | L14: 0 | M14: 15000 | N14: 0 | P14: 0
B15: ALINMA DINAR DEALs VAT | C15: 0 | D15: 0 | E15: 0 | F15: 0 | G15: 0 | H15: 0 | I15: 0 | J15: 0 | K15: 0 | L15: 2934.78 | M15: 0 | N15: 0 | P15: 43532.61
B16: ALINMA EQUITY | C16: 1315636.9 | D16: 2292020.2 | E16: 1849786.1 | F16: 88790.6 | G16: 1257082.2 | H16: 46543.89 | I16: 168320.11 | J16: 23714.23 | K16: 465178.53 | L16: 2339786.4 | M16: 3910746 | N16: 1030009.5 | P16: 767469.48
B17: ALINMA USD | C17: 0 | D17: 0 | E17: 0 | F17: 0 | G17: 0 | H17: 356567.64 | I17: 686567.64 | J17: 1186567.6 | K17: 1186567.6 | L17: 1232245.3 | M17: 0.44 | N17: 0.44 | P17: 0.44
B18: ALINMA VAT | C18: 131821.9 | D18: 100685.09 | E18: 88071.43 | F18: 67480.41 | G18: 29428.08 | H18: 29383.75 | I18: 29383.75 | J18: 39479.28 | K18: 39465.34 | L18: 54326.84 | M18: 34284.09 | N18: 19246.15 | P18: 90759.47
B19: ALINMA-DEBT | C19: 8593232.1 | D19: 10906870 | E19: 12317444 | F19: 3467930 | G19: 135882.26 | H19: 3806484.8 | I19: 7042461.1 | J19: 1958900.2 | K19: 606214.56 | L19: 991645.23 | M19: 3300295.3 | N19: 2883475.3 | P19: 2381669.3
B20: ANB-BILDNW TRADINGCOMPANY | C20: 6 | D20: 6 | E20: 6 | F20: 6 | G20: 6 | H20: 6 | I20: 6 | J20: 6 | K20: 6 | L20: 6 | M20: 6 | N20: 6 | P20: 100.8
B21: Riyadh Bank | C21: 30.48 | D21: 30.48 | E21: 30.48 | F21: 30.48 | G21: 30.48 | H21: 30.48 | I21: 30.48 | J21: 30.48 | K21: 30.48 | L21: 30.48 | M21: 30.48 | N21: 30.48 | P21: 6.31
B22: US Checking Account | C22: 0 | D22: 0 | E22: 0 | F22: 0 | G22: 0 | H22: 0 | I22: 0 | J22: 0 | K22: 0 | L22: 0 | M22: 0 | N22: 0
B23: anb - Tanmeya Debt Acct | C23: 37094.8 | D23: 94.8 | E23: 94.8 | F23: 94.8 | G23: 94.8 | H23: 94.8 | I23: 94.8 | J23: 94.8 | K23: 94.8 | L23: 94.8 | M23: 94.8 | N23: 94.8
B24: Simplifi | C24: 7822.62 | D24: 7822.62 | E24: 12970 | F24: 12970 | G24: 2970 | H24: 2970 | I24: 20 | J24: 0 | K24: 0 | L24: 0 | M24: 0 | N24: 0
B25: Petty Cash | C25: 26143.5 | D25: 8999.5 | E25: 4999.5 | F25: 102977 | G25: 3000 | H25: 3000 | I25: 3000 | J25: 3000 | K25: 3000 | L25: 3000 | M25: 3000 | N25: 0 | P25: 5800
B27: Trade Receivables (net) | C27: =SUM(C28:C29) -> 39178410 | D27: =SUM(D28:D29) -> 35535924 | E27: =SUM(E28:E29) -> 33632759 | F27: =SUM(F28:F29) -> 34548085 | G27: =SUM(G28:G29) -> 37084008 | H27: =SUM(H28:H29) -> 34268040 | I27: =SUM(I28:I29) -> 31927623 | J27: =SUM(J28:J29) -> 31054504 | ... N27: =SUM(N28:N29) -> 25019982 | P27: 25749560
B28: Trade Receivables - Gross | C28: 39584419 | D28: 35738924 | E28: 33835759 | F28: 34751085 | G28: 37287008 | H28: 34471040 | I28: 32130623 | J28: 31257504 | K28: 31952970 | L28: 29354142 | M28: 24957358 | N28: 25222982 | P28: 25749560
B29: Provision for doubtful Accounts | C29: -406009 | D29: -203000 | E29: -203000 | F29: -203000 | G29: -203000 | H29: -203000 | I29: -203000 | J29: -203000 | K29: -203000 | L29: -203000 | M29: -203000 | N29: -203000 | P29: 0
B31: Prepaid Expenses & Other recievables | C31: =SUM(C32:C44) -> 1263663.6 | D31: =SUM(D32:D44) -> 1239829.7 | E31: =SUM(E32:E44) -> 745420.18 | F31: =SUM(F32:F43) -> 366541.22 | G31: =SUM(G32:G43) -> 453953.95 | H31: =SUM(H32:H43) -> 352908.58 | I31: =SUM(I32:I43) -> 312499.7 | J31: =SUM(J32:J43) -> 353032.39 | K31: =SUM(K32:K43) -> 318973.06 | L31: =SUM(L32:L43) -> -1226013.6 | M31: =SUM(M32:M43) -> 283971.54 | N31: =SUM(N32:N43) -> 204303.4 | P31: 288133.91
B32: Prepaid Vendors | C32: 0 | D32: -8.05 | E32: -8.05 | F32: -18293.05 | G32: 17091.95 | H32: 17091.95 | I32: -8.05 | J32: -8.05 | K32: -8.05 | L32: -8.05 | M32: -8.05 | N32: -8.05 | P32: -8.05
B33: Prepaid Accommodation Rent Expense | C33: 0 | D33: -10666.63 | E33: -8533.3 | F33: -6399.97 | G33: -4266.64 | H33: -2133.31 | I33: 0.02 | J33: 2133.35 | K33: -8533.32 | L33: -6399.99 | M33: -2070.66 | N33: 2258.67
B34: Prepaid Financing Expense | C34: 34444.45 | D34: 35555.56 | E34: 36666.67 | F34: 37777.78 | G34: 38888.89 | H34: 0 | I34: 0 | J34: 0 | K34: 0 | L34: 0 | M34: 0 | N34: 0
B35: Prepaid Govt. Legal Expense | C35: 32500 | D35: 37916.67 | E35: 43333.34 | F35: 48750.01 | G35: 54166.68 | H35: 45.84 | I35: 91.67 | J35: 5554.17 | K35: 11016.67 | L35: 16479.17 | M35: 21941.67 | N35: 27404.17
B36: Prepaid IT Subscriptions Expense | C36: 70455.1 | D36: 7399.82 | E36: 8407.32 | F36: 11165.72 | G36: 13924.12 | H36: 7232.52 | I36: 9203.42 | J36: 11174.32 | K36: 10743.59 | L36: 12932.86 | M36: 15122.13 | N36: 17311.4
B37: Prepaid Office Rent Expense | C37: 126562.51 | D37: 156525.23 | E37: 11730.45 | F37: 17595.67 | G37: 23460.89 | H37: -5865.19 | I37: 0.02 | J37: 5833.35 | K37: 11666.68 | L37: 17500.01 | M37: 23333.34 | N37: 29166.67
B38: Prepaid Other Expense | C38: 75416.45 | D38: 108630.62 | E38: 90215.04 | F38: 121117.42 | G38: 146777.02 | H38: 173911.51 | I38: 110904.11 | J38: 123278.93 | K38: 122420.42 | L38: 2208.55 | M38: 99757.97 | N38: 9481.31 | P38: 71234.03
B39: Fund Raising Expense receivable
B40: Employee Receivable | C40: 150690.88 | D40: 130882.32 | E40: 127030.83 | F40: 99394.9 | G40: 108416.5 | H40: 107216.1 | I40: 138558.16 | J40: 152088.92 | K40: 119559.81 | L40: 92393.14 | M40: 76092.47 | N40: 70092.47 | P40: 57592.47
B41: Security deposits | C41: 2000 | D41: 2000 | E41: 2000 | F41: 2000 | G41: 2000 | H41: 1500 | I41: 1500 | J41: 1500 | K41: 1500 | L41: 1500 | M41: 1500 | N41: 1500 | P41: 1500
B42: Other Receivables | C42: 0 | D42: 0 | E42: 0 | F42: 0 | G42: 0 | H42: 500 | I42: 0 | J42: 0 | K42: 0 | L42: 0 | M42: 0 | N42: 0 | P42: 112999.2
B43: Input VAT | C43: 28469.18 | D43: 28469.18 | E43: 53952.88 | F43: 53432.74 | G43: 53494.54 | H43: 53409.16 | I43: 52250.35 | J43: 51477.4 | K43: 50607.26 | L43: -1362619.3 | M43: 48302.67 | N43: 47096.76 | P43: 44816.26
B44: Profit Reserve Account (Deposit) | C44: 743125 | D44: 743125 | E44: 380625 | F44: 0 | G44: 0 | I44: 0 | J44: 0 | K44: 0 | L44: 0 | M44: 0
B46: TOTAL CURRENT ASSETS | C46: =+C31+C10+C27 -> 50890809 | D46: =+D31+D10+D27 -> 50399221 | E46: =+E31+E10+E27 -> 48958521 | F46: =+F31+F10+F27 -> 38994527 | G46: =+G31+G10+G27 -> 39306076 | H46: =+H31+H10+H27 -> 39600856 | I46: =+I31+I10+I27 -> 40171790 | J46: =+J31+J10+J27 -> 34621113 | ... N46: =+N31+N10+N27 -> 29780732 | P46: 29995057
B49: Fixed Assets (net) | C49: =SUM(C50:C57) -> 208363.25 | D49: =SUM(D50:D57) -> 161601.55 | E49: =SUM(E50:E57) -> 145409.86 | F49: =SUM(F50:F57) -> 153435.27 | G49: =SUM(G50:G57) -> 159109.41 | H49: =SUM(H50:H57) -> 108959.76 | I49: =SUM(I50:I57) -> 113097.31 | J49: =SUM(J50:J57) -> 119833.96 | ... N49: =SUM(N50:N57) -> 128719.67 | P49: 129248.72
B50: Accumulated Depreciation - Furniture & Fixture | C50: -23841.55 | D50: -22527.08 | E50: -21212.61 | F50: -19898.14 | G50: -18583.67 | H50: -17269.2 | I50: -16033.57 | J50: -14797.94 | K50: -13562.31 | L50: -12326.68 | M50: -11091.05 | N50: -9855.42 | P50: -8619.79
B51: Accumulated Depreciation - Motor Vehicle | C51: -4022.45 | D51: -24226.6 | E51: -22546.75 | F51: -20866.9 | G51: -19187.05 | H51: -17507.2 | I51: -16631.84 | J51: -15756.48 | K51: -14881.12 | L51: -14005.76 | M51: -13130.4 | N51: -12255.04 | P51: -11379.68
...

Sheet IS Dec USA
B7: INCOME STATEMENT (US SAR) | C7: YTD | D7: Q4 | E7: MTD | F7: MTD | G7: MTD | H7: Q3 | I7: MTD | J7: MTD | K7: MTD | L7: Q2 | M7: MTD | N7: MTD | O7: MTD | P7: Q1 | Q7: MTD | R7: MTD | S7: MTD
B8: FOR THE PERIOD 31st December 2024 | C8: 45657 | D8: 2024 | E8: 45657 | F8: 45626 | G8: 45596 | H8: 2024 | I8: 45565 | J8: 45535 | K8: 45504 | L8: 2024 | M8: 45473 | N8: 45443 | O8: 45412 | P8: 2024 | Q8: 45382 | R8: 45350 | S8: 45322
B10: Sales | C10: =SUM(D10:S10)-P10-L10-H10-D10 -> 0 | D10: =SUM(E10:G10) -> 0 | H10: =SUM(I10:K10) -> 0 | I10: 0 | J10: 0 | K10: 0 | L10: =SUM(M10:O10) -> 0 | N10: 0 | O10: 0 | P10: =SUM(Q10:S10) -> 0
B11: Cost of Goods Sold | C11: =SUM(D11:S11)-P11-L11-H11-D11 -> 0 | D11: =SUM(E11:G11) -> 0 | H11: =SUM(I11:K11) -> 0 | I11: 0 | J11: 0 | K11: 0 | L11: =SUM(M11:O11) -> 0 | N11: 0 | O11: 0 | P11: =SUM(Q11:S11) -> 0
B12: Purchase Discounts | C12: =SUM(D12:S12)-P12-L12-H12-D12 -> 0 | D12: =SUM(E12:G12) -> 0 | H12: =SUM(I12:K12) -> 0 | I12: 0 | J12: 0 | K12: 0 | L12: =SUM(M12:O12) -> 0 | N12: 0 | O12: 0 | P12: =SUM(Q12:S12) -> 0 | R12: 0 | S12: 0
B13: Gross Profit / (Loss) | C13: =+C10-C11 -> 0 | D13: =+D10-D11 -> 0 | E13: =+E10-E11 -> 0 | F13: =+F10-F11 -> 0 | G13: =+G10-G11 -> 0 | H13: =+H10-H11 -> 0 | I13: =+I10-I11 -> 0 | J13: =+J10-J11 -> 0 | ... S13: =+S10-S11 -> 0
B14: Consultation Income | C14: =+D14+H14+L14+P14 -> 0 | D14: =SUM(E14:G14) -> 0 | H14: =SUM(I14:K14) -> 0 | I14: 0 | J14: 0 | K14: 0 | L14: =SUM(M14:O14) -> 0 | N14: 0 | O14: 0 | P14: =SUM(Q14:S14) -> 0 | R14: 0 | S14: 0
B15: Gross Income | C15: =+D15+H15+L15+P15 -> 0 | D15: =SUM(E15:G15) -> 0 | E15: =+E14+E13 -> 0 | F15: =+F14+F13 -> 0 | G15: =+G14+G13 -> 0 | H15: =SUM(I15:K15) -> 0 | I15: =+I14+I13 -> 0 | J15: =+J14+J13 -> 0 | K15: =+K14+K13 -> 0 | L15: =SUM(M15:O15) -> 0 | M15: =+M14+M13 -> 0 | N15: =+N14+N13 -> 0 | O15: =+O14+O13 -> 0 | P15: =SUM(Q15:S15) -> 0 | Q15: =+Q14+Q13 -> 0 | R15: =+R14+R13 -> 0 | S15: =+S14+S13 -> 0
B17: General and Administrative Expenses | C17: =SUM(C18:C31) -> 317021.54 | D17: =SUM(D18:D31) -> 115113.19 | E17: =SUM(E18:E31) -> 33034.48 | F17: =SUM(F18:F31) -> 44311.49 | G17: =SUM(G18:G31) -> 37767.22 | H17: =SUM(H18:H31) -> 77767.64 | I17: =SUM(I18:I31) -> 34142.11 | J17: =SUM(J18:J31) -> 21961.48 | ... S17: =SUM(S18:S31) -> 17457.23
B18: Bad Debt | C18: =SUM(D18:S18)-P18-L18-H18-D18 -> 0 | D18: =SUM(E18:G18) -> 0 | E18: 0 | F18: 0 | H18: =SUM(I18:K18) -> 0 | I18: 0 | J18: 0 | K18: 0 | L18: =SUM(M18:O18) -> 0 | N18: 0 | O18: 0 | P18: =SUM(Q18:S18) -> 0 | R18: 0 | S18: 0
B19: Bank Fees and Charges | C19: =SUM(D19:S19)-P19-L19-H19-D19 -> 17230.24 | D19: =SUM(E19:G19) -> 4537.66 | E19: 2027.25 | F19: 434.05 | G19: 2076.36 | H19: =SUM(I19:K19) -> 4386.01 | I19: 647.84 | J19: 1416.04 | K19: 2322.13 | L19: =SUM(M19:O19) -> 5055.6 | M19: 874.61 | N19: 2342.25 | O19: 1838.74 | P19: =SUM(Q19:S19) -> 3250.97 | Q19: 770.09 | R19: 1035.89 | S19: 1444.99
B20: Office Supplies | C20: =SUM(D20:S20)-P20-L20-H20-D20 -> 28437.69 | D20: =SUM(E20:G20) -> 0 | E20: 0 | F20: 0 | H20: =SUM(I20:K20) -> 3082.46 | I20: 0 | J20: 3082.46 | K20: 0 | L20: =SUM(M20:O20) -> 15407.8 | N20: 0 | O20: 15407.8 | P20: =SUM(Q20:S20) -> 9947.43 | Q20: 2311.17 | R20: 3758 | S20: 3878.26
B21: Office Utilities - Electricity/Water/Janitorial | C21: =SUM(D21:S21)-P21-L21-H21-D21 -> 0 | D21: =SUM(E21:G21) -> 0 | E21: 0 | H21: =SUM(I21:K21) -> 0 | I21: 0 | J21: 0 | K21: 0 | L21: =SUM(M21:O21) -> 0 | M21: 0 | N21: 0 | O21: 0 | P21: =SUM(Q21:S21) -> 0 | R21: 0 | S21: 0
B22: Office Equipment Expensed under Sect 1.263(a)-1(f) | C22: =SUM(D22:S22)-P22-L22-H22-D22 -> 2963.41 | D22: =SUM(E22:G22) -> 0 | E22: 0 | H22: =SUM(I22:K22) -> 0 | I22: 0 | J22: 0 | K22: 0 | L22: =SUM(M22:O22) -> 0 | M22: 0 | N22: 0 | O22: 0 | P22: =SUM(Q22:S22) -> 2963.41 | R22: 2963.41 | S22: 0
B23: Travel Expense | C23: =SUM(D23:S23)-P23-L23-H23-D23 -> 8231.25 | D23: =SUM(E23:G23) -> 0 | E23: 0 | H23: =SUM(I23:K23) -> 0 | I23: 0 | J23: 0 | K23: 0 | L23: =SUM(M23:O23) -> 581.28 | M23: 308.16 | N23: 0 | O23: 273.12 | P23: =SUM(Q23:S23) -> 7649.97 | Q23: 814.47 | R23: 6835.5 | S23: 0
B24: Printing and Stationery | C24: =SUM(D24:S24)-P24-L24-H24-D24 -> 0 | D24: =SUM(E24:G24) -> 0 | E24: 0 | H24: =SUM(I24:K24) -> 0 | I24: 0 | J24: 0 | K24: 0 | L24: =SUM(M24:O24) -> 0 | N24: 0 | O24: 0 | P24: =SUM(Q24:S24) -> 0 | R24: 0 | S24: 0
B25: Rent Expense (G&A) | C25: =SUM(D25:S25)-P25-L25-H25-D25 -> 0 | D25: =SUM(E25:G25) -> 0 | E25: 0 | H25: =SUM(I25:K25) -> 0 | I25: 0 | J25: 0 | K25: 0 | L25: =SUM(M25:O25) -> 0 | N25: 0 | O25: 0 | P25: =SUM(Q25:S25) -> 0 | R25: 0 | S25: 0
B26: Meals and Entertainment | C26: =SUM(D26:S26)-P26-L26-H26-D26 -> 7229.12 | D26: =SUM(E26:G26) -> 0 | E26: 0 | H26: =SUM(I26:K26) -> 3196.93 | I26: 202.7 | J26: 245.74 | K26: 2748.49 | L26: =SUM(M26:O26) -> 0 | N26: 0 | O26: 0 | P26: =SUM(Q26:S26) -> 4032.19 | R26: 198.65 | S26: 3833.54
B27: Audit & Consultancy expense | C27: =SUM(D27:S27)-P27-L27-H27-D27 -> 0 | D27: =SUM(E27:G27) -> 0 | E27: 0 | H27: =SUM(I27:K27) -> 0 | I27: 0 | J27: 0 | K27: 0 | L27: =SUM(M27:O27) -> 0 | N27: 0 | O27: 0 | P27: =SUM(Q27:S27) -> 0 | R27: 0 | S27: 0
B28: Communication Exp - Mobile & Internet | C28: =SUM(D28:S28)-P28-L28-H28-D28 -> 852.62 | D28: =SUM(E28:G28) -> 0 | E28: 0 | H28: =SUM(I28:K28) -> 346.26 | I28: 288.54 | J28: 0 | K28: 57.72 | L28: =SUM(M28:O28) -> 412.78 | M28: 115.45 | N28: 115.48 | O28: 181.85 | P28: =SUM(Q28:S28) -> 93.58 | Q28: 93.58 | R28: 0 | S28: 0
B29: Subscriptions & Memberships | C29: =SUM(D29:S29)-P29-L29-H29-D29 -> 244247.23 | D29: =SUM(E29:G29) -> 108883.98 | E29: 29315.68 | F29: 43877.44 | G29: 35690.86 | H29: =SUM(I29:K29) -> 60617.55 | I29: 26864.6 | J29: 17217.24 | K29: 16535.71 | L29: =SUM(M29:O29) -> 44868.96 | M29: 19305.83 | N29: 11534.28 | O29: 14028.85 | P29: =SUM(Q29:S29) -> 29876.74 | Q29: 10848.96 | R29: 10727.34 | S29: 8300.44
B30: Penny Difference | C30: =SUM(D30:S30)-P30-L30-H30-D30 -> 0 | E30: 0 | I30: 0 | J30: 0 | K30: 0 | N30: 0 | O30: 0 | P30: =SUM(Q30:S30) -> 0 | Q30: 0 | R30: 0 | S30: 0
B31: Low Value Assets | C31: =SUM(D31:S31)-P31-L31-H31-D31 -> 7829.98 | D31: =SUM(E31:G31) -> 1691.55 | E31: 1691.55 | H31: =SUM(I31:K31) -> 6138.43 | I31: 6138.43 | J31: 0 | K31: 0 | L31: =SUM(M31:O31) -> 0 | M31: 0 | N31: 0 | O31: 0 | P31: =SUM(Q31:S31) -> 0 | Q31: 0 | R31: 0 | S31: 0
B32: Charity | C32: =SUM(D32:S32)-P32-L32-H32-D32 -> 0 | D32: =SUM(E32:G32) -> 0
B33: Witholding Tax | C33: =SUM(D33:S33)-P33-L33-H33-D33 -> 0 | D33: =SUM(E33:G33) -> 0
B34: Selling Expenses | C34: =SUM(C35:C43) -> 179659.18 | D34: =SUM(E34:G34) -> 73090.28 | E34: =SUM(E35:E43) -> 29936.94 | F34: =SUM(F35:F43) -> 32160.56 | G34: =SUM(G35:G43) -> 10992.78 | H34: =SUM(I34:K34) -> 62020.56 | I34: =SUM(I35:I43) -> 40990.65 | J34: =SUM(J35:J43) -> 9457.6 | K34: =SUM(K35:K43) -> 11572.31 | L34: =SUM(M34:O34) -> 24919.87 | M34: =SUM(M35:M43) -> 4320.01 | N34: =SUM(N35:N43) -> 13096.29 | O34: =SUM(O35:O43) -> 7503.57 | P34: =SUM(Q34:S34) -> 19628.47 | Q34: =SUM(Q35:Q43) -> 11296.27 | R34: =SUM(R35:R43) -> 3875.59 | S34: =SUM(S35:S43) -> 4456.61
B35: Business travel expenses | C35: =SUM(D35:S35)-P35-L35-H35-D35 -> 14193.81 | D35: =SUM(E35:G35) -> 37.58 | E35: 37.58 | H35: =SUM(I35:K35) -> 2342.43 | I35: 0 | J35: 0 | K35: 2342.43 | L35: =SUM(M35:O35) -> 5343.88 | M35: 0 | N35: 2912.45 | O35: 2431.43 | P35: =SUM(Q35:S35) -> 6469.92 | Q35: 6469.92 | R35: 0 | S35: 0
B36: Collection Commission | C36: =SUM(D36:S36)-P36-L36-H36-D36 -> 0 | D36: =SUM(E36:G36) -> 0 | E36: 0 | H36: =SUM(I36:K36) -> 0 | I36: 0 | J36: 0 | K36: 0 | L36: =SUM(M36:O36) -> 0 | N36: 0 | O36: 0 | P36: =SUM(Q36:S36) -> 0 | R36: 0 | S36: 0
B37: Dinar commission | C37: =SUM(D37:S37)-P37-L37-H37-D37 -> 0 | D37: =SUM(E37:G37) -> 0 | E37: 0 | H37: =SUM(I37:K37) -> 0 | I37: 0 | J37: 0 | K37: 0 | L37: =SUM(M37:O37) -> 0 | N37: 0 | O37: 0 | P37: =SUM(Q37:S37) -> 0 | R37: 0 | S37: 0
B38: New customer commission | C38: =SUM(D38:S38)-P38-L38-H38-D38 -> 0 | D38: =SUM(E38:G38) -> 0 | E38: 0 | H38: =SUM(I38:K38) -> 0 | I38: 0 | J38: 0 | K38: 0 | L38: =SUM(M38:O38) -> 0 | N38: 0 | O38: 0 | P38: =SUM(Q38:S38) -> 0 | R38: 0 | S38: 0
B39: Cash Purchase - Backend Margin | E39: 0 | I39: 0 | J39: 0 | K39: 0 | L39: =SUM(M39:O39) -> 0
B40: Cash Sale Commission | E40: 0 | I40: 0 | J40: 0 | K40: 0 | L40: =SUM(M40:O40) -> 0
B41: Fuel/Mileage Expenses | C41: =SUM(D41:S41)-P41-L41-H41-D41 -> 0 | D41: =SUM(E41:G41) -> 0 | E41: 0 | H41: =SUM(I41:K41) -> 0 | I41: 0 | J41: 0 | K41: 0 | L41: =SUM(M41:O41) -> 0 | N41: 0 | O41: 0 | P41: =SUM(Q41:S41) -> 0 | R41: 0 | S41: 0
B42: Marketing & Advertising | C42: =SUM(D42:S42)-P42-L42-H42-D42 -> 165465.37 | D42: =SUM(E42:G42) -> 73052.7 | E42: 29899.36 | F42: 32160.56 | G42: 10992.78 | H42: =SUM(I42:K42) -> 59678.13 | I42: 40990.65 | J42: 9457.6 | K42: 9229.88 | L42: =SUM(M42:O42) -> 19575.99 | M42: 4320.01 | N42: 10183.84 | O42: 5072.14 | P42: =SUM(Q42:S42) -> 13158.55 | Q42: 4826.35 | R42: 3875.59 | S42: 4456.61
B43: Trade Credit Insurance | C43: =SUM(D43:S43)-P43-L43-H43-D43 -> 0 | D43: =SUM(E43:G43) -> 0 | E43: 0 | H43: =SUM(I43:K43) -> 0 | I43: 0 | J43: 0 | K43: 0 | L43: =SUM(M43:O43) -> 0 | N43: 0 | O43: 0 | P43: =SUM(Q43:S43) -> 0 | R43: 0 | S43: 0
B44: Legal & Consultation Expenses | C44: =SUM(C45:C47) -> 504511.88 | D44: =SUM(E44:G44) -> 214570.64 | E44: =SUM(E45:E47) -> 79135.86 | F44: =SUM(F45:F47) -> 26923.49 | G44: =SUM(G45:G47) -> 108511.29 | H44: =SUM(I44:K44) -> 118231.98 | I44: =SUM(I45:I47) -> 27099.12 | J44: =SUM(J45:J47) -> 49594.14 | K44: =SUM(K45:K47) -> 41538.72 | L44: =SUM(M44:O44) -> 61290.31 | M44: =SUM(M45:M47) -> 17127.84 | N44: =SUM(N45:N47) -> 20851.49 | O44: =SUM(O45:O47) -> 23310.98 | P44: =SUM(Q44:S44) -> 110418.95 | Q44: =SUM(Q45:Q47) -> 13644.14 | R44: =SUM(R45:R47) -> 57587.66 | S44: =SUM(S45:S47) -> 39187.15
B45: Consultant Expense | C45: =SUM(D45:S45)-P45-L45-H45-D45 -> 441363.3 | D45: =SUM(E45:G45) -> 201530.87 | E45: 74891.99 | F45: 22525.54 | G45: 104113.34 | H45: =SUM(I45:K45) -> 105445.39 | I45: 22970.96 | J45: 45311.9 | K45: 37162.53 | L45: =SUM(M45:O45) -> 46365.61 | M45: 12845.6 | N45: 16569.25 | O45: 16950.76 | P45: =SUM(Q45:S45) -> 88021.43 | Q45: 11297.91 | R45: 39882.6 | S45: 36840.92
B46: Government & Compliance Expense | C46: =SUM(D46:S46)-P46-L46-H46-D46 -> 0 | D46: =SUM(E46:G46) -> 0 | E46: 0 | H46: =SUM(I46:K46) -> 0 | I46: 0 | J46: 0 | K46: 0 | L46: =SUM(M46:O46) -> 0 | M46: 0 | N46: 0 | O46: 0 | P46: =SUM(Q46:S46) -> 0 | R46: 0 | S46: 0
B47: Legal | C47: =SUM(D47:S47)-P47-L47-H47-D47 -> 63148.58 | D47: =SUM(E47:G47) -> 13039.77 | E47: 4243.87 | F47: 4397.95 | G47: 4397.95 | H47: =SUM(I47:K47) -> 12786.59 | I47: 4128.16 | J47: 4282.24 | K47: 4376.19 | L47: =SUM(M47:O47) -> 14924.7 | M47: 4282.24 | N47: 4282.24 | O47: 6360.22 | P47: =SUM(Q47:S47) -> 22397.52 | Q47: 2346.23 | R47: 17705.06 | S47: 2346.23
B48: Depreciation Expenses | C48: =SUM(C49:C51) -> 3589.2 | D48: =SUM(E48:G48) -> 1794.6 | E48: =SUM(E49:E51) -> 598.2 | F48: =SUM(F49:F51) -> 598.2 | G48: =SUM(G49:G51) -> 598.2 | H48: =SUM(I48:K48) -> 1794.6 | I48: =SUM(I49:I51) -> 598.2 | J48: =SUM(J49:J51) -> 598.2 | K48: =SUM(K49:K51) -> 598.2 | L48: =SUM(M48:O48) -> 0 | M48: =SUM(M49:M51) -> 0 | N48: =SUM(N49:N51) -> 0 | O48: =SUM(O49:O51) -> 0 | P48: =SUM(Q48:S48) -> 0 | Q48: =SUM(Q49:Q51) -> 0 | R48: =SUM(R49:R51) -> 0 | S48: =SUM(S49:S51) -> 0
...

Sheet BS Dec USA
B6: STATEMENT OF FINANCIAL POSITION (US SAR) | C6: 45657 | D6: 45626 | E6: 45596 | F6: 45565 | G6: 45535 | H6: 45504 | I6: 45473 | J6: 45443 | K6: 45412 | L6: 45382 | M6: 45350 | N6: 45322
B7: As of 31st December 2024
B8: ASSETS
B10: Cash and Bank Balances | C10: =SUM(C11:C25) -> 2008252.4 | D10: =SUM(D11:D25) -> 2359619.8 | E10: =SUM(E11:E25) -> 2572070.2 | F10: =SUM(F11:F25) -> 2993836.8 | G10: =SUM(G11:G25) -> 3243627.6 | H10: =SUM(H11:H25) -> 3565406.1 | I10: =SUM(I11:I25) -> 2938541.7 | J10: =SUM(J11:J25) -> 1566648 | ... N10: =SUM(N11:N25) -> 4667300
B11: ALINMA BILDNW FEE | I11: 0 | J11: 0 | K11: 0 | L11: 0 | M11: 0 | N11: 0
B12: ALINMA BILDNW PROFIT | I12: 0 | J12: 0 | K12: 0 | L12: 0 | M12: 0 | N12: 0
B13: ALINMA CLIENT PROFIT | I13: 0 | J13: 0 | K13: 0 | L13: 0 | M13: 0 | N13: 0
B14: ALINMA DINAR DEALs PROFIT | I14: 0 | J14: 0 | K14: 0 | L14: 0 | M14: 0 | N14: 0
B15: ALINMA DINAR DEALs VAT | I15: 0 | J15: 0 | K15: 0 | L15: 0 | M15: 0 | N15: 0
B16: ALINMA EQUITY | I16: 0 | J16: 0 | K16: 0 | L16: 0 | M16: 0 | N16: 0
B17: ALINMA USD | I17: 0 | J17: 0 | K17: 0 | L17: 0 | M17: 0 | N17: 0
B18: ALINMA VAT | I18: 0 | J18: 0 | K18: 0 | L18: 0 | M18: 0 | N18: 0
B19: ALINMA-DEBT | I19: 0 | J19: 0 | K19: 0 | L19: 0 | M19: 0 | N19: 0
B20: ANB-BILDNW TRADINGCOMPANY | I20: 0 | J20: 0 | K20: 0 | L20: 0 | M20: 0 | N20: 0
B21: Riyad Bank | I21: 0 | J21: 0 | K21: 0 | L21: 0 | M21: 0 | N21: 0
B22: US Checking Account | C22: 2008252.4 | D22: 2359619.8 | E22: 2572070.2 | F22: 2993836.8 | G22: 3243627.6 | H22: 3565406.1 | I22: 2938541.7 | J22: 1566648 | K22: 1911675.5 | L22: 2135188.9 | M22: 2290858.8 | N22: 4663542
B23: ANB Tanmeya Debt A/C
B24: Simplifi
B25: Petty Cash | C25: 0 | F25: 0 | G25: 0 | H25: 0 | I25: 0 | J25: 0 | K25: 0 | L25: 0 | M25: 0 | N25: 3758
B27: Trade Receivables (net) | C27: =SUM(C28:C29) -> 0 | D27: =SUM(D28:D29) -> 0 | E27: =SUM(E28:E29) -> 0 | F27: =SUM(F28:F29) -> 0 | H27: =SUM(H28:H29) -> 0 | I27: =SUM(I28:I29) -> 0 | J27: =SUM(J28:J29) -> 0 | K27: =SUM(K28:K29) -> 0 | L27: =SUM(L28:L29) -> 0 | M27: =SUM(M28:M29) -> 0 | N27: =SUM(N28:N29) -> 0
B28: Trade Receivables - Gross | J28: 0 | K28: 0 | L28: 0 | M28: 0 | N28: 0
B29: Provision for doubtful Accounts | C29: 0 | D29: 0 | E29: 0 | F29: 0 | H29: 0 | I29: 0 | J29: 0 | K29: 0 | L29: 0 | M29: 0 | N29: 0
B31: Prepaid Expenses & Other recievables | C31: =SUM(C32:C43) -> 131186.62 | D31: =SUM(D32:D43) -> 131131.33 | E31: =SUM(E32:E43) -> 142099.49 | F31: =SUM(F32:F43) -> 123074.57 | G31: =SUM(G32:G43) -> 48284.73 | H31: =SUM(H32:H43) -> 1679.89 | I31: =SUM(I32:I43) -> 5808.05 | J31: =SUM(J32:J43) -> 9936.21 | ... N31: =SUM(N32:N43) -> -2192.15
B32: Prepaid Vendors | I32: 0 | J32: 0 | K32: 0 | L32: 0 | M32: 0 | N32: 0
B33: Prepaid Accommodation Rent Expense | I33: 0 | J33: 0 | K33: 0 | L33: 0 | M33: 0 | N33: 0
B34: Prepaid Financing Expense | C34: 71402.05 | D34: 72654.7 | E34: 73907.35 | F34: 75160 | G34: 0 | H34: 0 | I34: 0 | J34: 0 | K34: 0 | L34: 0 | M34: 0 | N34: 0
B35: Prepaid Govt. Legal Expense | I35: 0 | J35: 0 | K35: 0 | L35: 0 | M35: 0 | N35: 0
B36: Prepaid IT Subscriptions Expense | C36: 15798.79 | D36: 10246.98 | E36: 14090.17 | I36: 0 | J36: 0 | K36: 0 | L36: 0 | M36: 0 | N36: 0
B37: Prepaid Office Rent Expense | I37: 0 | J37: 0 | K37: 0 | L37: 0 | M37: 0 | N37: 0
B38: Prepaid Other Expense | C38: 6155.23 | D38: 10399.1 | E38: 14642.97 | F38: 6576.57 | G38: 10704.73 | H38: 1679.89 | I38: 5808.05 | J38: 9936.21 | K38: 14064.37 | L38: -6576.45 | M38: -4384.3 | N38: -2192.15
B39: Fund Raising Expense receivable | C39: 37580 | D39: 37580 | E39: 37580 | F39: 37580 | G39: 37580
B40: Employee Receivable | C40: 250.55 | D40: 250.55 | E40: 1879 | F40: 3758 | G40: 0 | H40: 0 | I40: 0 | J40: 0 | K40: 0 | L40: 0 | M40: 0 | N40: 0
B41: Security deposits | I41: 0 | J41: 0 | K41: 0 | L41: 0 | M41: 0 | N41: 0
B42: Other Receivable
B43: Input VAT | I43: 0 | J43: 0 | K43: 0 | L43: 0 | M43: 0 | N43: 0
B44: Profit Reserve Account (Depsoit)
B46: TOTAL CURRENT ASSETS | C46: =+C31+C10+C27 -> 2139439.1 | D46: =+D31+D10+D27 -> 2490751.1 | E46: =+E31+E10+E27 -> 2714169.7 | F46: =+F31+F10+F27 -> 3116911.4 | G46: =+G31+G10+G27 -> 3291912.4 | H46: =+H31+H10+H27 -> 3567086 | I46: =+I31+I10+I27 -> 2944349.7 | J46: =+J31+J10+J27 -> 1576584.2 | ... N46: =+N31+N10+N27 -> 4665107.8
B49: Fixed Assets (net) | C49: =SUM(C50:C56) -> 10767.83 | D49: =SUM(D50:D57) -> 11366.03 | E49: =SUM(E50:E57) -> 11964.23 | F49: =SUM(F50:F57) -> 12562.43 | G49: =SUM(G50:G57) -> 13160.63 | H49: =SUM(H50:H57) -> 13758.83 | I49: =SUM(I50:I57) -> 0 | J49: =SUM(J50:J57) -> 0 | K49: =SUM(K50:K57) -> 0 | ... N49: =SUM(N50:N57) -> 0
B50: Accumulated Depreciation - Furniture & Fixture | J50: 0 | K50: 0 | L50: 0 | M50: 0 | N50: 0
B51: Accumulated Depreciation - Motor Vehicle | J51: 0 | K51: 0 | L51: 0 | M51: 0 | N51: 0
...

Sheet Sheet3

Sheet IS Dec Consolidated
C2: =C63/3.75 -> 26271.371 | E2: 45321 | F2: =EDATE(E2,1) -> 45351 | G2: =EDATE(F2,1) -> 45380 | H2: =EDATE(G2,1) -> 45411 | I2: =EDATE(H2,1) -> 45441 | J2: =EDATE(I2,1) -> 45472 | K2: =EDATE(J2,1) -> 45502 | L2: =EDATE(K2,1) -> 45533 | M2: =EDATE(L2,1) -> 45564 | ... P2: =EDATE(O2,1) -> 45655
C3: =C2/40 -> 656.78427 | E3: 12 | F3: =E3-1 -> 11 | G3: =F3-1 -> 10 | H3: =G3-1 -> 9 | I3: =H3-1 -> 8 | J3: =I3-1 -> 7 | K3: =J3-1 -> 6 | L3: =K3-1 -> 5 | M3: =L3-1 -> 4 | ... P3: =O3-1 -> 1
E4: {=INDEX($E$6:$P$6,,MATCH(E3,$E$5:$P$5,FALSE))} -> -3864.75 | F4: {=INDEX($E$6:$P$6,,MATCH(F3,$E$5:$P$5,FALSE))} -> -15356.85 | G4: {=INDEX($E$6:$P$6,,MATCH(G3,$E$5:$P$5,FALSE))} -> -86801.8 | H4: {=INDEX($E$6:$P$6,,MATCH(H3,$E$5:$P$5,FALSE))} -> -37530.76 | I4: {=INDEX($E$6:$P$6,,MATCH(I3,$E$5:$P$5,FALSE))} -> -80455.25 | J4: {=INDEX($E$6:$P$6,,MATCH(J3,$E$5:$P$5,FALSE))} -> -55373.37 | K4: {=INDEX($E$6:$P$6,,MATCH(K3,$E$5:$P$5,FALSE))} -> -74578.66 | L4: {=INDEX($E$6:$P$6,,MATCH(L3,$E$5:$P$5,FALSE))} -> -122563.93 | ... P4: {=INDEX($E$6:$P$6,,MATCH(P3,$E$5:$P$5,FALSE))} -> -218169.59
E5: 1 | F5: 2 | G5: 3 | H5: 4 | I5: 5 | J5: 6 | K5: 7 | L5: 8 | M5: 9 | N5: 10 | O5: 11 | P5: 12
E6: =SUM(E53:E63,E68:E69)*-1 -> -218169.59 | F6: =SUM(F53:F63,F68:F69)*-1 -> -61700.21 | G6: =SUM(G53:G63,G68:G69)*-1 -> -60767.06 | H6: =SUM(I53:I63,I68:I69)*-1 -> -68531.35 | I6: =SUM(J53:J63,J68:J69)*-1 -> -122563.93 | J6: =SUM(K53:K63,K68:K69)*-1 -> -74578.66 | K6: =SUM(M53:M63,M68:M69)*-1 -> -55373.37 | L6: =SUM(N53:N63,N68:N69)*-1 -> -80455.25 | M6: =SUM(O53:O63,O68:O69)*-1 -> -37530.76 | N6: =SUM(Q53:Q63,Q68:Q69)*-1 -> -86801.8 | O6: =SUM(R53:R63,R68:R69)*-1 -> -15356.85 | P6: =SUM(S53:S63,S68:S69)*-1 -> -3864.75
B7: INCOME STATEMENT (US SAR) | C7: YTD | D7: Q4 - A | E7: MTD | F7: MTD | G7: MTD | H7: Q3 - A | I7: MTD | J7: MTD | K7: MTD | L7: Q2 - A | M7: MTD | N7: MTD | O7: MTD | P7: Q1 A | Q7: MTD | R7: MTD | S7: MTD
B8: FOR THE PERIOD 31st December 2024 | D8: 2024 | E8: 45657 | F8: 45626 | G8: 45596 | H8: 2024 | I8: 45565 | J8: 45535 | K8: 45504 | L8: 2024 | M8: 45473 | N8: 45443 | O8: 45412 | P8: 2024 | Q8: 45382 | R8: 45350 | S8: 45322
B10: Sales | C10: =G10+H10+L10+P10+F10+E10 -> 76420880 | D10: =SUM(E10:G10) -> 21384440 | E10: ='IS Dec KSA'!E10+'IS Dec USA'!E10 -> 10080211 | F10: ='IS Dec KSA'!F10+'IS Dec USA'!F10 -> 7198821.6 | G10: ='IS Dec KSA'!G10+'IS Dec USA'!G10 -> 4105407 | H10: =I10+J10+K10 -> 18352785 | I10: ='IS Dec KSA'!I10+'IS Dec USA'!I10 -> 4309452.5 | J10: ='IS Dec KSA'!J10+'IS Dec USA'!J10 -> 6772612 | K10: ='IS Dec KSA'!K10+'IS Dec USA'!K10 -> 7270720.4 | L10: =SUM(M10:O10) -> 19534533 | M10: ='IS Dec KSA'!M10+'IS Dec USA'!M10 -> 6957712.6 | N10: ='IS Dec KSA'!N10+'IS Dec USA'!N10 -> 7682337.2 | O10: ='IS Dec KSA'!O10+'IS Dec USA'!O10 -> 4894483.3 | P10: =SUM(Q10:S10) -> 17149122 | Q10: ='IS Dec KSA'!Q10+'IS Dec USA'!Q10 -> 9910492.9 | R10: ='IS Dec KSA'!R10+'IS Dec USA'!R10 -> 4805893.4 | S10: ='IS Dec KSA'!S10+'IS Dec USA'!S10 -> 2432735.6
B11: Cost of Goods Sold | C11: =G11+H11+L11+P11+F11+E11 -> 69127802 | D11: =SUM(E11:G11) -> 19099399 | E11: ='IS Dec KSA'!E11+'IS Dec USA'!E11 -> 9065157.9 | F11: ='IS Dec KSA'!F11+'IS Dec USA'!F11 -> 6363435 | G11: ='IS Dec KSA'!G11+'IS Dec USA'!G11 -> 3670806.6 | H11: =I11+J11+K11 -> 16705223 | I11: ='IS Dec KSA'!I11+'IS Dec USA'!I11 -> 3901380 | J11: ='IS Dec KSA'!J11+'IS Dec USA'!J11 -> 6268336 | K11: ='IS Dec KSA'!K11+'IS Dec USA'!K11 -> 6535506.8 | L11: =SUM(M11:O11) -> 17712883 | M11: ='IS Dec KSA'!M11+'IS Dec USA'!M11 -> 6212033.5 | N11: ='IS Dec KSA'!N11+'IS Dec USA'!N11 -> 6980089.4 | O11: ='IS Dec KSA'!O11+'IS Dec USA'!O11 -> 4520760 | P11: =SUM(Q11:S11) -> 15610297 | Q11: ='IS Dec KSA'!Q11+'IS Dec USA'!Q11 -> 9054208.4 | R11: ='IS Dec KSA'!R11+'IS Dec USA'!R11 -> 4407294 | S11: ='IS Dec KSA'!S11+'IS Dec USA'!S11 -> 2148794.4
B12: Purchase Discounts | C12: =G12+H12+L12+P12+F12+E12 -> -93226.45 | D12: =SUM(E12:G12) -> -1236.25 | E12: ='IS Dec KSA'!E12+'IS Dec USA'!E12 -> 0 | F12: ='IS Dec KSA'!F12+'IS Dec USA'!F12 -> 0 | G12: ='IS Dec KSA'!G12+'IS Dec USA'!G12 -> -1236.25 | H12: =I12+J12+K12 -> -54172.81 | I12: ='IS Dec KSA'!I12+'IS Dec USA'!I12 -> -6670 | J12: ='IS Dec KSA'!J12+'IS Dec USA'!J12 -> -7915.43 | K12: ='IS Dec KSA'!K12+'IS Dec USA'!K12 -> -39587.38 | L12: =SUM(M12:O12) -> -18295.8 | M12: ='IS Dec KSA'!M12+'IS Dec USA'!M12 -> 0 | N12: ='IS Dec KSA'!N12+'IS Dec USA'!N12 -> -5820.46 | O12: ='IS Dec KSA'!O12+'IS Dec USA'!O12 -> -12475.34 | P12: =SUM(Q12:S12) -> -19521.59 | Q12: ='IS Dec KSA'!Q12+'IS Dec USA'!Q12 -> -11033.03 | R12: ='IS Dec KSA'!R12+'IS Dec USA'!R12 -> -8488.56 | S12: ='IS Dec KSA'!S12+'IS Dec USA'!S12 -> 0
B13: Gross Profit / (Loss) | C13: =G13+H13+L13+P13+F13+E13 -> 7386304.4 | D13: =SUM(E13:G13) -> 2286276.6 | E13: ='IS Dec KSA'!E13+'IS Dec USA'!E13 -> 1015053.3 | F13: ='IS Dec KSA'!F13+'IS Dec USA'!F13 -> 835386.63 | G13: ='IS Dec KSA'!G13+'IS Dec USA'!G13 -> 435836.72 | H13: =I13+J13+K13 -> 1701735 | I13: ='IS Dec KSA'!I13+'IS Dec USA'!I13 -> 414742.55 | J13: ='IS Dec KSA'!J13+'IS Dec USA'!J13 -> 512191.45 | K13: ='IS Dec KSA'!K13+'IS Dec USA'!K13 -> 774800.95 | L13: =SUM(M13:O13) -> 1839946.1 | M13: ='IS Dec KSA'!M13+'IS Dec USA'!M13 -> 745679.15 | N13: ='IS Dec KSA'!N13+'IS Dec USA'!N13 -> 708068.27 | O13: ='IS Dec KSA'!O13+'IS Dec USA'!O13 -> 386198.65 | P13: =SUM(Q13:S13) -> 1558346.7 | Q13: ='IS Dec KSA'!Q13+'IS Dec USA'!Q13 -> 867317.58 | R13: ='IS Dec KSA'!R13+'IS Dec USA'!R13 -> 407087.92 | S13: ='IS Dec KSA'!S13+'IS Dec USA'!S13 -> 283941.25
B14: Consultation Income | C14: =G14+H14+L14+P14+F14+E14 -> 293478.27 | D14: =SUM(E14:G14) -> 26086.96 | E14: ='IS Dec KSA'!E14+'IS Dec USA'!E14 -> 26086.96 | F14: ='IS Dec KSA'!F14+'IS Dec USA'!F14 -> 0 | G14: ='IS Dec KSA'!G14+'IS Dec USA'!G14 -> 0 | H14: =I14+J14+K14 -> 143478.26 | I14: ='IS Dec KSA'!I14+'IS Dec USA'!I14 -> 0 | J14: ='IS Dec KSA'!J14+'IS Dec USA'!J14 -> 0 | K14: ='IS Dec KSA'!K14+'IS Dec USA'!K14 -> 143478.26 | L14: =SUM(M14:O14) -> 0 | M14: ='IS Dec KSA'!M14+'IS Dec USA'!M14 -> 0 | N14: ='IS Dec KSA'!N14+'IS Dec USA'!N14 -> 0 | O14: ='IS Dec KSA'!O14+'IS Dec USA'!O14 -> 0 | P14: =SUM(Q14:S14) -> 123913.05 | Q14: ='IS Dec KSA'!Q14+'IS Dec USA'!Q14 -> 19565.22 | R14: ='IS Dec KSA'!R14+'IS Dec USA'!R14 -> 104347.83 | S14: ='IS Dec KSA'!S14+'IS Dec USA'!S14 -> 0
B15: Gross Income | C15: =G15+H15+L15+P15+F15+E15 -> 7679782.6 | D15: =SUM(E15:G15) -> 2312363.6 | E15: =+E14+E13 -> 1041140.2 | F15: =+F14+F13 -> 835386.63 | G15: =+G14+G13 -> 435836.72 | H15: =+H14+H13 -> 1845213.2 | I15: =+I14+I13 -> 414742.55 | J15: =+J14+J13 -> 512191.45 | K15: =+K14+K13 -> 918279.21 | L15: =+L14+L13 -> 1839946.1 | ... S15: =+S14+S13 -> 283941.25
B17: General and Administrative Expenses | C17: =SUM(C18:C33) -> 1182570.3 | D17: =SUM(D18:D33) -> 588110.79 | E17: =SUM(E18:E33) -> 326464.28 | F17: =SUM(F18:F33) -> 118090.11 | G17: =SUM(G18:G33) -> 143556.4 | H17: =SUM(H18:H33) -> 222605.63 | I17: =SUM(I18:I33) -> 99971.72 | J17: =SUM(J18:J33) -> 54605.6 | ... S17: =SUM(S18:S33) -> 64127.9
B18: Bad Debt | C18: =G18+H18+L18+P18+F18+E18 -> 203016.64 | D18: =SUM(E18:G18) -> 203011.78 | E18: ='IS Dec KSA'!E18+'IS Dec USA'!E18 -> 203009.5 | F18: ='IS Dec KSA'!F18+'IS Dec USA'!F18 -> 0.37 | G18: ='IS Dec KSA'!G18+'IS Dec USA'!G18 -> 1.91 | H18: =I18+J18+K18 -> 2.67 | I18: ='IS Dec KSA'!I18+'IS Dec USA'!I18 -> 0.5 | J18: ='IS Dec KSA'!J18+'IS Dec USA'!J18 -> 0.4 | K18: ='IS Dec KSA'!K18+'IS Dec USA'!K18 -> 1.77 | L18: =SUM(M18:O18) -> 0.63 | M18: ='IS Dec KSA'!M18+'IS Dec USA'!M18 -> 0 | N18: ='IS Dec KSA'!N18+'IS Dec USA'!N18 -> 0.63 | O18: ='IS Dec KSA'!O18+'IS Dec USA'!O18 -> 0 | P18: =SUM(Q18:S18) -> 1.56 | Q18: ='IS Dec KSA'!Q18+'IS Dec USA'!Q18 -> 0.51 | R18: ='IS Dec KSA'!R18+'IS Dec USA'!R18 -> 0.27 | S18: ='IS Dec KSA'!S18+'IS Dec USA'!S18 -> 0.78
B19: Bank Fees and Charges | C19: =G19+H19+L19+P19+F19+E19 -> 24338.49 | D19: =SUM(E19:G19) -> 5748.42 | E19: ='IS Dec KSA'!E19+'IS Dec USA'!E19 -> 2381.41 | F19: ='IS Dec KSA'!F19+'IS Dec USA'!F19 -> 868.91 | G19: ='IS Dec KSA'!G19+'IS Dec USA'!G19 -> 2498.1 | H19: =I19+J19+K19 -> 5553.18 | I19: ='IS Dec KSA'!I19+'IS Dec USA'!I19 -> 916.73 | J19: ='IS Dec KSA'!J19+'IS Dec USA'!J19 -> 1735.73 | K19: ='IS Dec KSA'!K19+'IS Dec USA'!K19 -> 2900.72 | L19: =SUM(M19:O19) -> 7303.74 | M19: ='IS Dec KSA'!M19+'IS Dec USA'!M19 -> 1444.7 | N19: ='IS Dec KSA'!N19+'IS Dec USA'!N19 -> 3296.92 | O19: ='IS Dec KSA'!O19+'IS Dec USA'!O19 -> 2562.12 | P19: =SUM(Q19:S19) -> 5733.15 | Q19: ='IS Dec KSA'!Q19+'IS Dec USA'!Q19 -> 1642.49 | R19: ='IS Dec KSA'!R19+'IS Dec USA'!R19 -> 2076.03 | S19: ='IS Dec KSA'!S19+'IS Dec USA'!S19 -> 2014.63
B20: Office Supplies | C20: =G20+H20+L20+P20+F20+E20 -> 54128.03 | D20: =SUM(E20:G20) -> 2690.87 | E20: ='IS Dec KSA'!E20+'IS Dec USA'!E20 -> 819.32 | F20: ='IS Dec KSA'!F20+'IS Dec USA'!F20 -> 669.05 | G20: ='IS Dec KSA'!G20+'IS Dec USA'!G20 -> 1202.5 | H20: =I20+J20+K20 -> 11522.46 | I20: ='IS Dec KSA'!I20+'IS Dec USA'!I20 -> 4877.46 | J20: ='IS Dec KSA'!J20+'IS Dec USA'!J20 -> 6110.09 | K20: ='IS Dec KSA'!K20+'IS Dec USA'!K20 -> 534.91 | L20: =SUM(M20:O20) -> 24158.2 | M20: ='IS Dec KSA'!M20+'IS Dec USA'!M20 -> 682.6 | N20: ='IS Dec KSA'!N20+'IS Dec USA'!N20 -> 7993.77 | O20: ='IS Dec KSA'!O20+'IS Dec USA'!O20 -> 15481.83 | P20: =SUM(Q20:S20) -> 15756.5 | Q20: ='IS Dec KSA'!Q20+'IS Dec USA'!Q20 -> 2319 | R20: ='IS Dec KSA'!R20+'IS Dec USA'!R20 -> 6937.47 | S20: ='IS Dec KSA'!S20+'IS Dec USA'!S20 -> 6500.03
B21: Office Utilities - Electricity/Water/Janitorial | C21: =G21+H21+L21+P21+F21+E21 -> 24609.21 | D21: =SUM(E21:G21) -> 13664.34 | E21: ='IS Dec KSA'!E21+'IS Dec USA'!E21 -> 4705.55 | F21: ='IS Dec KSA'!F21+'IS Dec USA'!F21 -> 1182.28 | G21: ='IS Dec KSA'!G21+'IS Dec USA'!G21 -> 7776.51 | H21: =I21+J21+K21 -> 6139.69 | I21: ='IS Dec KSA'!I21+'IS Dec USA'!I21 -> 282 | J21: ='IS Dec KSA'!J21+'IS Dec USA'!J21 -> 4257.65 | K21: ='IS Dec KSA'!K21+'IS Dec USA'!K21 -> 1600.04 | L21: =SUM(M21:O21) -> 3342.28 | M21: ='IS Dec KSA'!M21+'IS Dec USA'!M21 -> 983.6 | N21: ='IS Dec KSA'!N21+'IS Dec USA'!N21 -> 1889.74 | O21: ='IS Dec KSA'!O21+'IS Dec USA'!O21 -> 468.94 | P21: =SUM(Q21:S21) -> 1462.9 | Q21: ='IS Dec KSA'!Q21+'IS Dec USA'!Q21 -> 824.4 | R21: ='IS Dec KSA'!R21+'IS Dec USA'!R21 -> 454 | S21: ='IS Dec KSA'!S21+'IS Dec USA'!S21 -> 184.5
B22: Office Expenses | C22: =G22+H22+L22+P22+F22+E22 -> 3444.41 | D22: =SUM(E22:G22) -> 1 | E22: ='IS Dec KSA'!E22+'IS Dec USA'!E22 -> 0 | F22: ='IS Dec KSA'!F22+'IS Dec USA'!F22 -> 0 | G22: ='IS Dec KSA'!G22+'IS Dec USA'!G22 -> 1 | H22: =I22+J22+K22 -> 0 | I22: ='IS Dec KSA'!I22+'IS Dec USA'!I22 -> 0 | J22: ='IS Dec KSA'!J22+'IS Dec USA'!J22 -> 0 | K22: ='IS Dec KSA'!K22+'IS Dec USA'!K22 -> 0 | L22: =SUM(M22:O22) -> 0 | M22: ='IS Dec KSA'!M22+'IS Dec USA'!M22 -> 0 | N22: ='IS Dec KSA'!N22+'IS Dec USA'!N22 -> 0 | O22: ='IS Dec KSA'!O22+'IS Dec USA'!O22 -> 0 | P22: =SUM(Q22:S22) -> 3443.41 | Q22: ='IS Dec KSA'!Q22+'IS Dec USA'!Q22 -> 0 | R22: ='IS Dec KSA'!R22+'IS Dec USA'!R22 -> 3443.41 | S22: ='IS Dec KSA'!S22+'IS Dec USA'!S22 -> 0
B23: Travel Expense | C23: =G23+H23+L23+P23+F23+E23 -> 38163.24 | D23: =SUM(E23:G23) -> 3750 | E23: ='IS Dec KSA'!E23+'IS Dec USA'!E23 -> 3750 | F23: ='IS Dec KSA'!F23+'IS Dec USA'!F23 -> 0 | G23: ='IS Dec KSA'!G23+'IS Dec USA'!G23 -> 0 | H23: =I23+J23+K23 -> 18156.74 | I23: ='IS Dec KSA'!I23+'IS Dec USA'!I23 -> 2446.84 | J23: ='IS Dec KSA'!J23+'IS Dec USA'!J23 -> 0 | K23: ='IS Dec KSA'!K23+'IS Dec USA'!K23 -> 15709.9 | L23: =SUM(M23:O23) -> 8606.53 | M23: ='IS Dec KSA'!M23+'IS Dec USA'!M23 -> 308.16 | N23: ='IS Dec KSA'!N23+'IS Dec USA'!N23 -> 8025.25 | O23: ='IS Dec KSA'!O23+'IS Dec USA'!O23 -> 273.12 | P23: =SUM(Q23:S23) -> 7649.97 | Q23: ='IS Dec KSA'!Q23+'IS Dec USA'!Q23 -> 814.47 | R23: ='IS Dec KSA'!R23+'IS Dec USA'!R23 -> 6835.5 | S23: ='IS Dec KSA'!S23+'IS Dec USA'!S23 -> 0
B24: Printing and Stationery | C24: =G24+H24+L24+P24+F24+E24 -> 4591.36 | D24: =SUM(E24:G24) -> 1056.29 | E24: ='IS Dec KSA'!E24+'IS Dec USA'!E24 -> 241 | F24: ='IS Dec KSA'!F24+'IS Dec USA'!F24 -> 675.29 | G24: ='IS Dec KSA'!G24+'IS Dec USA'!G24 -> 140 | H24: =I24+J24+K24 -> 2690.93 | I24: ='IS Dec KSA'!I24+'IS Dec USA'!I24 -> 990.06 | J24: ='IS Dec KSA'!J24+'IS Dec USA'!J24 -> 0 | K24: ='IS Dec KSA'!K24+'IS Dec USA'!K24 -> 1700.87 | L24: =SUM(M24:O24) -> 69.57 | M24: ='IS Dec KSA'!M24+'IS Dec USA'!M24 -> 69.57 | N24: ='IS Dec KSA'!N24+'IS Dec USA'!N24 -> 0 | O24: ='IS Dec KSA'!O24+'IS Dec USA'!O24 -> 0 | P24: =SUM(Q24:S24) -> 774.57 | Q24: ='IS Dec KSA'!Q24+'IS Dec USA'!Q24 -> 0 | R24: ='IS Dec KSA'!R24+'IS Dec USA'!R24 -> 774.57 | S24: ='IS Dec KSA'!S24+'IS Dec USA'!S24 -> 0
B25: Rent Expense (G&A) | C25: =G25+H25+L25+P25+F25+E25 -> 127377.94 | D25: =SUM(E25:G25) -> 48093.19 | E25: ='IS Dec KSA'!E25+'IS Dec USA'!E25 -> 32096.09 | F25: ='IS Dec KSA'!F25+'IS Dec USA'!F25 -> 7998.55 | G25: ='IS Dec KSA'!G25+'IS Dec USA'!G25 -> 7998.55 | H25: =I25+J25+K25 -> 23995.64 | I25: ='IS Dec KSA'!I25+'IS Dec USA'!I25 -> 7998.55 | J25: ='IS Dec KSA'!J25+'IS Dec USA'!J25 -> 7998.55 | K25: ='IS Dec KSA'!K25+'IS Dec USA'!K25 -> 7998.54 | L25: =SUM(M25:O25) -> 23899.98 | M25: ='IS Dec KSA'!M25+'IS Dec USA'!M25 -> 7966.66 | N25: ='IS Dec KSA'!N25+'IS Dec USA'!N25 -> 7966.66 | O25: ='IS Dec KSA'!O25+'IS Dec USA'!O25 -> 7966.66 | P25: =SUM(Q25:S25) -> 31389.13 | Q25: ='IS Dec KSA'!Q25+'IS Dec USA'!Q25 -> 10162.66 | R25: ='IS Dec KSA'!R25+'IS Dec USA'!R25 -> 10162.66 | S25: ='IS Dec KSA'!S25+'IS Dec USA'!S25 -> 11063.81
B26: Meals and Entertainment | C26: =G26+H26+L26+P26+F26+E26 -> 91973.44 | D26: =SUM(E26:G26) -> 48368.41 | E26: ='IS Dec KSA'!E26+'IS Dec USA'!E26 -> 3897.75 | F26: ='IS Dec KSA'!F26+'IS Dec USA'!F26 -> 25111.76 | G26: ='IS Dec KSA'!G26+'IS Dec USA'!G26 -> 19358.9 | H26: =I26+J26+K26 -> 22739.23 | I26: ='IS Dec KSA'!I26+'IS Dec USA'!I26 -> 8471.34 | J26: ='IS Dec KSA'!J26+'IS Dec USA'!J26 -> 6298.48 | K26: ='IS Dec KSA'!K26+'IS Dec USA'!K26 -> 7969.41 | L26: =SUM(M26:O26) -> 8918.73 | M26: ='IS Dec KSA'!M26+'IS Dec USA'!M26 -> 3696.52 | N26: ='IS Dec KSA'!N26+'IS Dec USA'!N26 -> 3183.82 | O26: ='IS Dec KSA'!O26+'IS Dec USA'!O26 -> 2038.39 | P26: =SUM(Q26:S26) -> 11947.07 | Q26: ='IS Dec KSA'!Q26+'IS Dec USA'!Q26 -> 1173.66 | R26: ='IS Dec KSA'!R26+'IS Dec USA'!R26 -> 3677.22 | S26: ='IS Dec KSA'!S26+'IS Dec USA'!S26 -> 7096.19
B27: Audit & Consultancy expense | C27: =G27+H27+L27+P27+F27+E27 -> 42500 | D27: =SUM(E27:G27) -> 17500 | E27: ='IS Dec KSA'!E27+'IS Dec USA'!E27 -> 17500 | F27: ='IS Dec KSA'!F27+'IS Dec USA'!F27 -> 0 | G27: ='IS Dec KSA'!G27+'IS Dec USA'!G27 -> 0 | H27: =I27+J27+K27 -> 0 | I27: ='IS Dec KSA'!I27+'IS Dec USA'!I27 -> 0 | J27: ='IS Dec KSA'!J27+'IS Dec USA'!J27 -> 0 | K27: ='IS Dec KSA'!K27+'IS Dec USA'!K27 -> 0 | L27: =SUM(M27:O27) -> 12500 | M27: ='IS Dec KSA'!M27+'IS Dec USA'!M27 -> 12500 | N27: ='IS Dec KSA'!N27+'IS Dec USA'!N27 -> 0 | O27: ='IS Dec KSA'!O27+'IS Dec USA'!O27 -> 0 | P27: =SUM(Q27:S27) -> 12500 | Q27: ='IS Dec KSA'!Q27+'IS Dec USA'!Q27 -> 0 | R27: ='IS Dec KSA'!R27+'IS Dec USA'!R27 -> 0 | S27: ='IS Dec KSA'!S27+'IS Dec USA'!S27 -> 12500
B28: Communication Exp - Mobile & Internet | C28: =G28+H28+L28+P28+F28+E28 -> 25607.52 | D28: =SUM(E28:G28) -> 8450.21 | E28: ='IS Dec KSA'!E28+'IS Dec USA'!E28 -> 2142.64 | F28: ='IS Dec KSA'!F28+'IS Dec USA'!F28 -> 2122.61 | G28: ='IS Dec KSA'!G28+'IS Dec USA'!G28 -> 4184.96 | H28: =I28+J28+K28 -> 4191.5 | I28: ='IS Dec KSA'!I28+'IS Dec USA'!I28 -> 288.54 | J28: ='IS Dec KSA'!J28+'IS Dec USA'!J28 -> 1922.61 | K28: ='IS Dec KSA'!K28+'IS Dec USA'!K28 -> 1980.35 | L28: =SUM(M28:O28) -> 7104.36 | M28: ='IS Dec KSA'!M28+'IS Dec USA'!M28 -> 2045.28 | N28: ='IS Dec KSA'!N28+'IS Dec USA'!N28 -> 2927.6 | O28: ='IS Dec KSA'!O28+'IS Dec USA'!O28 -> 2131.48 | P28: =SUM(Q28:S28) -> 5861.45 | Q28: ='IS Dec KSA'!Q28+'IS Dec USA'!Q28 -> 2016.21 | R28: ='IS Dec KSA'!R28+'IS Dec USA'!R28 -> 1922.61 | S28: ='IS Dec KSA'!S28+'IS Dec USA'!S28 -> 1922.63
B29: Subscriptions & Memberships | C29: =G29+H29+L29+P29+F29+E29 -> 472140.14 | D29: =SUM(E29:G29) -> 171131.28 | E29: ='IS Dec KSA'!E29+'IS Dec USA'!E29 -> 51500.23 | F29: ='IS Dec KSA'!F29+'IS Dec USA'!F29 -> 75292.78 | G29: ='IS Dec KSA'!G29+'IS Dec USA'!G29 -> 44338.27 | H29: =I29+J29+K29 -> 121579.29 | I29: ='IS Dec KSA'!I29+'IS Dec USA'!I29 -> 67561.27 | J29: ='IS Dec KSA'!J29+'IS Dec USA'!J29 -> 26386.19 | K29: ='IS Dec KSA'!K29+'IS Dec USA'!K29 -> 27631.83 | L29: =SUM(M29:O29) -> 99523.89 | M29: ='IS Dec KSA'!M29+'IS Dec USA'!M29 -> 26720.77 | N29: ='IS Dec KSA'!N29+'IS Dec USA'!N29 -> 39015.77 | O29: ='IS Dec KSA'!O29+'IS Dec USA'!O29 -> 33787.35 | P29: =SUM(Q29:S29) -> 79905.68 | Q29: ='IS Dec KSA'!Q29+'IS Dec USA'!Q29 -> 30359.81 | R29: ='IS Dec KSA'!R29+'IS Dec USA'!R29 -> 26700.54 | S29: ='IS Dec KSA'!S29+'IS Dec USA'!S29 -> 22845.33
... B31: Low Value Assets | C31: =G31+H31+L31+P31+F31+E31 -> 13174.86 | D31: =SUM(E31:G31) -> 7036.43 | E31: ='IS Dec KSA'!E31+'IS Dec USA'!E31 -> 2420.55 | F31: ='IS Dec KSA'!F31+'IS Dec USA'!F31 -> 4168.5 | G31: ='IS Dec KSA'!G31+'IS Dec USA'!G31 -> 447.38 | H31: =I31+J31+K31 -> 6138.43 | I31: ='IS Dec KSA'!I31+'IS Dec USA'!I31 -> 6138.43 | J31: ='IS Dec KSA'!J31+'IS Dec USA'!J31 -> 0 | K31: ='IS Dec KSA'!K31+'IS Dec USA'!K31 -> 0 | L31: =SUM(M31:O31) -> 0 | M31: ='IS Dec KSA'!M31+'IS Dec USA'!M31 -> 0 | N31: ='IS Dec KSA'!N31+'IS Dec USA'!N31 -> 0 | O31: ='IS Dec KSA'!O31+'IS Dec USA'!O31 -> 0 | P31: =SUM(Q31:S31) -> 0 | Q31: ='IS Dec KSA'!Q31+'IS Dec USA'!Q31 -> 0 | R31: ='IS Dec KSA'!R31+'IS Dec USA'!R31 -> 0 | S31: ='IS Dec KSA'!S31+'IS Dec USA'!S31 -> 0
B32: Charity | C32: =G32+H32+L32+P32+F32+E32 -> 10000 | D32: =SUM(E32:G32) -> 10000 | E32: ='IS Dec KSA'!E32+'IS Dec USA'!E32 -> 2000 | F32: ='IS Dec KSA'!F32+'IS Dec USA'!F32 -> 0 | G32: ='IS Dec KSA'!G32+'IS Dec USA'!G32 -> 8000
B33: Witholding Tax | C33: =G33+H33+L33+P33+F33+E33 -> 47608.81 | D33: =SUM(E33:G33) -> 47608.81 | E33: ='IS Dec KSA'!E33+'IS Dec USA'!E33 -> 0 | F33: ='IS Dec KSA'!F33+'IS Dec USA'!F33 -> 0 | G33: ='IS Dec KSA'!G33+'IS Dec USA'!G33 -> 47608.81
B34: Selling Expenses | C34: =SUM(C35:C43) -> 771628.36 | D34: =SUM(E34:G34) -> 263087.79 | E34: =SUM(E35:E43) -> 88341.5 | F34: =SUM(F35:F43) -> 99215.19 | G34: =SUM(G35:G43) -> 75531.1 | H34: =SUM(H35:H43) -> 217926.39 | I34: =SUM(I35:I43) -> 110136.53 | J34: =SUM(J35:J43) -> 52412.66 | K34: =SUM(K35:K43) -> 55377.2 | L34: =SUM(L35:L43) -> 174055.86 | ... S34: =SUM(S35:S43) -> 29131.09
B35: Business travel expenses | C35: =G35+H35+L35+P35+F35+E35 -> 110575.44 | D35: =SUM(E35:G35) -> 61398.61 | E35: ='IS Dec KSA'!E35+'IS Dec USA'!E35 -> 18308.59 | F35: ='IS Dec KSA'!F35+'IS Dec USA'!F35 -> 18913.71 | G35: ='IS Dec KSA'!G35+'IS Dec USA'!G35 -> 24176.31 | H35: =I35+J35+K35 -> 15855.33 | I35: ='IS Dec KSA'!I35+'IS Dec USA'!I35 -> 4564.64 | J35: ='IS Dec KSA'!J35+'IS Dec USA'!J35 -> 690 | K35: ='IS Dec KSA'!K35+'IS Dec USA'!K35 -> 10600.69 | L35: =SUM(M35:O35) -> 21622.38 | M35: ='IS Dec KSA'!M35+'IS Dec USA'!M35 -> 2500 | N35: ='IS Dec KSA'!N35+'IS Dec USA'!N35 -> 2912.45 | O35: ='IS Dec KSA'!O35+'IS Dec USA'!O35 -> 16209.93 | P35: =SUM(Q35:S35) -> 11699.12 | Q35: ='IS Dec KSA'!Q35+'IS Dec USA'!Q35 -> 7809.92 | R35: ='IS Dec KSA'!R35+'IS Dec USA'!R35 -> 3889.2 | S35: ='IS Dec KSA'!S35+'IS Dec USA'!S35 -> 0
B36: Collection Commission | C36: =G36+H36+L36+P36+F36+E36 -> 61150.53 | D36: =SUM(E36:G36) -> 8117.57 | E36: ='IS Dec KSA'!E36+'IS Dec USA'!E36 -> 4797.13 | F36: ='IS Dec KSA'!F36+'IS Dec USA'!F36 -> 0 | G36: ='IS Dec KSA'!G36+'IS Dec USA'!G36 -> 3320.44 | H36: =I36+J36+K36 -> 17715.01 | I36: ='IS Dec KSA'!I36+'IS Dec USA'!I36 -> 3388.45 | J36: ='IS Dec KSA'!J36+'IS Dec USA'!J36 -> 11016.84 | K36: ='IS Dec KSA'!K36+'IS Dec USA'!K36 -> 3309.72 | L36: =SUM(M36:O36) -> 17647.36 | M36: ='IS Dec KSA'!M36+'IS Dec USA'!M36 -> 10814.05 | N36: ='IS Dec KSA'!N36+'IS Dec USA'!N36 -> 4426.28 | O36: ='IS Dec KSA'!O36+'IS Dec USA'!O36 -> 2407.03 | P36: =SUM(Q36:S36) -> 17670.59 | Q36: ='IS Dec KSA'!Q36+'IS Dec USA'!Q36 -> 6731.53 | R36: ='IS Dec KSA'!R36+'IS Dec USA'!R36 -> 1817.82 | S36: ='IS Dec KSA'!S36+'IS Dec USA'!S36 -> 9121.24
